{"text": "2024-12-18 17:54:14.439 | DEBUG    | __main__:<module>:47 - Starting\n", "record": {"elapsed": {"repr": "0:00:00.335856", "seconds": 0.335856}, "exception": null, "extra": {}, "file": {"name": "user.py", "path": "D:\\–ê–°–£–ü\\Python\\Projects\\OwnBot\\classes\\user.py"}, "function": "<module>", "level": {"icon": "üêû", "name": "DEBUG", "no": 10}, "line": 47, "message": "Starting", "module": "user", "name": "__main__", "process": {"id": 18440, "name": "MainProcess"}, "thread": {"id": 17468, "name": "MainThread"}, "time": {"repr": "2024-12-18 17:54:14.439237+06:00", "timestamp": 1734522854.439237}}}
{"text": "2024-12-18 17:58:07.902 | DEBUG    | __main__:<module>:47 - Starting\n", "record": {"elapsed": {"repr": "0:00:00.173196", "seconds": 0.173196}, "exception": null, "extra": {}, "file": {"name": "user.py", "path": "D:\\–ê–°–£–ü\\Python\\Projects\\OwnBot\\classes\\user.py"}, "function": "<module>", "level": {"icon": "üêû", "name": "DEBUG", "no": 10}, "line": 47, "message": "Starting", "module": "user", "name": "__main__", "process": {"id": 8372, "name": "MainProcess"}, "thread": {"id": 16420, "name": "MainThread"}, "time": {"repr": "2024-12-18 17:58:07.902486+06:00", "timestamp": 1734523087.902486}}}
{"text": "2024-12-19 09:38:23.033 | ERROR    | __main__:create_user:19 - –û—à–∏–±–∫–∞ –∑–∞–ø–∏—Å–∏ –≤ –ë–î –¥–ª—è 1238658905\n", "record": {"elapsed": {"repr": "0:00:00.026968", "seconds": 0.026968}, "exception": null, "extra": {}, "file": {"name": "user_db_utils.py", "path": "D:\\–ê–°–£–ü\\Python\\Projects\\OwnBot\\db\\db_utils\\user_db_utils.py"}, "function": "create_user", "level": {"icon": "‚ùå", "name": "ERROR", "no": 40}, "line": 19, "message": "–û—à–∏–±–∫–∞ –∑–∞–ø–∏—Å–∏ –≤ –ë–î –¥–ª—è 1238658905", "module": "user_db_utils", "name": "__main__", "process": {"id": 10684, "name": "MainProcess"}, "thread": {"id": 5640, "name": "MainThread"}, "time": {"repr": "2024-12-19 09:38:23.033007+06:00", "timestamp": 1734579503.033007}}}
{"text": "2024-12-19 09:39:33.393 | ERROR    | __main__:create_user:19 - –û—à–∏–±–∫–∞ –∑–∞–ø–∏—Å–∏ –≤ –ë–î –¥–ª—è 1238658905\n", "record": {"elapsed": {"repr": "0:00:00.026137", "seconds": 0.026137}, "exception": null, "extra": {"exc_info": true}, "file": {"name": "user_db_utils.py", "path": "D:\\–ê–°–£–ü\\Python\\Projects\\OwnBot\\db\\db_utils\\user_db_utils.py"}, "function": "create_user", "level": {"icon": "‚ùå", "name": "ERROR", "no": 40}, "line": 19, "message": "–û—à–∏–±–∫–∞ –∑–∞–ø–∏—Å–∏ –≤ –ë–î –¥–ª—è 1238658905", "module": "user_db_utils", "name": "__main__", "process": {"id": 5672, "name": "MainProcess"}, "thread": {"id": 2360, "name": "MainThread"}, "time": {"repr": "2024-12-19 09:39:33.393146+06:00", "timestamp": 1734579573.393146}}}
{"text": "2024-12-19 09:41:11.972 | ERROR    | __main__:create_user:19 - –û—à–∏–±–∫–∞ –∑–∞–ø–∏—Å–∏ –≤ –ë–î –¥–ª—è 1238658905\n", "record": {"elapsed": {"repr": "0:00:00.026946", "seconds": 0.026946}, "exception": null, "extra": {"exc_info": true}, "file": {"name": "user_db_utils.py", "path": "D:\\–ê–°–£–ü\\Python\\Projects\\OwnBot\\db\\db_utils\\user_db_utils.py"}, "function": "create_user", "level": {"icon": "‚ùå", "name": "ERROR", "no": 40}, "line": 19, "message": "–û—à–∏–±–∫–∞ –∑–∞–ø–∏—Å–∏ –≤ –ë–î –¥–ª—è 1238658905", "module": "user_db_utils", "name": "__main__", "process": {"id": 4796, "name": "MainProcess"}, "thread": {"id": 32, "name": "MainThread"}, "time": {"repr": "2024-12-19 09:41:11.972183+06:00", "timestamp": 1734579671.972183}}}
{"text": "2024-12-19 09:41:11.972 | ERROR    | __main__:create_user:20 - (sqlite3.IntegrityError) UNIQUE constraint failed: usermodel.telegram_id\n[SQL: INSERT INTO usermodel (telegram_id, todoist_token) VALUES (?, ?) RETURNING id, created_at, updated_at]\n[parameters: (1238658905, None)]\n(Background on this error at: https://sqlalche.me/e/20/gkpj)\nTraceback (most recent call last):\n\n  File \"D:\\–ê–°–£–ü\\Python\\Projects\\OwnBot\\venv\\Lib\\site-packages\\sqlalchemy\\engine\\base.py\", line 1967, in _exec_single_context\n    self.dialect.do_execute(\n    ‚îÇ    ‚îÇ       ‚îî <function DefaultDialect.do_execute at 0x0000024BB7B5DBC0>\n    ‚îÇ    ‚îî <sqlalchemy.dialects.sqlite.aiosqlite.SQLiteDialect_aiosqlite object at 0x0000024BB7C608F0>\n    ‚îî <sqlalchemy.engine.base.Connection object at 0x0000024BB93D0860>\n  File \"D:\\–ê–°–£–ü\\Python\\Projects\\OwnBot\\venv\\Lib\\site-packages\\sqlalchemy\\engine\\default.py\", line 941, in do_execute\n    cursor.execute(statement, parameters)\n    ‚îÇ      ‚îÇ       ‚îÇ          ‚îî (1238658905, None)\n    ‚îÇ      ‚îÇ       ‚îî 'INSERT INTO usermodel (telegram_id, todoist_token) VALUES (?, ?) RETURNING id, created_at, updated_at'\n    ‚îÇ      ‚îî <function AsyncAdapt_aiosqlite_cursor.execute at 0x0000024BB8260A40>\n    ‚îî <sqlalchemy.dialects.sqlite.aiosqlite.AsyncAdapt_aiosqlite_cursor object at 0x0000024BB834AF80>\n  File \"D:\\–ê–°–£–ü\\Python\\Projects\\OwnBot\\venv\\Lib\\site-packages\\sqlalchemy\\dialects\\sqlite\\aiosqlite.py\", line 147, in execute\n    self._adapt_connection._handle_exception(error)\n    ‚îÇ    ‚îî <member '_adapt_connection' of 'AsyncAdapt_aiosqlite_cursor' objects>\n    ‚îî <sqlalchemy.dialects.sqlite.aiosqlite.AsyncAdapt_aiosqlite_cursor object at 0x0000024BB834AF80>\n  File \"D:\\–ê–°–£–ü\\Python\\Projects\\OwnBot\\venv\\Lib\\site-packages\\sqlalchemy\\dialects\\sqlite\\aiosqlite.py\", line 298, in _handle_exception\n    raise error\n          ‚îî IntegrityError('UNIQUE constraint failed: usermodel.telegram_id')\n  File \"D:\\–ê–°–£–ü\\Python\\Projects\\OwnBot\\venv\\Lib\\site-packages\\sqlalchemy\\dialects\\sqlite\\aiosqlite.py\", line 129, in execute\n    self.await_(_cursor.execute(operation, parameters))\n    ‚îÇ    ‚îÇ      ‚îÇ       ‚îÇ       ‚îÇ          ‚îî (1238658905, None)\n    ‚îÇ    ‚îÇ      ‚îÇ       ‚îÇ       ‚îî 'INSERT INTO usermodel (telegram_id, todoist_token) VALUES (?, ?) RETURNING id, created_at, updated_at'\n    ‚îÇ    ‚îÇ      ‚îÇ       ‚îî <function Cursor.execute at 0x0000024BB8342160>\n    ‚îÇ    ‚îÇ      ‚îî <aiosqlite.cursor.Cursor object at 0x0000024BB93F7C20>\n    ‚îÇ    ‚îî <member 'await_' of 'AsyncAdapt_aiosqlite_cursor' objects>\n    ‚îî <sqlalchemy.dialects.sqlite.aiosqlite.AsyncAdapt_aiosqlite_cursor object at 0x0000024BB834AF80>\n  File \"D:\\–ê–°–£–ü\\Python\\Projects\\OwnBot\\venv\\Lib\\site-packages\\sqlalchemy\\util\\_concurrency_py3k.py\", line 132, in await_only\n    return current.parent.switch(awaitable)  # type: ignore[no-any-return,attr-defined] # noqa: E501\n           ‚îÇ       ‚îÇ             ‚îî <coroutine object Cursor.execute at 0x0000024BB94BF3E0>\n           ‚îÇ       ‚îî <attribute 'parent' of 'greenlet.greenlet' objects>\n           ‚îî <_AsyncIoGreenlet object at 0x0000024BB94B7280 (otid=0x0000024BB6D2BFC0) dead>\n  File \"D:\\–ê–°–£–ü\\Python\\Projects\\OwnBot\\venv\\Lib\\site-packages\\sqlalchemy\\util\\_concurrency_py3k.py\", line 196, in greenlet_spawn\n    value = await result\n                  ‚îî <coroutine object Connection.rollback at 0x0000024BB94EC580>\n  File \"D:\\–ê–°–£–ü\\Python\\Projects\\OwnBot\\venv\\Lib\\site-packages\\aiosqlite\\cursor.py\", line 48, in execute\n    await self._execute(self._cursor.execute, sql, parameters)\n          ‚îÇ    ‚îÇ        ‚îÇ    ‚îÇ       ‚îÇ        ‚îÇ    ‚îî (1238658905, None)\n          ‚îÇ    ‚îÇ        ‚îÇ    ‚îÇ       ‚îÇ        ‚îî 'INSERT INTO usermodel (telegram_id, todoist_token) VALUES (?, ?) RETURNING id, created_at, updated_at'\n          ‚îÇ    ‚îÇ        ‚îÇ    ‚îÇ       ‚îî <method 'execute' of 'sqlite3.Cursor' objects>\n          ‚îÇ    ‚îÇ        ‚îÇ    ‚îî <sqlite3.Cursor object at 0x0000024BB9350EC0>\n          ‚îÇ    ‚îÇ        ‚îî <aiosqlite.cursor.Cursor object at 0x0000024BB93F7C20>\n          ‚îÇ    ‚îî <function Cursor._execute at 0x0000024BB83420C0>\n          ‚îî <aiosqlite.cursor.Cursor object at 0x0000024BB93F7C20>\n  File \"D:\\–ê–°–£–ü\\Python\\Projects\\OwnBot\\venv\\Lib\\site-packages\\aiosqlite\\cursor.py\", line 40, in _execute\n    return await self._conn._execute(fn, *args, **kwargs)\n                 ‚îÇ    ‚îÇ     ‚îÇ        ‚îÇ    ‚îÇ       ‚îî {}\n                 ‚îÇ    ‚îÇ     ‚îÇ        ‚îÇ    ‚îî ('INSERT INTO usermodel (telegram_id, todoist_token) VALUES (?, ?) RETURNING id, created_at, updated_at', (1238658905, None))\n                 ‚îÇ    ‚îÇ     ‚îÇ        ‚îî <built-in method execute of sqlite3.Cursor object at 0x0000024BB9350EC0>\n                 ‚îÇ    ‚îÇ     ‚îî <function Connection._execute at 0x0000024BB8343380>\n                 ‚îÇ    ‚îî <Connection(Thread-1, stopped daemon 11636)>\n                 ‚îî <aiosqlite.cursor.Cursor object at 0x0000024BB93F7C20>\n  File \"D:\\–ê–°–£–ü\\Python\\Projects\\OwnBot\\venv\\Lib\\site-packages\\aiosqlite\\core.py\", line 132, in _execute\n    return await future\n                 ‚îî <Future finished exception=IntegrityError('UNIQUE constraint failed: usermodel.telegram_id')>\n  File \"D:\\–ê–°–£–ü\\Python\\Projects\\OwnBot\\venv\\Lib\\site-packages\\aiosqlite\\core.py\", line 115, in run\n    result = function()\n             ‚îî functools.partial(<built-in method close of sqlite3.Connection object at 0x0000024BB950B100>)\n\nsqlite3.IntegrityError: UNIQUE constraint failed: usermodel.telegram_id\n\n\nThe above exception was the direct cause of the following exception:\n\n\nTraceback (most recent call last):\n\n  File \"D:\\–ê–°–£–ü\\Python\\Projects\\OwnBot\\db\\db_utils\\user_db_utils.py\", line 42, in <module>\n    asyncio.run(create_user(telegram_id=settings.SUPER_USER_TG_ID))\n    ‚îÇ       ‚îÇ   ‚îÇ                       ‚îÇ        ‚îî 1238658905\n    ‚îÇ       ‚îÇ   ‚îÇ                       ‚îî Settings(BASE_DIR=WindowsPath('D:/–ê–°–£–ü/Python/Projects/OwnBot'), DB_NAME='ownbot.db', BOT_TOKEN='6682762558:AAFU51myQEDgMkblN...\n    ‚îÇ       ‚îÇ   ‚îî <function connection.<locals>.wrapper at 0x0000024BB8332480>\n    ‚îÇ       ‚îî <function run at 0x0000024BB6CA8040>\n    ‚îî <module 'asyncio' from 'C:\\\\Users\\\\user-18\\\\AppData\\\\Local\\\\Programs\\\\Python\\\\Python312\\\\Lib\\\\asyncio\\\\__init__.py'>\n\n  File \"C:\\Users\\user-18\\AppData\\Local\\Programs\\Python\\Python312\\Lib\\asyncio\\runners.py\", line 194, in run\n    return runner.run(main)\n           ‚îÇ      ‚îÇ   ‚îî <coroutine object connection.<locals>.wrapper at 0x0000024BB9372A40>\n           ‚îÇ      ‚îî <function Runner.run at 0x0000024BB6CDDEE0>\n           ‚îî <asyncio.runners.Runner object at 0x0000024BB82DDDC0>\n  File \"C:\\Users\\user-18\\AppData\\Local\\Programs\\Python\\Python312\\Lib\\asyncio\\runners.py\", line 118, in run\n    return self._loop.run_until_complete(task)\n           ‚îÇ    ‚îÇ     ‚îÇ                  ‚îî <Task pending name='Task-1' coro=<connection.<locals>.wrapper() running at D:\\–ê–°–£–ü\\Python\\Projects\\OwnBot\\db\\database.py:49> ...\n           ‚îÇ    ‚îÇ     ‚îî <function BaseEventLoop.run_until_complete at 0x0000024BB6CDB9C0>\n           ‚îÇ    ‚îî <ProactorEventLoop running=True closed=False debug=False>\n           ‚îî <asyncio.runners.Runner object at 0x0000024BB82DDDC0>\n  File \"C:\\Users\\user-18\\AppData\\Local\\Programs\\Python\\Python312\\Lib\\asyncio\\base_events.py\", line 673, in run_until_complete\n    self.run_forever()\n    ‚îÇ    ‚îî <function ProactorEventLoop.run_forever at 0x0000024BB6D4D080>\n    ‚îî <ProactorEventLoop running=True closed=False debug=False>\n  File \"C:\\Users\\user-18\\AppData\\Local\\Programs\\Python\\Python312\\Lib\\asyncio\\windows_events.py\", line 322, in run_forever\n    super().run_forever()\n  File \"C:\\Users\\user-18\\AppData\\Local\\Programs\\Python\\Python312\\Lib\\asyncio\\base_events.py\", line 640, in run_forever\n    self._run_once()\n    ‚îÇ    ‚îî <function BaseEventLoop._run_once at 0x0000024BB6CDD760>\n    ‚îî <ProactorEventLoop running=True closed=False debug=False>\n  File \"C:\\Users\\user-18\\AppData\\Local\\Programs\\Python\\Python312\\Lib\\asyncio\\base_events.py\", line 1992, in _run_once\n    handle._run()\n    ‚îÇ      ‚îî <function Handle._run at 0x0000024BB6C71760>\n    ‚îî <Handle Task.task_wakeup(<Future finished result=None>)>\n  File \"C:\\Users\\user-18\\AppData\\Local\\Programs\\Python\\Python312\\Lib\\asyncio\\events.py\", line 88, in _run\n    self._context.run(self._callback, *self._args)\n    ‚îÇ    ‚îÇ            ‚îÇ    ‚îÇ           ‚îÇ    ‚îî <member '_args' of 'Handle' objects>\n    ‚îÇ    ‚îÇ            ‚îÇ    ‚îÇ           ‚îî <Handle Task.task_wakeup(<Future finished result=None>)>\n    ‚îÇ    ‚îÇ            ‚îÇ    ‚îî <member '_callback' of 'Handle' objects>\n    ‚îÇ    ‚îÇ            ‚îî <Handle Task.task_wakeup(<Future finished result=None>)>\n    ‚îÇ    ‚îî <member '_context' of 'Handle' objects>\n    ‚îî <Handle Task.task_wakeup(<Future finished result=None>)>\n\n  File \"D:\\–ê–°–£–ü\\Python\\Projects\\OwnBot\\db\\database.py\", line 49, in wrapper\n    return await method(*args, session=session, **kwargs)\n                 ‚îÇ       ‚îÇ             ‚îÇ          ‚îî {'telegram_id': 1238658905}\n                 ‚îÇ       ‚îÇ             ‚îî <sqlalchemy.ext.asyncio.session.AsyncSession object at 0x0000024BB8266B70>\n                 ‚îÇ       ‚îî ()\n                 ‚îî <function create_user at 0x0000024BB4748EA0>\n\n> File \"D:\\–ê–°–£–ü\\Python\\Projects\\OwnBot\\db\\db_utils\\user_db_utils.py\", line 15, in create_user\n    await session.commit()\n          ‚îÇ       ‚îî <function AsyncSession.commit at 0x0000024BB7F0F1A0>\n          ‚îî <sqlalchemy.ext.asyncio.session.AsyncSession object at 0x0000024BB8266B70>\n\n  File \"D:\\–ê–°–£–ü\\Python\\Projects\\OwnBot\\venv\\Lib\\site-packages\\sqlalchemy\\ext\\asyncio\\session.py\", line 1009, in commit\n    await greenlet_spawn(self.sync_session.commit)\n          ‚îÇ              ‚îÇ    ‚îÇ            ‚îî <function Session.commit at 0x0000024BB7DFDD00>\n          ‚îÇ              ‚îÇ    ‚îî <sqlalchemy.orm.session.Session object at 0x0000024BB933D6A0>\n          ‚îÇ              ‚îî <sqlalchemy.ext.asyncio.session.AsyncSession object at 0x0000024BB8266B70>\n          ‚îî <function greenlet_spawn at 0x0000024BB6D840E0>\n  File \"D:\\–ê–°–£–ü\\Python\\Projects\\OwnBot\\venv\\Lib\\site-packages\\sqlalchemy\\util\\_concurrency_py3k.py\", line 203, in greenlet_spawn\n    result = context.switch(value)\n             ‚îÇ       ‚îÇ      ‚îî None\n             ‚îÇ       ‚îî <method 'switch' of 'greenlet.greenlet' objects>\n             ‚îî <_AsyncIoGreenlet object at 0x0000024BB94B7280 (otid=0x0000024BB6D2BFC0) dead>\n  File \"D:\\–ê–°–£–ü\\Python\\Projects\\OwnBot\\venv\\Lib\\site-packages\\sqlalchemy\\orm\\session.py\", line 2028, in commit\n    trans.commit(_to_root=True)\n    ‚îÇ     ‚îî <function SessionTransaction.commit at 0x0000024BB7DFCE00>\n    ‚îî <sqlalchemy.orm.session.SessionTransaction object at 0x0000024BB9331510>\n  File \"<string>\", line 2, in commit\n  File \"D:\\–ê–°–£–ü\\Python\\Projects\\OwnBot\\venv\\Lib\\site-packages\\sqlalchemy\\orm\\state_changes.py\", line 139, in _go\n    ret_value = fn(self, *arg, **kw)\n                ‚îÇ  ‚îÇ      ‚îÇ      ‚îî {'_to_root': True}\n                ‚îÇ  ‚îÇ      ‚îî ()\n                ‚îÇ  ‚îî <sqlalchemy.orm.session.SessionTransaction object at 0x0000024BB9331510>\n                ‚îî <function SessionTransaction.commit at 0x0000024BB7DFCC20>\n  File \"D:\\–ê–°–£–ü\\Python\\Projects\\OwnBot\\venv\\Lib\\site-packages\\sqlalchemy\\orm\\session.py\", line 1313, in commit\n    self._prepare_impl()\n    ‚îÇ    ‚îî <function SessionTransaction._prepare_impl at 0x0000024BB7DFCAE0>\n    ‚îî <sqlalchemy.orm.session.SessionTransaction object at 0x0000024BB9331510>\n  File \"<string>\", line 2, in _prepare_impl\n  File \"D:\\–ê–°–£–ü\\Python\\Projects\\OwnBot\\venv\\Lib\\site-packages\\sqlalchemy\\orm\\state_changes.py\", line 139, in _go\n    ret_value = fn(self, *arg, **kw)\n                ‚îÇ  ‚îÇ      ‚îÇ      ‚îî {}\n                ‚îÇ  ‚îÇ      ‚îî ()\n                ‚îÇ  ‚îî <sqlalchemy.orm.session.SessionTransaction object at 0x0000024BB9331510>\n                ‚îî <function SessionTransaction._prepare_impl at 0x0000024BB7DFCA40>\n  File \"D:\\–ê–°–£–ü\\Python\\Projects\\OwnBot\\venv\\Lib\\site-packages\\sqlalchemy\\orm\\session.py\", line 1288, in _prepare_impl\n    self.session.flush()\n    ‚îÇ    ‚îÇ       ‚îî <function Session.flush at 0x0000024BB7E08C20>\n    ‚îÇ    ‚îî <sqlalchemy.orm.session.Session object at 0x0000024BB933D6A0>\n    ‚îî <sqlalchemy.orm.session.SessionTransaction object at 0x0000024BB9331510>\n  File \"D:\\–ê–°–£–ü\\Python\\Projects\\OwnBot\\venv\\Lib\\site-packages\\sqlalchemy\\orm\\session.py\", line 4352, in flush\n    self._flush(objects)\n    ‚îÇ    ‚îÇ      ‚îî None\n    ‚îÇ    ‚îî <function Session._flush at 0x0000024BB7E08E00>\n    ‚îî <sqlalchemy.orm.session.Session object at 0x0000024BB933D6A0>\n  File \"D:\\–ê–°–£–ü\\Python\\Projects\\OwnBot\\venv\\Lib\\site-packages\\sqlalchemy\\orm\\session.py\", line 4487, in _flush\n    with util.safe_reraise():\n         ‚îÇ    ‚îî <class 'sqlalchemy.util.langhelpers.safe_reraise'>\n         ‚îî <module 'sqlalchemy.util' from 'D:\\\\–ê–°–£–ü\\\\Python\\\\Projects\\\\OwnBot\\\\venv\\\\Lib\\\\site-packages\\\\sqlalchemy\\\\util\\\\__init__.py'>\n  File \"D:\\–ê–°–£–ü\\Python\\Projects\\OwnBot\\venv\\Lib\\site-packages\\sqlalchemy\\util\\langhelpers.py\", line 146, in __exit__\n    raise exc_value.with_traceback(exc_tb)\n          ‚îÇ         ‚îÇ              ‚îî <traceback object at 0x0000024BB94A2F00>\n          ‚îÇ         ‚îî <method 'with_traceback' of 'BaseException' objects>\n          ‚îî IntegrityError('(sqlite3.IntegrityError) UNIQUE constraint failed: usermodel.telegram_id')\n  File \"D:\\–ê–°–£–ü\\Python\\Projects\\OwnBot\\venv\\Lib\\site-packages\\sqlalchemy\\orm\\session.py\", line 4448, in _flush\n    flush_context.execute()\n    ‚îÇ             ‚îî <function UOWTransaction.execute at 0x0000024BB7DE9580>\n    ‚îî <sqlalchemy.orm.unitofwork.UOWTransaction object at 0x0000024BB7172BA0>\n  File \"D:\\–ê–°–£–ü\\Python\\Projects\\OwnBot\\venv\\Lib\\site-packages\\sqlalchemy\\orm\\unitofwork.py\", line 466, in execute\n    rec.execute(self)\n    ‚îÇ   ‚îÇ       ‚îî <sqlalchemy.orm.unitofwork.UOWTransaction object at 0x0000024BB7172BA0>\n    ‚îÇ   ‚îî <function SaveUpdateAll.execute at 0x0000024BB7DEA0C0>\n    ‚îî SaveUpdateAll(Mapper[UserModel(usermodel)])\n  File \"D:\\–ê–°–£–ü\\Python\\Projects\\OwnBot\\venv\\Lib\\site-packages\\sqlalchemy\\orm\\unitofwork.py\", line 642, in execute\n    util.preloaded.orm_persistence.save_obj(\n    ‚îÇ    ‚îÇ         ‚îÇ               ‚îî <function save_obj at 0x0000024BB7D9E2A0>\n    ‚îÇ    ‚îÇ         ‚îî <module 'sqlalchemy.orm.persistence' from 'D:\\\\–ê–°–£–ü\\\\Python\\\\Projects\\\\OwnBot\\\\venv\\\\Lib\\\\site-packages\\\\sqlalchemy\\\\orm\\\\per...\n    ‚îÇ    ‚îî <module 'sqlalchemy.util.preloaded' from 'D:\\\\–ê–°–£–ü\\\\Python\\\\Projects\\\\OwnBot\\\\venv\\\\Lib\\\\site-packages\\\\sqlalchemy\\\\util\\\\pre...\n    ‚îî <module 'sqlalchemy.util' from 'D:\\\\–ê–°–£–ü\\\\Python\\\\Projects\\\\OwnBot\\\\venv\\\\Lib\\\\site-packages\\\\sqlalchemy\\\\util\\\\__init__.py'>\n  File \"D:\\–ê–°–£–ü\\Python\\Projects\\OwnBot\\venv\\Lib\\site-packages\\sqlalchemy\\orm\\persistence.py\", line 93, in save_obj\n    _emit_insert_statements(\n    ‚îî <function _emit_insert_statements at 0x0000024BB7DE0680>\n  File \"D:\\–ê–°–£–ü\\Python\\Projects\\OwnBot\\venv\\Lib\\site-packages\\sqlalchemy\\orm\\persistence.py\", line 1233, in _emit_insert_statements\n    result = connection.execute(\n             ‚îÇ          ‚îî <function Connection.execute at 0x0000024BB7AAEE80>\n             ‚îî <sqlalchemy.engine.base.Connection object at 0x0000024BB93D0860>\n  File \"D:\\–ê–°–£–ü\\Python\\Projects\\OwnBot\\venv\\Lib\\site-packages\\sqlalchemy\\engine\\base.py\", line 1418, in execute\n    return meth(\n           ‚îî <bound method ClauseElement._execute_on_connection of <sqlalchemy.sql.dml.Insert object at 0x0000024BB82DECC0>>\n  File \"D:\\–ê–°–£–ü\\Python\\Projects\\OwnBot\\venv\\Lib\\site-packages\\sqlalchemy\\sql\\elements.py\", line 515, in _execute_on_connection\n    return connection._execute_clauseelement(\n           ‚îÇ          ‚îî <function Connection._execute_clauseelement at 0x0000024BB7AAF1A0>\n           ‚îî <sqlalchemy.engine.base.Connection object at 0x0000024BB93D0860>\n  File \"D:\\–ê–°–£–ü\\Python\\Projects\\OwnBot\\venv\\Lib\\site-packages\\sqlalchemy\\engine\\base.py\", line 1640, in _execute_clauseelement\n    ret = self._execute_context(\n          ‚îÇ    ‚îî <function Connection._execute_context at 0x0000024BB7AAF380>\n          ‚îî <sqlalchemy.engine.base.Connection object at 0x0000024BB93D0860>\n  File \"D:\\–ê–°–£–ü\\Python\\Projects\\OwnBot\\venv\\Lib\\site-packages\\sqlalchemy\\engine\\base.py\", line 1846, in _execute_context\n    return self._exec_single_context(\n           ‚îÇ    ‚îî <function Connection._exec_single_context at 0x0000024BB7AAF420>\n           ‚îî <sqlalchemy.engine.base.Connection object at 0x0000024BB93D0860>\n  File \"D:\\–ê–°–£–ü\\Python\\Projects\\OwnBot\\venv\\Lib\\site-packages\\sqlalchemy\\engine\\base.py\", line 1986, in _exec_single_context\n    self._handle_dbapi_exception(\n    ‚îÇ    ‚îî <function Connection._handle_dbapi_exception at 0x0000024BB7AAF6A0>\n    ‚îî <sqlalchemy.engine.base.Connection object at 0x0000024BB93D0860>\n  File \"D:\\–ê–°–£–ü\\Python\\Projects\\OwnBot\\venv\\Lib\\site-packages\\sqlalchemy\\engine\\base.py\", line 2355, in _handle_dbapi_exception\n    raise sqlalchemy_exception.with_traceback(exc_info[2]) from e\n          ‚îÇ                    ‚îÇ              ‚îÇ                 ‚îî IntegrityError('UNIQUE constraint failed: usermodel.telegram_id')\n          ‚îÇ                    ‚îÇ              ‚îî (<class 'sqlite3.IntegrityError'>, IntegrityError('UNIQUE constraint failed: usermodel.telegram_id'), <traceback object at 0x...\n          ‚îÇ                    ‚îî <method 'with_traceback' of 'BaseException' objects>\n          ‚îî IntegrityError('(sqlite3.IntegrityError) UNIQUE constraint failed: usermodel.telegram_id')\n  File \"D:\\–ê–°–£–ü\\Python\\Projects\\OwnBot\\venv\\Lib\\site-packages\\sqlalchemy\\engine\\base.py\", line 1967, in _exec_single_context\n    self.dialect.do_execute(\n    ‚îÇ    ‚îÇ       ‚îî <function DefaultDialect.do_execute at 0x0000024BB7B5DBC0>\n    ‚îÇ    ‚îî <sqlalchemy.dialects.sqlite.aiosqlite.SQLiteDialect_aiosqlite object at 0x0000024BB7C608F0>\n    ‚îî <sqlalchemy.engine.base.Connection object at 0x0000024BB93D0860>\n  File \"D:\\–ê–°–£–ü\\Python\\Projects\\OwnBot\\venv\\Lib\\site-packages\\sqlalchemy\\engine\\default.py\", line 941, in do_execute\n    cursor.execute(statement, parameters)\n    ‚îÇ      ‚îÇ       ‚îÇ          ‚îî (1238658905, None)\n    ‚îÇ      ‚îÇ       ‚îî 'INSERT INTO usermodel (telegram_id, todoist_token) VALUES (?, ?) RETURNING id, created_at, updated_at'\n    ‚îÇ      ‚îî <function AsyncAdapt_aiosqlite_cursor.execute at 0x0000024BB8260A40>\n    ‚îî <sqlalchemy.dialects.sqlite.aiosqlite.AsyncAdapt_aiosqlite_cursor object at 0x0000024BB834AF80>\n  File \"D:\\–ê–°–£–ü\\Python\\Projects\\OwnBot\\venv\\Lib\\site-packages\\sqlalchemy\\dialects\\sqlite\\aiosqlite.py\", line 147, in execute\n    self._adapt_connection._handle_exception(error)\n    ‚îÇ    ‚îî <member '_adapt_connection' of 'AsyncAdapt_aiosqlite_cursor' objects>\n    ‚îî <sqlalchemy.dialects.sqlite.aiosqlite.AsyncAdapt_aiosqlite_cursor object at 0x0000024BB834AF80>\n  File \"D:\\–ê–°–£–ü\\Python\\Projects\\OwnBot\\venv\\Lib\\site-packages\\sqlalchemy\\dialects\\sqlite\\aiosqlite.py\", line 298, in _handle_exception\n    raise error\n          ‚îî IntegrityError('UNIQUE constraint failed: usermodel.telegram_id')\n  File \"D:\\–ê–°–£–ü\\Python\\Projects\\OwnBot\\venv\\Lib\\site-packages\\sqlalchemy\\dialects\\sqlite\\aiosqlite.py\", line 129, in execute\n    self.await_(_cursor.execute(operation, parameters))\n    ‚îÇ    ‚îÇ      ‚îÇ       ‚îÇ       ‚îÇ          ‚îî (1238658905, None)\n    ‚îÇ    ‚îÇ      ‚îÇ       ‚îÇ       ‚îî 'INSERT INTO usermodel (telegram_id, todoist_token) VALUES (?, ?) RETURNING id, created_at, updated_at'\n    ‚îÇ    ‚îÇ      ‚îÇ       ‚îî <function Cursor.execute at 0x0000024BB8342160>\n    ‚îÇ    ‚îÇ      ‚îî <aiosqlite.cursor.Cursor object at 0x0000024BB93F7C20>\n    ‚îÇ    ‚îî <member 'await_' of 'AsyncAdapt_aiosqlite_cursor' objects>\n    ‚îî <sqlalchemy.dialects.sqlite.aiosqlite.AsyncAdapt_aiosqlite_cursor object at 0x0000024BB834AF80>\n  File \"D:\\–ê–°–£–ü\\Python\\Projects\\OwnBot\\venv\\Lib\\site-packages\\sqlalchemy\\util\\_concurrency_py3k.py\", line 132, in await_only\n    return current.parent.switch(awaitable)  # type: ignore[no-any-return,attr-defined] # noqa: E501\n           ‚îÇ       ‚îÇ             ‚îî <coroutine object Cursor.execute at 0x0000024BB94BF3E0>\n           ‚îÇ       ‚îî <attribute 'parent' of 'greenlet.greenlet' objects>\n           ‚îî <_AsyncIoGreenlet object at 0x0000024BB94B7280 (otid=0x0000024BB6D2BFC0) dead>\n  File \"D:\\–ê–°–£–ü\\Python\\Projects\\OwnBot\\venv\\Lib\\site-packages\\sqlalchemy\\util\\_concurrency_py3k.py\", line 196, in greenlet_spawn\n    value = await result\n                  ‚îî <coroutine object Connection.rollback at 0x0000024BB94EC580>\n  File \"D:\\–ê–°–£–ü\\Python\\Projects\\OwnBot\\venv\\Lib\\site-packages\\aiosqlite\\cursor.py\", line 48, in execute\n    await self._execute(self._cursor.execute, sql, parameters)\n          ‚îÇ    ‚îÇ        ‚îÇ    ‚îÇ       ‚îÇ        ‚îÇ    ‚îî (1238658905, None)\n          ‚îÇ    ‚îÇ        ‚îÇ    ‚îÇ       ‚îÇ        ‚îî 'INSERT INTO usermodel (telegram_id, todoist_token) VALUES (?, ?) RETURNING id, created_at, updated_at'\n          ‚îÇ    ‚îÇ        ‚îÇ    ‚îÇ       ‚îî <method 'execute' of 'sqlite3.Cursor' objects>\n          ‚îÇ    ‚îÇ        ‚îÇ    ‚îî <sqlite3.Cursor object at 0x0000024BB9350EC0>\n          ‚îÇ    ‚îÇ        ‚îî <aiosqlite.cursor.Cursor object at 0x0000024BB93F7C20>\n          ‚îÇ    ‚îî <function Cursor._execute at 0x0000024BB83420C0>\n          ‚îî <aiosqlite.cursor.Cursor object at 0x0000024BB93F7C20>\n  File \"D:\\–ê–°–£–ü\\Python\\Projects\\OwnBot\\venv\\Lib\\site-packages\\aiosqlite\\cursor.py\", line 40, in _execute\n    return await self._conn._execute(fn, *args, **kwargs)\n                 ‚îÇ    ‚îÇ     ‚îÇ        ‚îÇ    ‚îÇ       ‚îî {}\n                 ‚îÇ    ‚îÇ     ‚îÇ        ‚îÇ    ‚îî ('INSERT INTO usermodel (telegram_id, todoist_token) VALUES (?, ?) RETURNING id, created_at, updated_at', (1238658905, None))\n                 ‚îÇ    ‚îÇ     ‚îÇ        ‚îî <built-in method execute of sqlite3.Cursor object at 0x0000024BB9350EC0>\n                 ‚îÇ    ‚îÇ     ‚îî <function Connection._execute at 0x0000024BB8343380>\n                 ‚îÇ    ‚îî <Connection(Thread-1, stopped daemon 11636)>\n                 ‚îî <aiosqlite.cursor.Cursor object at 0x0000024BB93F7C20>\n  File \"D:\\–ê–°–£–ü\\Python\\Projects\\OwnBot\\venv\\Lib\\site-packages\\aiosqlite\\core.py\", line 132, in _execute\n    return await future\n                 ‚îî <Future finished exception=IntegrityError('UNIQUE constraint failed: usermodel.telegram_id')>\n  File \"D:\\–ê–°–£–ü\\Python\\Projects\\OwnBot\\venv\\Lib\\site-packages\\aiosqlite\\core.py\", line 115, in run\n    result = function()\n             ‚îî functools.partial(<built-in method close of sqlite3.Connection object at 0x0000024BB950B100>)\n\nsqlalchemy.exc.IntegrityError: (sqlite3.IntegrityError) UNIQUE constraint failed: usermodel.telegram_id\n[SQL: INSERT INTO usermodel (telegram_id, todoist_token) VALUES (?, ?) RETURNING id, created_at, updated_at]\n[parameters: (1238658905, None)]\n(Background on this error at: https://sqlalche.me/e/20/gkpj)\n", "record": {"elapsed": {"repr": "0:00:00.026946", "seconds": 0.026946}, "exception": {"type": "IntegrityError", "value": "(sqlite3.IntegrityError) UNIQUE constraint failed: usermodel.telegram_id\n[SQL: INSERT INTO usermodel (telegram_id, todoist_token) VALUES (?, ?) RETURNING id, created_at, updated_at]\n[parameters: (1238658905, None)]\n(Background on this error at: https://sqlalche.me/e/20/gkpj)", "traceback": true}, "extra": {}, "file": {"name": "user_db_utils.py", "path": "D:\\–ê–°–£–ü\\Python\\Projects\\OwnBot\\db\\db_utils\\user_db_utils.py"}, "function": "create_user", "level": {"icon": "‚ùå", "name": "ERROR", "no": 40}, "line": 20, "message": "(sqlite3.IntegrityError) UNIQUE constraint failed: usermodel.telegram_id\n[SQL: INSERT INTO usermodel (telegram_id, todoist_token) VALUES (?, ?) RETURNING id, created_at, updated_at]\n[parameters: (1238658905, None)]\n(Background on this error at: https://sqlalche.me/e/20/gkpj)", "module": "user_db_utils", "name": "__main__", "process": {"id": 4796, "name": "MainProcess"}, "thread": {"id": 32, "name": "MainThread"}, "time": {"repr": "2024-12-19 09:41:11.972183+06:00", "timestamp": 1734579671.972183}}}
{"text": "2024-12-19 09:44:57.697 | ERROR    | __main__:create_user:19 - –û—à–∏–±–∫–∞ –∑–∞–ø–∏—Å–∏ –≤ –ë–î –¥–ª—è 1238658905\n", "record": {"elapsed": {"repr": "0:00:00.025970", "seconds": 0.02597}, "exception": null, "extra": {"exc_info": true}, "file": {"name": "user_db_utils.py", "path": "D:\\–ê–°–£–ü\\Python\\Projects\\OwnBot\\db\\db_utils\\user_db_utils.py"}, "function": "create_user", "level": {"icon": "‚ùå", "name": "ERROR", "no": 40}, "line": 19, "message": "–û—à–∏–±–∫–∞ –∑–∞–ø–∏—Å–∏ –≤ –ë–î –¥–ª—è 1238658905", "module": "user_db_utils", "name": "__main__", "process": {"id": 10780, "name": "MainProcess"}, "thread": {"id": 12612, "name": "MainThread"}, "time": {"repr": "2024-12-19 09:44:57.697069+06:00", "timestamp": 1734579897.697069}}}
{"text": "2024-12-19 09:45:43.052 | DEBUG    | __main__:<module>:74 - Starting\n", "record": {"elapsed": {"repr": "0:00:00.414412", "seconds": 0.414412}, "exception": null, "extra": {}, "file": {"name": "user.py", "path": "D:\\–ê–°–£–ü\\Python\\Projects\\OwnBot\\classes\\user.py"}, "function": "<module>", "level": {"icon": "üêû", "name": "DEBUG", "no": 10}, "line": 74, "message": "Starting", "module": "user", "name": "__main__", "process": {"id": 13320, "name": "MainProcess"}, "thread": {"id": 11988, "name": "MainThread"}, "time": {"repr": "2024-12-19 09:45:43.052516+06:00", "timestamp": 1734579943.052516}}}
{"text": "2024-12-19 09:45:49.114 | ERROR    | __main__:create_user:19 - –û—à–∏–±–∫–∞ –∑–∞–ø–∏—Å–∏ –≤ –ë–î –¥–ª—è 1238658905\n", "record": {"elapsed": {"repr": "0:00:00.027000", "seconds": 0.027}, "exception": null, "extra": {"exc_info": true}, "file": {"name": "user_db_utils.py", "path": "D:\\–ê–°–£–ü\\Python\\Projects\\OwnBot\\db\\db_utils\\user_db_utils.py"}, "function": "create_user", "level": {"icon": "‚ùå", "name": "ERROR", "no": 40}, "line": 19, "message": "–û—à–∏–±–∫–∞ –∑–∞–ø–∏—Å–∏ –≤ –ë–î –¥–ª—è 1238658905", "module": "user_db_utils", "name": "__main__", "process": {"id": 3880, "name": "MainProcess"}, "thread": {"id": 9240, "name": "MainThread"}, "time": {"repr": "2024-12-19 09:45:49.114639+06:00", "timestamp": 1734579949.114639}}}
{"text": "2024-12-19 09:49:41.886 | ERROR    | __main__:create_user:19 - –û—à–∏–±–∫–∞ –∑–∞–ø–∏—Å–∏ –≤ –ë–î –¥–ª—è 1238658905\n", "record": {"elapsed": {"repr": "0:00:00.026997", "seconds": 0.026997}, "exception": null, "extra": {"exc_info": "(sqlite3.IntegrityError) UNIQUE constraint failed: usermodel.telegram_id\n[SQL: INSERT INTO usermodel (telegram_id, todoist_token) VALUES (?, ?) RETURNING id, created_at, updated_at]\n[parameters: (1238658905, None)]\n(Background on this error at: https://sqlalche.me/e/20/gkpj)"}, "file": {"name": "user_db_utils.py", "path": "D:\\–ê–°–£–ü\\Python\\Projects\\OwnBot\\db\\db_utils\\user_db_utils.py"}, "function": "create_user", "level": {"icon": "‚ùå", "name": "ERROR", "no": 40}, "line": 19, "message": "–û—à–∏–±–∫–∞ –∑–∞–ø–∏—Å–∏ –≤ –ë–î –¥–ª—è 1238658905", "module": "user_db_utils", "name": "__main__", "process": {"id": 9752, "name": "MainProcess"}, "thread": {"id": 5764, "name": "MainThread"}, "time": {"repr": "2024-12-19 09:49:41.886493+06:00", "timestamp": 1734580181.886493}}}
{"text": "2024-12-19 09:53:07.287 | ERROR    | __main__:create_user:20 - –û—à–∏–±–∫–∞ –∑–∞–ø–∏—Å–∏ –≤ –ë–î –¥–ª—è 1238658905\n", "record": {"elapsed": {"repr": "0:00:00.027444", "seconds": 0.027444}, "exception": null, "extra": {"exc_info": "(sqlite3.IntegrityError) UNIQUE constraint failed: usermodel.telegram_id\n[SQL: INSERT INTO usermodel (telegram_id, todoist_token) VALUES (?, ?) RETURNING id, created_at, updated_at]\n[parameters: (1238658905, None)]\n(Background on this error at: https://sqlalche.me/e/20/gkpj)"}, "file": {"name": "user_db_utils.py", "path": "D:\\–ê–°–£–ü\\Python\\Projects\\OwnBot\\db\\db_utils\\user_db_utils.py"}, "function": "create_user", "level": {"icon": "‚ùå", "name": "ERROR", "no": 40}, "line": 20, "message": "–û—à–∏–±–∫–∞ –∑–∞–ø–∏—Å–∏ –≤ –ë–î –¥–ª—è 1238658905", "module": "user_db_utils", "name": "__main__", "process": {"id": 4464, "name": "MainProcess"}, "thread": {"id": 12340, "name": "MainThread"}, "time": {"repr": "2024-12-19 09:53:07.287912+06:00", "timestamp": 1734580387.287912}}}
{"text": "2024-12-19 09:55:13.198 | ERROR    | __main__:create_user:22 - –û—à–∏–±–∫–∞ –∑–∞–ø–∏—Å–∏ –≤ –ë–î –¥–ª—è 1238658905\n", "record": {"elapsed": {"repr": "0:00:00.027000", "seconds": 0.027}, "exception": null, "extra": {"exc_info": "(sqlite3.IntegrityError) UNIQUE constraint failed: usermodel.telegram_id\n[SQL: INSERT INTO usermodel (telegram_id, todoist_token) VALUES (?, ?) RETURNING id, created_at, updated_at]\n[parameters: (1238658905, None)]\n(Background on this error at: https://sqlalche.me/e/20/gkpj)"}, "file": {"name": "user_db_utils.py", "path": "D:\\–ê–°–£–ü\\Python\\Projects\\OwnBot\\db\\db_utils\\user_db_utils.py"}, "function": "create_user", "level": {"icon": "‚ùå", "name": "ERROR", "no": 40}, "line": 22, "message": "–û—à–∏–±–∫–∞ –∑–∞–ø–∏—Å–∏ –≤ –ë–î –¥–ª—è 1238658905", "module": "user_db_utils", "name": "__main__", "process": {"id": 6872, "name": "MainProcess"}, "thread": {"id": 3848, "name": "MainThread"}, "time": {"repr": "2024-12-19 09:55:13.198727+06:00", "timestamp": 1734580513.198727}}}
{"text": "2024-12-19 09:57:33.236 | ERROR    | __main__:create_user:22 - –û—à–∏–±–∫–∞ –∑–∞–ø–∏—Å–∏ –≤ –ë–î –¥–ª—è 1238658905\n", "record": {"elapsed": {"repr": "0:00:00.026002", "seconds": 0.026002}, "exception": null, "extra": {"exc_info": "(sqlite3.IntegrityError) UNIQUE constraint failed: usermodel.telegram_id\n[SQL: INSERT INTO usermodel (telegram_id, todoist_token) VALUES (?, ?) RETURNING id, created_at, updated_at]\n[parameters: (1238658905, None)]\n(Background on this error at: https://sqlalche.me/e/20/gkpj)"}, "file": {"name": "user_db_utils.py", "path": "D:\\–ê–°–£–ü\\Python\\Projects\\OwnBot\\db\\db_utils\\user_db_utils.py"}, "function": "create_user", "level": {"icon": "‚ùå", "name": "ERROR", "no": 40}, "line": 22, "message": "–û—à–∏–±–∫–∞ –∑–∞–ø–∏—Å–∏ –≤ –ë–î –¥–ª—è 1238658905", "module": "user_db_utils", "name": "__main__", "process": {"id": 12060, "name": "MainProcess"}, "thread": {"id": 13740, "name": "MainThread"}, "time": {"repr": "2024-12-19 09:57:33.236810+06:00", "timestamp": 1734580653.23681}}}
{"text": "2024-12-19 09:59:42.022 | ERROR    | __main__:create_user:22 - –û—à–∏–±–∫–∞ –∑–∞–ø–∏—Å–∏ –≤ –ë–î –¥–ª—è 1238658905\n", "record": {"elapsed": {"repr": "0:00:00.026787", "seconds": 0.026787}, "exception": null, "extra": {"exc_info": "(sqlite3.IntegrityError) UNIQUE constraint failed: usermodel.telegram_id\n[SQL: INSERT INTO usermodel (telegram_id, todoist_token) VALUES (?, ?) RETURNING id, created_at, updated_at]\n[parameters: (1238658905, None)]\n(Background on this error at: https://sqlalche.me/e/20/gkpj)"}, "file": {"name": "user_db_utils.py", "path": "D:\\–ê–°–£–ü\\Python\\Projects\\OwnBot\\db\\db_utils\\user_db_utils.py"}, "function": "create_user", "level": {"icon": "‚ùå", "name": "ERROR", "no": 40}, "line": 22, "message": "–û—à–∏–±–∫–∞ –∑–∞–ø–∏—Å–∏ –≤ –ë–î –¥–ª—è 1238658905", "module": "user_db_utils", "name": "__main__", "process": {"id": 1156, "name": "MainProcess"}, "thread": {"id": 13328, "name": "MainThread"}, "time": {"repr": "2024-12-19 09:59:42.022541+06:00", "timestamp": 1734580782.022541}}}
{"text": "2024-12-19 10:00:17.137 | ERROR    | __main__:create_user:22 - –û—à–∏–±–∫–∞ –∑–∞–ø–∏—Å–∏ –≤ –ë–î –¥–ª—è 1238658905\n", "record": {"elapsed": {"repr": "0:00:00.027004", "seconds": 0.027004}, "exception": null, "extra": {"exc_info": "(sqlite3.IntegrityError) UNIQUE constraint failed: usermodel.telegram_id\n[SQL: INSERT INTO usermodel (telegram_id, todoist_token) VALUES (?, ?) RETURNING id, created_at, updated_at]\n[parameters: (1238658905, None)]\n(Background on this error at: https://sqlalche.me/e/20/gkpj)"}, "file": {"name": "user_db_utils.py", "path": "D:\\–ê–°–£–ü\\Python\\Projects\\OwnBot\\db\\db_utils\\user_db_utils.py"}, "function": "create_user", "level": {"icon": "‚ùå", "name": "ERROR", "no": 40}, "line": 22, "message": "–û—à–∏–±–∫–∞ –∑–∞–ø–∏—Å–∏ –≤ –ë–î –¥–ª—è 1238658905", "module": "user_db_utils", "name": "__main__", "process": {"id": 3132, "name": "MainProcess"}, "thread": {"id": 15200, "name": "MainThread"}, "time": {"repr": "2024-12-19 10:00:17.137851+06:00", "timestamp": 1734580817.137851}}}
{"text": "2024-12-19 10:00:51.691 | ERROR    | __main__:create_user:22 - –û—à–∏–±–∫–∞ –∑–∞–ø–∏—Å–∏ –≤ –ë–î –¥–ª—è 1238658905\n", "record": {"elapsed": {"repr": "0:00:00.026004", "seconds": 0.026004}, "exception": null, "extra": {"exc_info": "(sqlite3.IntegrityError) UNIQUE constraint failed: usermodel.telegram_id\n[SQL: INSERT INTO usermodel (telegram_id, todoist_token) VALUES (?, ?) RETURNING id, created_at, updated_at]\n[parameters: (1238658905, None)]\n(Background on this error at: https://sqlalche.me/e/20/gkpj)"}, "file": {"name": "user_db_utils.py", "path": "D:\\–ê–°–£–ü\\Python\\Projects\\OwnBot\\db\\db_utils\\user_db_utils.py"}, "function": "create_user", "level": {"icon": "‚ùå", "name": "ERROR", "no": 40}, "line": 22, "message": "–û—à–∏–±–∫–∞ –∑–∞–ø–∏—Å–∏ –≤ –ë–î –¥–ª—è 1238658905", "module": "user_db_utils", "name": "__main__", "process": {"id": 8044, "name": "MainProcess"}, "thread": {"id": 15984, "name": "MainThread"}, "time": {"repr": "2024-12-19 10:00:51.691716+06:00", "timestamp": 1734580851.691716}}}
{"text": "2024-12-19 10:01:17.224 | ERROR    | __main__:create_user:22 - –û—à–∏–±–∫–∞ –∑–∞–ø–∏—Å–∏ –≤ –ë–î –¥–ª—è 1238658905\n", "record": {"elapsed": {"repr": "0:00:00.026999", "seconds": 0.026999}, "exception": null, "extra": {"exc_info": "(sqlite3.IntegrityError) UNIQUE constraint failed: usermodel.telegram_id\n[SQL: INSERT INTO usermodel (telegram_id, todoist_token) VALUES (?, ?) RETURNING id, created_at, updated_at]\n[parameters: (1238658905, None)]\n(Background on this error at: https://sqlalche.me/e/20/gkpj)"}, "file": {"name": "user_db_utils.py", "path": "D:\\–ê–°–£–ü\\Python\\Projects\\OwnBot\\db\\db_utils\\user_db_utils.py"}, "function": "create_user", "level": {"icon": "‚ùå", "name": "ERROR", "no": 40}, "line": 22, "message": "–û—à–∏–±–∫–∞ –∑–∞–ø–∏—Å–∏ –≤ –ë–î –¥–ª—è 1238658905", "module": "user_db_utils", "name": "__main__", "process": {"id": 14668, "name": "MainProcess"}, "thread": {"id": 9764, "name": "MainThread"}, "time": {"repr": "2024-12-19 10:01:17.224028+06:00", "timestamp": 1734580877.224028}}}
{"text": "2024-12-19 10:01:33.309 | ERROR    | __main__:create_user:22 - –û—à–∏–±–∫–∞ –∑–∞–ø–∏—Å–∏ –≤ –ë–î –¥–ª—è 1238658905\n", "record": {"elapsed": {"repr": "0:00:00.027001", "seconds": 0.027001}, "exception": null, "extra": {"exc_info": "(sqlite3.IntegrityError) UNIQUE constraint failed: usermodel.telegram_id\n[SQL: INSERT INTO usermodel (telegram_id, todoist_token) VALUES (?, ?) RETURNING id, created_at, updated_at]\n[parameters: (1238658905, None)]\n(Background on this error at: https://sqlalche.me/e/20/gkpj)"}, "file": {"name": "user_db_utils.py", "path": "D:\\–ê–°–£–ü\\Python\\Projects\\OwnBot\\db\\db_utils\\user_db_utils.py"}, "function": "create_user", "level": {"icon": "‚ùå", "name": "ERROR", "no": 40}, "line": 22, "message": "–û—à–∏–±–∫–∞ –∑–∞–ø–∏—Å–∏ –≤ –ë–î –¥–ª—è 1238658905", "module": "user_db_utils", "name": "__main__", "process": {"id": 1912, "name": "MainProcess"}, "thread": {"id": 4056, "name": "MainThread"}, "time": {"repr": "2024-12-19 10:01:33.309049+06:00", "timestamp": 1734580893.309049}}}
{"text": "2024-12-19 10:07:07.945 | ERROR    | __main__:create_user:21 - –û—à–∏–±–∫–∞ –∑–∞–ø–∏—Å–∏ –≤ –ë–î —É–∂–µ —Å—É—â–µ—Å—Ç–≤—É—é—â–µ–≥–æ –ø–æ–ª—å–∑–æ–≤–∞—Ç–µ–ª—è –¥–ª—è 1238658905\n", "record": {"elapsed": {"repr": "0:00:00.026995", "seconds": 0.026995}, "exception": null, "extra": {"exc_info": "(sqlite3.IntegrityError) UNIQUE constraint failed: usermodel.telegram_id\n[SQL: INSERT INTO usermodel (telegram_id, todoist_token) VALUES (?, ?) RETURNING id, created_at, updated_at]\n[parameters: (1238658905, None)]\n(Background on this error at: https://sqlalche.me/e/20/gkpj)"}, "file": {"name": "user_db_utils.py", "path": "D:\\–ê–°–£–ü\\Python\\Projects\\OwnBot\\db\\db_utils\\user_db_utils.py"}, "function": "create_user", "level": {"icon": "‚ùå", "name": "ERROR", "no": 40}, "line": 21, "message": "–û—à–∏–±–∫–∞ –∑–∞–ø–∏—Å–∏ –≤ –ë–î —É–∂–µ —Å—É—â–µ—Å—Ç–≤—É—é—â–µ–≥–æ –ø–æ–ª—å–∑–æ–≤–∞—Ç–µ–ª—è –¥–ª—è 1238658905", "module": "user_db_utils", "name": "__main__", "process": {"id": 6388, "name": "MainProcess"}, "thread": {"id": 12284, "name": "MainThread"}, "time": {"repr": "2024-12-19 10:07:07.945177+06:00", "timestamp": 1734581227.945177}}}
{"text": "2024-12-19 11:12:13.657 | ERROR    | __main__:get_todoist_data:51 - –û—à–∏–±–∫–∞ –≤ completed_tasks_get\n", "record": {"elapsed": {"repr": "0:00:04.725381", "seconds": 4.725381}, "exception": null, "extra": {"exc_info": "too many values to unpack (expected 2)"}, "file": {"name": "save_todoist_data.py", "path": "D:\\–ê–°–£–ü\\Python\\Projects\\OwnBot\\todoist_api\\save_todoist_data.py"}, "function": "get_todoist_data", "level": {"icon": "‚ùå", "name": "ERROR", "no": 40}, "line": 51, "message": "–û—à–∏–±–∫–∞ –≤ completed_tasks_get", "module": "save_todoist_data", "name": "__main__", "process": {"id": 14176, "name": "MainProcess"}, "thread": {"id": 3520, "name": "MainThread"}, "time": {"repr": "2024-12-19 11:12:13.657384+06:00", "timestamp": 1734585133.657384}}}
{"text": "2024-12-19 11:13:07.160 | ERROR    | __main__:get_todoist_data:51 - –û—à–∏–±–∫–∞ –≤ completed_tasks_get\n", "record": {"elapsed": {"repr": "0:00:00.754775", "seconds": 0.754775}, "exception": null, "extra": {"exc_info": "too many values to unpack (expected 2)"}, "file": {"name": "save_todoist_data.py", "path": "D:\\–ê–°–£–ü\\Python\\Projects\\OwnBot\\todoist_api\\save_todoist_data.py"}, "function": "get_todoist_data", "level": {"icon": "‚ùå", "name": "ERROR", "no": 40}, "line": 51, "message": "–û—à–∏–±–∫–∞ –≤ completed_tasks_get", "module": "save_todoist_data", "name": "__main__", "process": {"id": 15648, "name": "MainProcess"}, "thread": {"id": 7936, "name": "MainThread"}, "time": {"repr": "2024-12-19 11:13:07.160744+06:00", "timestamp": 1734585187.160744}}}
{"text": "2024-12-19 11:13:07.160 | ERROR    | __main__:get_todoist_data:52 - too many values to unpack (expected 2)\nTraceback (most recent call last):\n\n  File \"D:\\–ê–°–£–ü\\Python\\Projects\\OwnBot\\todoist_api\\save_todoist_data.py\", line 59, in <module>\n    get_todoist_data(token='48cbdb22977eb9d84368aef673d3c7ba7c0f311a')\n    ‚îî <function get_todoist_data at 0x0000019687208EA0>\n\n> File \"D:\\–ê–°–£–ü\\Python\\Projects\\OwnBot\\todoist_api\\save_todoist_data.py\", line 29, in get_todoist_data\n    for task_id, completed_at in response_result['items']])\n                                 ‚îî {'items': [{'completed_at': '2024-12-19T02:15:30.000000Z', 'content': 'Med', 'id': '7912036814', 'item_object': None, 'meta_d...\n\nValueError: too many values to unpack (expected 2)\n", "record": {"elapsed": {"repr": "0:00:00.754775", "seconds": 0.754775}, "exception": {"type": "ValueError", "value": "too many values to unpack (expected 2)", "traceback": true}, "extra": {}, "file": {"name": "save_todoist_data.py", "path": "D:\\–ê–°–£–ü\\Python\\Projects\\OwnBot\\todoist_api\\save_todoist_data.py"}, "function": "get_todoist_data", "level": {"icon": "‚ùå", "name": "ERROR", "no": 40}, "line": 52, "message": "too many values to unpack (expected 2)", "module": "save_todoist_data", "name": "__main__", "process": {"id": 15648, "name": "MainProcess"}, "thread": {"id": 7936, "name": "MainThread"}, "time": {"repr": "2024-12-19 11:13:07.160744+06:00", "timestamp": 1734585187.160744}}}
{"text": "2024-12-19 11:25:53.743 | ERROR    | __main__:get_todoist_data:51 - –û—à–∏–±–∫–∞ –≤ completed_tasks_get\n", "record": {"elapsed": {"repr": "0:00:00.932091", "seconds": 0.932091}, "exception": null, "extra": {"exc_info": "400 Client Error: Bad Request for url: https://api.todoist.com/sync/v9/archive/items"}, "file": {"name": "save_todoist_data.py", "path": "D:\\–ê–°–£–ü\\Python\\Projects\\OwnBot\\todoist_api\\save_todoist_data.py"}, "function": "get_todoist_data", "level": {"icon": "‚ùå", "name": "ERROR", "no": 40}, "line": 51, "message": "–û—à–∏–±–∫–∞ –≤ completed_tasks_get", "module": "save_todoist_data", "name": "__main__", "process": {"id": 13512, "name": "MainProcess"}, "thread": {"id": 13496, "name": "MainThread"}, "time": {"repr": "2024-12-19 11:25:53.743572+06:00", "timestamp": 1734585953.743572}}}
{"text": "2024-12-19 11:25:53.743 | ERROR    | __main__:get_todoist_data:52 - 400 Client Error: Bad Request for url: https://api.todoist.com/sync/v9/archive/items\nTraceback (most recent call last):\n\n  File \"D:\\–ê–°–£–ü\\Python\\Projects\\OwnBot\\todoist_api\\save_todoist_data.py\", line 56, in <module>\n    get_todoist_data(token='48cbdb22977eb9d84368aef673d3c7ba7c0f311a')\n    ‚îî <function get_todoist_data at 0x0000023A9E718EA0>\n\n> File \"D:\\–ê–°–£–ü\\Python\\Projects\\OwnBot\\todoist_api\\save_todoist_data.py\", line 30, in get_todoist_data\n    pprint(api.get_completed_items())\n    ‚îÇ      ‚îÇ   ‚îî <function TodoistAPI.get_completed_items at 0x0000023AA0D76980>\n    ‚îÇ      ‚îî <todoist_api_python.api.TodoistAPI object at 0x0000023A9E73FE90>\n    ‚îî <function pprint at 0x0000023A9E71BA60>\n\n  File \"D:\\–ê–°–£–ü\\Python\\Projects\\OwnBot\\venv\\Lib\\site-packages\\todoist_api_python\\api.py\", line 231, in get_completed_items\n    completed_items = get(\n                      ‚îî <function get at 0x0000023AA0C15760>\n  File \"D:\\–ê–°–£–ü\\Python\\Projects\\OwnBot\\venv\\Lib\\site-packages\\todoist_api_python\\http_requests.py\", line 23, in get\n    response.raise_for_status()\n    ‚îÇ        ‚îî <function Response.raise_for_status at 0x0000023AA0BF7420>\n    ‚îî <Response [400]>\n  File \"D:\\–ê–°–£–ü\\Python\\Projects\\OwnBot\\venv\\Lib\\site-packages\\requests\\models.py\", line 1024, in raise_for_status\n    raise HTTPError(http_error_msg, response=self)\n          ‚îÇ         ‚îÇ                        ‚îî <Response [400]>\n          ‚îÇ         ‚îî '400 Client Error: Bad Request for url: https://api.todoist.com/sync/v9/archive/items'\n          ‚îî <class 'requests.exceptions.HTTPError'>\n\nrequests.exceptions.HTTPError: 400 Client Error: Bad Request for url: https://api.todoist.com/sync/v9/archive/items\n", "record": {"elapsed": {"repr": "0:00:00.932091", "seconds": 0.932091}, "exception": {"type": "HTTPError", "value": "400 Client Error: Bad Request for url: https://api.todoist.com/sync/v9/archive/items", "traceback": true}, "extra": {}, "file": {"name": "save_todoist_data.py", "path": "D:\\–ê–°–£–ü\\Python\\Projects\\OwnBot\\todoist_api\\save_todoist_data.py"}, "function": "get_todoist_data", "level": {"icon": "‚ùå", "name": "ERROR", "no": 40}, "line": 52, "message": "400 Client Error: Bad Request for url: https://api.todoist.com/sync/v9/archive/items", "module": "save_todoist_data", "name": "__main__", "process": {"id": 13512, "name": "MainProcess"}, "thread": {"id": 13496, "name": "MainThread"}, "time": {"repr": "2024-12-19 11:25:53.743572+06:00", "timestamp": 1734585953.743572}}}
{"text": "2024-12-19 11:36:38.459 | ERROR    | __main__:get_todoist_data:69 - –û—à–∏–±–∫–∞ –≤ completed_tasks_get\n", "record": {"elapsed": {"repr": "0:00:05.027375", "seconds": 5.027375}, "exception": null, "extra": {"exc_info": "400 Client Error: Bad Request for url: https://api.todoist.com/sync/v9/archive/items?project_id=project_id&project_id=limit"}, "file": {"name": "save_todoist_data.py", "path": "D:\\–ê–°–£–ü\\Python\\Projects\\OwnBot\\todoist_api\\save_todoist_data.py"}, "function": "get_todoist_data", "level": {"icon": "‚ùå", "name": "ERROR", "no": 40}, "line": 69, "message": "–û—à–∏–±–∫–∞ –≤ completed_tasks_get", "module": "save_todoist_data", "name": "__main__", "process": {"id": 10112, "name": "MainProcess"}, "thread": {"id": 10124, "name": "MainThread"}, "time": {"repr": "2024-12-19 11:36:38.459193+06:00", "timestamp": 1734586598.459193}}}
{"text": "2024-12-19 11:36:38.459 | ERROR    | __main__:get_todoist_data:70 - 400 Client Error: Bad Request for url: https://api.todoist.com/sync/v9/archive/items?project_id=project_id&project_id=limit\nTraceback (most recent call last):\n\n  File \"D:\\–ê–°–£–ü\\Python\\Projects\\OwnBot\\todoist_api\\save_todoist_data.py\", line 74, in <module>\n    get_todoist_data(token='48cbdb22977eb9d84368aef673d3c7ba7c0f311a')\n    ‚îî <function get_todoist_data at 0x000001E5FEFA9BC0>\n\n> File \"D:\\–ê–°–£–ü\\Python\\Projects\\OwnBot\\todoist_api\\save_todoist_data.py\", line 38, in get_todoist_data\n    response = api.get_completed_items({\"project_id\": project.id} | {\"limit\": 100})\n               ‚îÇ   ‚îÇ                                  ‚îÇ       ‚îî '2303388551'\n               ‚îÇ   ‚îÇ                                  ‚îî Project(color='grey', comment_count=0, id='2303388551', is_favorite=False, is_inbox_project=True, is_shared=False, is_team_in...\n               ‚îÇ   ‚îî <function TodoistAPI.get_completed_items at 0x000001E5816F2A20>\n               ‚îî <todoist_api_python.api.TodoistAPI object at 0x000001E5FF01C2F0>\n\n  File \"D:\\–ê–°–£–ü\\Python\\Projects\\OwnBot\\venv\\Lib\\site-packages\\todoist_api_python\\api.py\", line 231, in get_completed_items\n    completed_items = get(\n                      ‚îî <function get at 0x000001E581595800>\n  File \"D:\\–ê–°–£–ü\\Python\\Projects\\OwnBot\\venv\\Lib\\site-packages\\todoist_api_python\\http_requests.py\", line 23, in get\n    response.raise_for_status()\n    ‚îÇ        ‚îî <function Response.raise_for_status at 0x000001E5815774C0>\n    ‚îî <Response [400]>\n  File \"D:\\–ê–°–£–ü\\Python\\Projects\\OwnBot\\venv\\Lib\\site-packages\\requests\\models.py\", line 1024, in raise_for_status\n    raise HTTPError(http_error_msg, response=self)\n          ‚îÇ         ‚îÇ                        ‚îî <Response [400]>\n          ‚îÇ         ‚îî '400 Client Error: Bad Request for url: https://api.todoist.com/sync/v9/archive/items?project_id=project_id&project_id=limit'\n          ‚îî <class 'requests.exceptions.HTTPError'>\n\nrequests.exceptions.HTTPError: 400 Client Error: Bad Request for url: https://api.todoist.com/sync/v9/archive/items?project_id=project_id&project_id=limit\n", "record": {"elapsed": {"repr": "0:00:05.027375", "seconds": 5.027375}, "exception": {"type": "HTTPError", "value": "400 Client Error: Bad Request for url: https://api.todoist.com/sync/v9/archive/items?project_id=project_id&project_id=limit", "traceback": true}, "extra": {}, "file": {"name": "save_todoist_data.py", "path": "D:\\–ê–°–£–ü\\Python\\Projects\\OwnBot\\todoist_api\\save_todoist_data.py"}, "function": "get_todoist_data", "level": {"icon": "‚ùå", "name": "ERROR", "no": 40}, "line": 70, "message": "400 Client Error: Bad Request for url: https://api.todoist.com/sync/v9/archive/items?project_id=project_id&project_id=limit", "module": "save_todoist_data", "name": "__main__", "process": {"id": 10112, "name": "MainProcess"}, "thread": {"id": 10124, "name": "MainThread"}, "time": {"repr": "2024-12-19 11:36:38.459193+06:00", "timestamp": 1734586598.459193}}}
{"text": "2024-12-19 13:25:33.547 | ERROR    | __main__:get_todoist_data:81 - –û—à–∏–±–∫–∞ –≤ completed_tasks_get\n", "record": {"elapsed": {"repr": "0:00:11.388353", "seconds": 11.388353}, "exception": null, "extra": {"exc_info": "name 'items' is not defined"}, "file": {"name": "save_todoist_data.py", "path": "D:\\–ê–°–£–ü\\Python\\Projects\\OwnBot\\todoist_api\\save_todoist_data.py"}, "function": "get_todoist_data", "level": {"icon": "‚ùå", "name": "ERROR", "no": 40}, "line": 81, "message": "–û—à–∏–±–∫–∞ –≤ completed_tasks_get", "module": "save_todoist_data", "name": "__main__", "process": {"id": 8244, "name": "MainProcess"}, "thread": {"id": 13732, "name": "MainThread"}, "time": {"repr": "2024-12-19 13:25:33.547838+06:00", "timestamp": 1734593133.547838}}}
{"text": "2024-12-19 13:25:33.547 | ERROR    | __main__:get_todoist_data:82 - name 'items' is not defined\nTraceback (most recent call last):\n\n  File \"D:\\–ê–°–£–ü\\Python\\Projects\\OwnBot\\todoist_api\\save_todoist_data.py\", line 86, in <module>\n    get_todoist_data(token='48cbdb22977eb9d84368aef673d3c7ba7c0f311a')\n    ‚îî <function get_todoist_data at 0x0000020A02678EA0>\n\n> File \"D:\\–ê–°–£–ü\\Python\\Projects\\OwnBot\\todoist_api\\save_todoist_data.py\", line 55, in get_todoist_data\n    pprint(items)\n    ‚îî <function pprint at 0x0000020A0267BA60>\n\nNameError: name 'items' is not defined\n", "record": {"elapsed": {"repr": "0:00:11.388353", "seconds": 11.388353}, "exception": {"type": "NameError", "value": "name 'items' is not defined", "traceback": true}, "extra": {}, "file": {"name": "save_todoist_data.py", "path": "D:\\–ê–°–£–ü\\Python\\Projects\\OwnBot\\todoist_api\\save_todoist_data.py"}, "function": "get_todoist_data", "level": {"icon": "‚ùå", "name": "ERROR", "no": 40}, "line": 82, "message": "name 'items' is not defined", "module": "save_todoist_data", "name": "__main__", "process": {"id": 8244, "name": "MainProcess"}, "thread": {"id": 13732, "name": "MainThread"}, "time": {"repr": "2024-12-19 13:25:33.547838+06:00", "timestamp": 1734593133.547838}}}
{"text": "2024-12-19 13:28:16.258 | ERROR    | __main__:get_todoist_data:84 - –û—à–∏–±–∫–∞ –≤ completed_tasks_get\n", "record": {"elapsed": {"repr": "0:00:12.805327", "seconds": 12.805327}, "exception": null, "extra": {"exc_info": "name 'items' is not defined"}, "file": {"name": "save_todoist_data.py", "path": "D:\\–ê–°–£–ü\\Python\\Projects\\OwnBot\\todoist_api\\save_todoist_data.py"}, "function": "get_todoist_data", "level": {"icon": "‚ùå", "name": "ERROR", "no": 40}, "line": 84, "message": "–û—à–∏–±–∫–∞ –≤ completed_tasks_get", "module": "save_todoist_data", "name": "__main__", "process": {"id": 4576, "name": "MainProcess"}, "thread": {"id": 12524, "name": "MainThread"}, "time": {"repr": "2024-12-19 13:28:16.258849+06:00", "timestamp": 1734593296.258849}}}
{"text": "2024-12-19 13:28:16.258 | ERROR    | __main__:get_todoist_data:85 - name 'items' is not defined\nTraceback (most recent call last):\n\n  File \"D:\\–ê–°–£–ü\\Python\\Projects\\OwnBot\\todoist_api\\save_todoist_data.py\", line 89, in <module>\n    get_todoist_data(token='48cbdb22977eb9d84368aef673d3c7ba7c0f311a')\n    ‚îî <function get_todoist_data at 0x000001BE1B508EA0>\n\n> File \"D:\\–ê–°–£–ü\\Python\\Projects\\OwnBot\\todoist_api\\save_todoist_data.py\", line 58, in get_todoist_data\n    pprint(items)\n    ‚îî <function pprint at 0x000001BE1B50BA60>\n\nNameError: name 'items' is not defined\n", "record": {"elapsed": {"repr": "0:00:12.805327", "seconds": 12.805327}, "exception": {"type": "NameError", "value": "name 'items' is not defined", "traceback": true}, "extra": {}, "file": {"name": "save_todoist_data.py", "path": "D:\\–ê–°–£–ü\\Python\\Projects\\OwnBot\\todoist_api\\save_todoist_data.py"}, "function": "get_todoist_data", "level": {"icon": "‚ùå", "name": "ERROR", "no": 40}, "line": 85, "message": "name 'items' is not defined", "module": "save_todoist_data", "name": "__main__", "process": {"id": 4576, "name": "MainProcess"}, "thread": {"id": 12524, "name": "MainThread"}, "time": {"repr": "2024-12-19 13:28:16.258849+06:00", "timestamp": 1734593296.258849}}}
{"text": "2024-12-19 13:30:05.869 | ERROR    | __main__:get_todoist_data:86 - –û—à–∏–±–∫–∞ –≤ completed_tasks_get\n", "record": {"elapsed": {"repr": "0:00:03.423355", "seconds": 3.423355}, "exception": null, "extra": {"exc_info": "name 'items' is not defined"}, "file": {"name": "save_todoist_data.py", "path": "D:\\–ê–°–£–ü\\Python\\Projects\\OwnBot\\todoist_api\\save_todoist_data.py"}, "function": "get_todoist_data", "level": {"icon": "‚ùå", "name": "ERROR", "no": 40}, "line": 86, "message": "–û—à–∏–±–∫–∞ –≤ completed_tasks_get", "module": "save_todoist_data", "name": "__main__", "process": {"id": 9308, "name": "MainProcess"}, "thread": {"id": 13428, "name": "MainThread"}, "time": {"repr": "2024-12-19 13:30:05.869896+06:00", "timestamp": 1734593405.869896}}}
{"text": "2024-12-19 13:30:05.869 | ERROR    | __main__:get_todoist_data:87 - name 'items' is not defined\nTraceback (most recent call last):\n\n  File \"D:\\–ê–°–£–ü\\Python\\Projects\\OwnBot\\todoist_api\\save_todoist_data.py\", line 91, in <module>\n    get_todoist_data(token='48cbdb22977eb9d84368aef673d3c7ba7c0f311a')\n    ‚îî <function get_todoist_data at 0x000001954CDD8EA0>\n\n> File \"D:\\–ê–°–£–ü\\Python\\Projects\\OwnBot\\todoist_api\\save_todoist_data.py\", line 60, in get_todoist_data\n    pprint(items)\n    ‚îî <function pprint at 0x000001954CDDBA60>\n\nNameError: name 'items' is not defined\n", "record": {"elapsed": {"repr": "0:00:03.423355", "seconds": 3.423355}, "exception": {"type": "NameError", "value": "name 'items' is not defined", "traceback": true}, "extra": {}, "file": {"name": "save_todoist_data.py", "path": "D:\\–ê–°–£–ü\\Python\\Projects\\OwnBot\\todoist_api\\save_todoist_data.py"}, "function": "get_todoist_data", "level": {"icon": "‚ùå", "name": "ERROR", "no": 40}, "line": 87, "message": "name 'items' is not defined", "module": "save_todoist_data", "name": "__main__", "process": {"id": 9308, "name": "MainProcess"}, "thread": {"id": 13428, "name": "MainThread"}, "time": {"repr": "2024-12-19 13:30:05.869896+06:00", "timestamp": 1734593405.869896}}}
{"text": "2024-12-19 13:30:28.169 | ERROR    | __main__:get_todoist_data:86 - –û—à–∏–±–∫–∞ –≤ completed_tasks_get\n", "record": {"elapsed": {"repr": "0:00:03.122686", "seconds": 3.122686}, "exception": null, "extra": {"exc_info": "name 'items' is not defined"}, "file": {"name": "save_todoist_data.py", "path": "D:\\–ê–°–£–ü\\Python\\Projects\\OwnBot\\todoist_api\\save_todoist_data.py"}, "function": "get_todoist_data", "level": {"icon": "‚ùå", "name": "ERROR", "no": 40}, "line": 86, "message": "–û—à–∏–±–∫–∞ –≤ completed_tasks_get", "module": "save_todoist_data", "name": "__main__", "process": {"id": 8560, "name": "MainProcess"}, "thread": {"id": 4336, "name": "MainThread"}, "time": {"repr": "2024-12-19 13:30:28.169299+06:00", "timestamp": 1734593428.169299}}}
{"text": "2024-12-19 13:30:28.170 | ERROR    | __main__:get_todoist_data:87 - name 'items' is not defined\nTraceback (most recent call last):\n\n  File \"D:\\–ê–°–£–ü\\Python\\Projects\\OwnBot\\todoist_api\\save_todoist_data.py\", line 91, in <module>\n    get_todoist_data(token='48cbdb22977eb9d84368aef673d3c7ba7c0f311a')\n    ‚îî <function get_todoist_data at 0x0000017D73198EA0>\n\n> File \"D:\\–ê–°–£–ü\\Python\\Projects\\OwnBot\\todoist_api\\save_todoist_data.py\", line 60, in get_todoist_data\n    pprint(items)\n    ‚îî <function pprint at 0x0000017D7319BA60>\n\nNameError: name 'items' is not defined\n", "record": {"elapsed": {"repr": "0:00:03.123689", "seconds": 3.123689}, "exception": {"type": "NameError", "value": "name 'items' is not defined", "traceback": true}, "extra": {}, "file": {"name": "save_todoist_data.py", "path": "D:\\–ê–°–£–ü\\Python\\Projects\\OwnBot\\todoist_api\\save_todoist_data.py"}, "function": "get_todoist_data", "level": {"icon": "‚ùå", "name": "ERROR", "no": 40}, "line": 87, "message": "name 'items' is not defined", "module": "save_todoist_data", "name": "__main__", "process": {"id": 8560, "name": "MainProcess"}, "thread": {"id": 4336, "name": "MainThread"}, "time": {"repr": "2024-12-19 13:30:28.170302+06:00", "timestamp": 1734593428.170302}}}
{"text": "2024-12-19 14:07:15.592 | ERROR    | __main__:get_todoist_data:104 - –û—à–∏–±–∫–∞ –≤ completed_tasks_get\n", "record": {"elapsed": {"repr": "0:00:05.044321", "seconds": 5.044321}, "exception": null, "extra": {"exc_info": "400 Client Error: Bad Request for url: https://api.todoist.com/sync/v9/archive/items?limit=10"}, "file": {"name": "save_todoist_data.py", "path": "D:\\–ê–°–£–ü\\Python\\Projects\\OwnBot\\todoist_api\\save_todoist_data.py"}, "function": "get_todoist_data", "level": {"icon": "‚ùå", "name": "ERROR", "no": 40}, "line": 104, "message": "–û—à–∏–±–∫–∞ –≤ completed_tasks_get", "module": "save_todoist_data", "name": "__main__", "process": {"id": 12888, "name": "MainProcess"}, "thread": {"id": 4412, "name": "MainThread"}, "time": {"repr": "2024-12-19 14:07:15.592368+06:00", "timestamp": 1734595635.592368}}}
{"text": "2024-12-19 14:07:15.593 | ERROR    | __main__:get_todoist_data:105 - 400 Client Error: Bad Request for url: https://api.todoist.com/sync/v9/archive/items?limit=10\nTraceback (most recent call last):\n\n  File \"D:\\–ê–°–£–ü\\Python\\Projects\\OwnBot\\todoist_api\\save_todoist_data.py\", line 109, in <module>\n    get_todoist_data(token='48cbdb22977eb9d84368aef673d3c7ba7c0f311a')\n    ‚îî <function get_todoist_data at 0x0000026CF80D8EA0>\n\n> File \"D:\\–ê–°–£–ü\\Python\\Projects\\OwnBot\\todoist_api\\save_todoist_data.py\", line 35, in get_todoist_data\n    pprint(api.get_completed_items(limit=10))\n    ‚îÇ      ‚îÇ   ‚îî <function TodoistAPI.get_completed_items at 0x0000026CFA7C2A20>\n    ‚îÇ      ‚îî <todoist_api_python.api.TodoistAPI object at 0x0000026CF80FFE90>\n    ‚îî <function pprint at 0x0000026CF812BF60>\n\n  File \"D:\\–ê–°–£–ü\\Python\\Projects\\OwnBot\\venv\\Lib\\site-packages\\todoist_api_python\\api.py\", line 231, in get_completed_items\n    completed_items = get(\n                      ‚îî <function get at 0x0000026CFA655800>\n  File \"D:\\–ê–°–£–ü\\Python\\Projects\\OwnBot\\venv\\Lib\\site-packages\\todoist_api_python\\http_requests.py\", line 23, in get\n    response.raise_for_status()\n    ‚îÇ        ‚îî <function Response.raise_for_status at 0x0000026CFA6334C0>\n    ‚îî <Response [400]>\n  File \"D:\\–ê–°–£–ü\\Python\\Projects\\OwnBot\\venv\\Lib\\site-packages\\requests\\models.py\", line 1024, in raise_for_status\n    raise HTTPError(http_error_msg, response=self)\n          ‚îÇ         ‚îÇ                        ‚îî <Response [400]>\n          ‚îÇ         ‚îî '400 Client Error: Bad Request for url: https://api.todoist.com/sync/v9/archive/items?limit=10'\n          ‚îî <class 'requests.exceptions.HTTPError'>\n\nrequests.exceptions.HTTPError: 400 Client Error: Bad Request for url: https://api.todoist.com/sync/v9/archive/items?limit=10\n", "record": {"elapsed": {"repr": "0:00:05.045360", "seconds": 5.04536}, "exception": {"type": "HTTPError", "value": "400 Client Error: Bad Request for url: https://api.todoist.com/sync/v9/archive/items?limit=10", "traceback": true}, "extra": {}, "file": {"name": "save_todoist_data.py", "path": "D:\\–ê–°–£–ü\\Python\\Projects\\OwnBot\\todoist_api\\save_todoist_data.py"}, "function": "get_todoist_data", "level": {"icon": "‚ùå", "name": "ERROR", "no": 40}, "line": 105, "message": "400 Client Error: Bad Request for url: https://api.todoist.com/sync/v9/archive/items?limit=10", "module": "save_todoist_data", "name": "__main__", "process": {"id": 12888, "name": "MainProcess"}, "thread": {"id": 4412, "name": "MainThread"}, "time": {"repr": "2024-12-19 14:07:15.593407+06:00", "timestamp": 1734595635.593407}}}
{"text": "2024-12-19 14:13:34.193 | ERROR    | __main__:get_todoist_data:104 - –û—à–∏–±–∫–∞ –≤ completed_tasks_get\n", "record": {"elapsed": {"repr": "0:00:05.471412", "seconds": 5.471412}, "exception": null, "extra": {"exc_info": "400 Client Error: Bad Request for url: https://api.todoist.com/sync/v9/archive/items?limit=10"}, "file": {"name": "save_todoist_data.py", "path": "D:\\–ê–°–£–ü\\Python\\Projects\\OwnBot\\todoist_api\\save_todoist_data.py"}, "function": "get_todoist_data", "level": {"icon": "‚ùå", "name": "ERROR", "no": 40}, "line": 104, "message": "–û—à–∏–±–∫–∞ –≤ completed_tasks_get", "module": "save_todoist_data", "name": "__main__", "process": {"id": 4664, "name": "MainProcess"}, "thread": {"id": 5708, "name": "MainThread"}, "time": {"repr": "2024-12-19 14:13:34.193420+06:00", "timestamp": 1734596014.19342}}}
{"text": "2024-12-19 14:13:34.193 | ERROR    | __main__:get_todoist_data:105 - 400 Client Error: Bad Request for url: https://api.todoist.com/sync/v9/archive/items?limit=10\nTraceback (most recent call last):\n\n  File \"D:\\–ê–°–£–ü\\Python\\Projects\\OwnBot\\todoist_api\\save_todoist_data.py\", line 109, in <module>\n    get_todoist_data(token='48cbdb22977eb9d84368aef673d3c7ba7c0f311a')\n    ‚îî <function get_todoist_data at 0x0000025023148EA0>\n\n> File \"D:\\–ê–°–£–ü\\Python\\Projects\\OwnBot\\todoist_api\\save_todoist_data.py\", line 35, in get_todoist_data\n    pprint(api.get_completed_items(project_id = None, limit=10))\n    ‚îÇ      ‚îÇ   ‚îî <function TodoistAPI.get_completed_items at 0x00000250257E2980>\n    ‚îÇ      ‚îî <todoist_api_python.api.TodoistAPI object at 0x000002502316FE00>\n    ‚îî <function pprint at 0x000002502314BA60>\n\n  File \"D:\\–ê–°–£–ü\\Python\\Projects\\OwnBot\\venv\\Lib\\site-packages\\todoist_api_python\\api.py\", line 231, in get_completed_items\n    completed_items = get(\n                      ‚îî <function get at 0x0000025025675760>\n  File \"D:\\–ê–°–£–ü\\Python\\Projects\\OwnBot\\venv\\Lib\\site-packages\\todoist_api_python\\http_requests.py\", line 23, in get\n    response.raise_for_status()\n    ‚îÇ        ‚îî <function Response.raise_for_status at 0x0000025025653420>\n    ‚îî <Response [400]>\n  File \"D:\\–ê–°–£–ü\\Python\\Projects\\OwnBot\\venv\\Lib\\site-packages\\requests\\models.py\", line 1024, in raise_for_status\n    raise HTTPError(http_error_msg, response=self)\n          ‚îÇ         ‚îÇ                        ‚îî <Response [400]>\n          ‚îÇ         ‚îî '400 Client Error: Bad Request for url: https://api.todoist.com/sync/v9/archive/items?limit=10'\n          ‚îî <class 'requests.exceptions.HTTPError'>\n\nrequests.exceptions.HTTPError: 400 Client Error: Bad Request for url: https://api.todoist.com/sync/v9/archive/items?limit=10\n", "record": {"elapsed": {"repr": "0:00:05.471412", "seconds": 5.471412}, "exception": {"type": "HTTPError", "value": "400 Client Error: Bad Request for url: https://api.todoist.com/sync/v9/archive/items?limit=10", "traceback": true}, "extra": {}, "file": {"name": "save_todoist_data.py", "path": "D:\\–ê–°–£–ü\\Python\\Projects\\OwnBot\\todoist_api\\save_todoist_data.py"}, "function": "get_todoist_data", "level": {"icon": "‚ùå", "name": "ERROR", "no": 40}, "line": 105, "message": "400 Client Error: Bad Request for url: https://api.todoist.com/sync/v9/archive/items?limit=10", "module": "save_todoist_data", "name": "__main__", "process": {"id": 4664, "name": "MainProcess"}, "thread": {"id": 5708, "name": "MainThread"}, "time": {"repr": "2024-12-19 14:13:34.193420+06:00", "timestamp": 1734596014.19342}}}
{"text": "2024-12-19 15:16:56.327 | ERROR    | __main__:get_todoist_data:79 - –û—à–∏–±–∫–∞ –≤ completed_tasks_get\n", "record": {"elapsed": {"repr": "0:00:04.005096", "seconds": 4.005096}, "exception": null, "extra": {"exc_info": "type object 'dict' has no attribute 'write'"}, "file": {"name": "save_todoist_data.py", "path": "D:\\–ê–°–£–ü\\Python\\Projects\\OwnBot\\todoist_api\\save_todoist_data.py"}, "function": "get_todoist_data", "level": {"icon": "‚ùå", "name": "ERROR", "no": 40}, "line": 79, "message": "–û—à–∏–±–∫–∞ –≤ completed_tasks_get", "module": "save_todoist_data", "name": "__main__", "process": {"id": 3948, "name": "MainProcess"}, "thread": {"id": 9864, "name": "MainThread"}, "time": {"repr": "2024-12-19 15:16:56.327433+06:00", "timestamp": 1734599816.327433}}}
{"text": "2024-12-19 15:16:56.327 | ERROR    | __main__:get_todoist_data:80 - type object 'dict' has no attribute 'write'\nTraceback (most recent call last):\n\n  File \"D:\\–ê–°–£–ü\\Python\\Projects\\OwnBot\\todoist_api\\save_todoist_data.py\", line 84, in <module>\n    get_todoist_data(token='48cbdb22977eb9d84368aef673d3c7ba7c0f311a')\n    ‚îî <function get_todoist_data at 0x0000023DDC6A9BC0>\n\n> File \"D:\\–ê–°–£–ü\\Python\\Projects\\OwnBot\\todoist_api\\save_todoist_data.py\", line 59, in get_todoist_data\n    pprint(response, type(response))\n    ‚îÇ      ‚îÇ              ‚îî {'items': [{'completed_at': '2024-12-19T02:15:30.000000Z', 'content': 'Med', 'id': '7912036814', 'item_object': None, 'meta_d...\n    ‚îÇ      ‚îî {'items': [{'completed_at': '2024-12-19T02:15:30.000000Z', 'content': 'Med', 'id': '7912036814', 'item_object': None, 'meta_d...\n    ‚îî <function pprint at 0x0000023DDC6FBF60>\n\n  File \"C:\\Users\\user-18\\AppData\\Local\\Programs\\Python\\Python312\\Lib\\pprint.py\", line 55, in pprint\n    printer.pprint(object)\n    ‚îÇ       ‚îÇ      ‚îî {'items': [{'completed_at': '2024-12-19T02:15:30.000000Z', 'content': 'Med', 'id': '7912036814', 'item_object': None, 'meta_d...\n    ‚îÇ       ‚îî <function PrettyPrinter.pprint at 0x0000023DDC857740>\n    ‚îî <pprint.PrettyPrinter object at 0x0000023DDECC1370>\n  File \"C:\\Users\\user-18\\AppData\\Local\\Programs\\Python\\Python312\\Lib\\pprint.py\", line 156, in pprint\n    self._format(object, self._stream, 0, 0, {}, 0)\n    ‚îÇ    ‚îÇ       ‚îÇ       ‚îÇ    ‚îî <class 'dict'>\n    ‚îÇ    ‚îÇ       ‚îÇ       ‚îî <pprint.PrettyPrinter object at 0x0000023DDECC1370>\n    ‚îÇ    ‚îÇ       ‚îî {'items': [{'completed_at': '2024-12-19T02:15:30.000000Z', 'content': 'Med', 'id': '7912036814', 'item_object': None, 'meta_d...\n    ‚îÇ    ‚îî <function PrettyPrinter._format at 0x0000023DDC8579C0>\n    ‚îî <pprint.PrettyPrinter object at 0x0000023DDECC1370>\n  File \"C:\\Users\\user-18\\AppData\\Local\\Programs\\Python\\Python312\\Lib\\pprint.py\", line 184, in _format\n    p(self, object, stream, indent, allowance, context, level + 1)\n    ‚îÇ ‚îÇ     ‚îÇ       ‚îÇ       ‚îÇ       ‚îÇ          ‚îÇ        ‚îî 0\n    ‚îÇ ‚îÇ     ‚îÇ       ‚îÇ       ‚îÇ       ‚îÇ          ‚îî {2464768454400: 1}\n    ‚îÇ ‚îÇ     ‚îÇ       ‚îÇ       ‚îÇ       ‚îî 0\n    ‚îÇ ‚îÇ     ‚îÇ       ‚îÇ       ‚îî 0\n    ‚îÇ ‚îÇ     ‚îÇ       ‚îî <class 'dict'>\n    ‚îÇ ‚îÇ     ‚îî {'items': [{'completed_at': '2024-12-19T02:15:30.000000Z', 'content': 'Med', 'id': '7912036814', 'item_object': None, 'meta_d...\n    ‚îÇ ‚îî <pprint.PrettyPrinter object at 0x0000023DDECC1370>\n    ‚îî <function PrettyPrinter._pprint_dict at 0x0000023DDC857B00>\n  File \"C:\\Users\\user-18\\AppData\\Local\\Programs\\Python\\Python312\\Lib\\pprint.py\", line 210, in _pprint_dict\n    write = stream.write\n            ‚îî <class 'dict'>\n\nAttributeError: type object 'dict' has no attribute 'write'\n", "record": {"elapsed": {"repr": "0:00:04.005096", "seconds": 4.005096}, "exception": {"type": "AttributeError", "value": "type object 'dict' has no attribute 'write'", "traceback": true}, "extra": {}, "file": {"name": "save_todoist_data.py", "path": "D:\\–ê–°–£–ü\\Python\\Projects\\OwnBot\\todoist_api\\save_todoist_data.py"}, "function": "get_todoist_data", "level": {"icon": "‚ùå", "name": "ERROR", "no": 40}, "line": 80, "message": "type object 'dict' has no attribute 'write'", "module": "save_todoist_data", "name": "__main__", "process": {"id": 3948, "name": "MainProcess"}, "thread": {"id": 9864, "name": "MainThread"}, "time": {"repr": "2024-12-19 15:16:56.327433+06:00", "timestamp": 1734599816.327433}}}
{"text": "2024-12-19 15:20:39.525 | ERROR    | __main__:get_todoist_data:80 - –û—à–∏–±–∫–∞ –≤ completed_tasks_get\n", "record": {"elapsed": {"repr": "0:00:00.735481", "seconds": 0.735481}, "exception": null, "extra": {"exc_info": "string indices must be integers, not 'str'"}, "file": {"name": "save_todoist_data.py", "path": "D:\\–ê–°–£–ü\\Python\\Projects\\OwnBot\\todoist_api\\save_todoist_data.py"}, "function": "get_todoist_data", "level": {"icon": "‚ùå", "name": "ERROR", "no": 40}, "line": 80, "message": "–û—à–∏–±–∫–∞ –≤ completed_tasks_get", "module": "save_todoist_data", "name": "__main__", "process": {"id": 12932, "name": "MainProcess"}, "thread": {"id": 13368, "name": "MainThread"}, "time": {"repr": "2024-12-19 15:20:39.525521+06:00", "timestamp": 1734600039.525521}}}
{"text": "2024-12-19 15:20:39.526 | ERROR    | __main__:get_todoist_data:81 - string indices must be integers, not 'str'\nTraceback (most recent call last):\n\n  File \"D:\\–ê–°–£–ü\\Python\\Projects\\OwnBot\\todoist_api\\save_todoist_data.py\", line 85, in <module>\n    get_todoist_data(token='48cbdb22977eb9d84368aef673d3c7ba7c0f311a')\n    ‚îî <function get_todoist_data at 0x0000024406B28EA0>\n\n> File \"D:\\–ê–°–£–ü\\Python\\Projects\\OwnBot\\todoist_api\\save_todoist_data.py\", line 60, in get_todoist_data\n    projects = {project: project['name'] for project in response['projects']}\n                                                        ‚îî {'items': [{'completed_at': '2024-12-19T02:15:30.000000Z', 'content': 'Med', 'id': '7912036814', 'item_object': None, 'meta_d...\n\nTypeError: string indices must be integers, not 'str'\n", "record": {"elapsed": {"repr": "0:00:00.736481", "seconds": 0.736481}, "exception": {"type": "TypeError", "value": "string indices must be integers, not 'str'", "traceback": true}, "extra": {}, "file": {"name": "save_todoist_data.py", "path": "D:\\–ê–°–£–ü\\Python\\Projects\\OwnBot\\todoist_api\\save_todoist_data.py"}, "function": "get_todoist_data", "level": {"icon": "‚ùå", "name": "ERROR", "no": 40}, "line": 81, "message": "string indices must be integers, not 'str'", "module": "save_todoist_data", "name": "__main__", "process": {"id": 12932, "name": "MainProcess"}, "thread": {"id": 13368, "name": "MainThread"}, "time": {"repr": "2024-12-19 15:20:39.526521+06:00", "timestamp": 1734600039.526521}}}
{"text": "2024-12-19 15:21:38.830 | ERROR    | __main__:get_todoist_data:80 - –û—à–∏–±–∫–∞ –≤ completed_tasks_get\n", "record": {"elapsed": {"repr": "0:00:00.594958", "seconds": 0.594958}, "exception": null, "extra": {"exc_info": "'builtin_function_or_method' object is not iterable"}, "file": {"name": "save_todoist_data.py", "path": "D:\\–ê–°–£–ü\\Python\\Projects\\OwnBot\\todoist_api\\save_todoist_data.py"}, "function": "get_todoist_data", "level": {"icon": "‚ùå", "name": "ERROR", "no": 40}, "line": 80, "message": "–û—à–∏–±–∫–∞ –≤ completed_tasks_get", "module": "save_todoist_data", "name": "__main__", "process": {"id": 8208, "name": "MainProcess"}, "thread": {"id": 2272, "name": "MainThread"}, "time": {"repr": "2024-12-19 15:21:38.830433+06:00", "timestamp": 1734600098.830433}}}
{"text": "2024-12-19 15:21:38.831 | ERROR    | __main__:get_todoist_data:81 - 'builtin_function_or_method' object is not iterable\nTraceback (most recent call last):\n\n  File \"D:\\–ê–°–£–ü\\Python\\Projects\\OwnBot\\todoist_api\\save_todoist_data.py\", line 85, in <module>\n    get_todoist_data(token='48cbdb22977eb9d84368aef673d3c7ba7c0f311a')\n    ‚îî <function get_todoist_data at 0x0000015C76598EA0>\n\n> File \"D:\\–ê–°–£–ü\\Python\\Projects\\OwnBot\\todoist_api\\save_todoist_data.py\", line 60, in get_todoist_data\n    projects = {project: project['name'] for project, value in response['projects'].items}\n                                                               ‚îî {'items': [{'completed_at': '2024-12-19T02:15:30.000000Z', 'content': 'Med', 'id': '7912036814', 'item_object': None, 'meta_d...\n\nTypeError: 'builtin_function_or_method' object is not iterable\n", "record": {"elapsed": {"repr": "0:00:00.595959", "seconds": 0.595959}, "exception": {"type": "TypeError", "value": "'builtin_function_or_method' object is not iterable", "traceback": true}, "extra": {}, "file": {"name": "save_todoist_data.py", "path": "D:\\–ê–°–£–ü\\Python\\Projects\\OwnBot\\todoist_api\\save_todoist_data.py"}, "function": "get_todoist_data", "level": {"icon": "‚ùå", "name": "ERROR", "no": 40}, "line": 81, "message": "'builtin_function_or_method' object is not iterable", "module": "save_todoist_data", "name": "__main__", "process": {"id": 8208, "name": "MainProcess"}, "thread": {"id": 2272, "name": "MainThread"}, "time": {"repr": "2024-12-19 15:21:38.831434+06:00", "timestamp": 1734600098.831434}}}
{"text": "2024-12-19 15:21:46.988 | ERROR    | __main__:get_todoist_data:80 - –û—à–∏–±–∫–∞ –≤ completed_tasks_get\n", "record": {"elapsed": {"repr": "0:00:00.647950", "seconds": 0.64795}, "exception": null, "extra": {"exc_info": "string indices must be integers, not 'str'"}, "file": {"name": "save_todoist_data.py", "path": "D:\\–ê–°–£–ü\\Python\\Projects\\OwnBot\\todoist_api\\save_todoist_data.py"}, "function": "get_todoist_data", "level": {"icon": "‚ùå", "name": "ERROR", "no": 40}, "line": 80, "message": "–û—à–∏–±–∫–∞ –≤ completed_tasks_get", "module": "save_todoist_data", "name": "__main__", "process": {"id": 11676, "name": "MainProcess"}, "thread": {"id": 6528, "name": "MainThread"}, "time": {"repr": "2024-12-19 15:21:46.988479+06:00", "timestamp": 1734600106.988479}}}
{"text": "2024-12-19 15:21:46.988 | ERROR    | __main__:get_todoist_data:81 - string indices must be integers, not 'str'\nTraceback (most recent call last):\n\n  File \"D:\\–ê–°–£–ü\\Python\\Projects\\OwnBot\\todoist_api\\save_todoist_data.py\", line 85, in <module>\n    get_todoist_data(token='48cbdb22977eb9d84368aef673d3c7ba7c0f311a')\n    ‚îî <function get_todoist_data at 0x000001663F2C8EA0>\n\n> File \"D:\\–ê–°–£–ü\\Python\\Projects\\OwnBot\\todoist_api\\save_todoist_data.py\", line 60, in get_todoist_data\n    projects = {project: project['name'] for project, value in response['projects'].items()}\n                                                               ‚îî {'items': [{'completed_at': '2024-12-19T02:15:30.000000Z', 'content': 'Med', 'id': '7912036814', 'item_object': None, 'meta_d...\n\nTypeError: string indices must be integers, not 'str'\n", "record": {"elapsed": {"repr": "0:00:00.647950", "seconds": 0.64795}, "exception": {"type": "TypeError", "value": "string indices must be integers, not 'str'", "traceback": true}, "extra": {}, "file": {"name": "save_todoist_data.py", "path": "D:\\–ê–°–£–ü\\Python\\Projects\\OwnBot\\todoist_api\\save_todoist_data.py"}, "function": "get_todoist_data", "level": {"icon": "‚ùå", "name": "ERROR", "no": 40}, "line": 81, "message": "string indices must be integers, not 'str'", "module": "save_todoist_data", "name": "__main__", "process": {"id": 11676, "name": "MainProcess"}, "thread": {"id": 6528, "name": "MainThread"}, "time": {"repr": "2024-12-19 15:21:46.988479+06:00", "timestamp": 1734600106.988479}}}
{"text": "2024-12-19 15:40:16.293 | ERROR    | __main__:get_todoist_data:99 - –û—à–∏–±–∫–∞ –≤ completed_tasks_get\n", "record": {"elapsed": {"repr": "0:00:04.650710", "seconds": 4.65071}, "exception": null, "extra": {"exc_info": "'Task' object has no attribute 'completed_at'"}, "file": {"name": "save_todoist_data.py", "path": "D:\\–ê–°–£–ü\\Python\\Projects\\OwnBot\\todoist_api\\save_todoist_data.py"}, "function": "get_todoist_data", "level": {"icon": "‚ùå", "name": "ERROR", "no": 40}, "line": 99, "message": "–û—à–∏–±–∫–∞ –≤ completed_tasks_get", "module": "save_todoist_data", "name": "__main__", "process": {"id": 3208, "name": "MainProcess"}, "thread": {"id": 10148, "name": "MainThread"}, "time": {"repr": "2024-12-19 15:40:16.293169+06:00", "timestamp": 1734601216.293169}}}
{"text": "2024-12-19 15:40:16.293 | ERROR    | __main__:get_todoist_data:100 - 'Task' object has no attribute 'completed_at'\nTraceback (most recent call last):\n\n  File \"D:\\–ê–°–£–ü\\Python\\Projects\\OwnBot\\todoist_api\\save_todoist_data.py\", line 104, in <module>\n    get_todoist_data(token='48cbdb22977eb9d84368aef673d3c7ba7c0f311a')\n    ‚îî <function get_todoist_data at 0x0000011EEA42BD80>\n\n> File \"D:\\–ê–°–£–ü\\Python\\Projects\\OwnBot\\todoist_api\\save_todoist_data.py\", line 75, in get_todoist_data\n    'completed_at': completed_task.completed_at,\n                    ‚îî Task(assignee_id=None, assigner_id=None, comment_count=0, is_completed=False, content='Med', created_at='2022-12-02T07:44:42....\n\nAttributeError: 'Task' object has no attribute 'completed_at'\n", "record": {"elapsed": {"repr": "0:00:04.650710", "seconds": 4.65071}, "exception": {"type": "AttributeError", "value": "'Task' object has no attribute 'completed_at'", "traceback": true}, "extra": {}, "file": {"name": "save_todoist_data.py", "path": "D:\\–ê–°–£–ü\\Python\\Projects\\OwnBot\\todoist_api\\save_todoist_data.py"}, "function": "get_todoist_data", "level": {"icon": "‚ùå", "name": "ERROR", "no": 40}, "line": 100, "message": "'Task' object has no attribute 'completed_at'", "module": "save_todoist_data", "name": "__main__", "process": {"id": 3208, "name": "MainProcess"}, "thread": {"id": 10148, "name": "MainThread"}, "time": {"repr": "2024-12-19 15:40:16.293169+06:00", "timestamp": 1734601216.293169}}}
{"text": "2024-12-19 16:18:10.624 | ERROR    | __main__:get_todoist_data:103 - –û—à–∏–±–∫–∞ –≤ completed_tasks_get\n", "record": {"elapsed": {"repr": "0:00:05.097827", "seconds": 5.097827}, "exception": null, "extra": {"exc_info": "parser._parse() got an unexpected keyword argument 'tzinfo'"}, "file": {"name": "save_todoist_data.py", "path": "D:\\–ê–°–£–ü\\Python\\Projects\\OwnBot\\todoist_api\\save_todoist_data.py"}, "function": "get_todoist_data", "level": {"icon": "‚ùå", "name": "ERROR", "no": 40}, "line": 103, "message": "–û—à–∏–±–∫–∞ –≤ completed_tasks_get", "module": "save_todoist_data", "name": "__main__", "process": {"id": 5916, "name": "MainProcess"}, "thread": {"id": 10856, "name": "MainThread"}, "time": {"repr": "2024-12-19 16:18:10.624665+06:00", "timestamp": 1734603490.624665}}}
{"text": "2024-12-19 16:18:10.624 | ERROR    | __main__:get_todoist_data:104 - parser._parse() got an unexpected keyword argument 'tzinfo'\nTraceback (most recent call last):\n\n  File \"D:\\–ê–°–£–ü\\Python\\Projects\\OwnBot\\todoist_api\\save_todoist_data.py\", line 108, in <module>\n    get_todoist_data(token='48cbdb22977eb9d84368aef673d3c7ba7c0f311a')\n    ‚îî <function get_todoist_data at 0x00000263DF85BD80>\n\n> File \"D:\\–ê–°–£–ü\\Python\\Projects\\OwnBot\\todoist_api\\save_todoist_data.py\", line 77, in get_todoist_data\n    'completed_at': parse(task_id[1], tzinfo=tzinfos),  # + timedelta(hours=TIME_ZONE),\n                    ‚îÇ     ‚îÇ                  ‚îî {'BRST': -7200, 'CST': tzfile('America/Chicago')}\n                    ‚îÇ     ‚îî ('6402304524', '2024-12-19T02:15:30.000000Z')\n                    ‚îî <function parse at 0x00000263E2C445E0>\n\n  File \"D:\\–ê–°–£–ü\\Python\\Projects\\OwnBot\\venv\\Lib\\site-packages\\dateutil\\parser\\_parser.py\", line 1368, in parse\n    return DEFAULTPARSER.parse(timestr, **kwargs)\n           ‚îÇ             ‚îÇ     ‚îÇ          ‚îî {'tzinfo': {'BRST': -7200, 'CST': tzfile('America/Chicago')}}\n           ‚îÇ             ‚îÇ     ‚îî '2024-12-19T02:15:30.000000Z'\n           ‚îÇ             ‚îî <function parser.parse at 0x00000263E2C46E80>\n           ‚îî <dateutil.parser._parser.parser object at 0x00000263E2C18A70>\n  File \"D:\\–ê–°–£–ü\\Python\\Projects\\OwnBot\\venv\\Lib\\site-packages\\dateutil\\parser\\_parser.py\", line 640, in parse\n    res, skipped_tokens = self._parse(timestr, **kwargs)\n                          ‚îÇ    ‚îÇ      ‚îÇ          ‚îî {'tzinfo': {'BRST': -7200, 'CST': tzfile('America/Chicago')}}\n                          ‚îÇ    ‚îÇ      ‚îî '2024-12-19T02:15:30.000000Z'\n                          ‚îÇ    ‚îî <function parser._parse at 0x00000263E2C46F20>\n                          ‚îî <dateutil.parser._parser.parser object at 0x00000263E2C18A70>\n\nTypeError: parser._parse() got an unexpected keyword argument 'tzinfo'\n", "record": {"elapsed": {"repr": "0:00:05.097827", "seconds": 5.097827}, "exception": {"type": "TypeError", "value": "parser._parse() got an unexpected keyword argument 'tzinfo'", "traceback": true}, "extra": {}, "file": {"name": "save_todoist_data.py", "path": "D:\\–ê–°–£–ü\\Python\\Projects\\OwnBot\\todoist_api\\save_todoist_data.py"}, "function": "get_todoist_data", "level": {"icon": "‚ùå", "name": "ERROR", "no": 40}, "line": 104, "message": "parser._parse() got an unexpected keyword argument 'tzinfo'", "module": "save_todoist_data", "name": "__main__", "process": {"id": 5916, "name": "MainProcess"}, "thread": {"id": 10856, "name": "MainThread"}, "time": {"repr": "2024-12-19 16:18:10.624665+06:00", "timestamp": 1734603490.624665}}}
{"text": "2024-12-19 16:21:36.224 | ERROR    | __main__:get_todoist_data:103 - –û—à–∏–±–∫–∞ –≤ completed_tasks_get\n", "record": {"elapsed": {"repr": "0:00:01.324499", "seconds": 1.324499}, "exception": null, "extra": {"exc_info": "unhashable type: 'tzfile'"}, "file": {"name": "save_todoist_data.py", "path": "D:\\–ê–°–£–ü\\Python\\Projects\\OwnBot\\todoist_api\\save_todoist_data.py"}, "function": "get_todoist_data", "level": {"icon": "‚ùå", "name": "ERROR", "no": 40}, "line": 103, "message": "–û—à–∏–±–∫–∞ –≤ completed_tasks_get", "module": "save_todoist_data", "name": "__main__", "process": {"id": 5712, "name": "MainProcess"}, "thread": {"id": 12520, "name": "MainThread"}, "time": {"repr": "2024-12-19 16:21:36.224124+06:00", "timestamp": 1734603696.224124}}}
{"text": "2024-12-19 16:21:36.225 | ERROR    | __main__:get_todoist_data:104 - unhashable type: 'tzfile'\nTraceback (most recent call last):\n\n  File \"D:\\–ê–°–£–ü\\Python\\Projects\\OwnBot\\todoist_api\\save_todoist_data.py\", line 108, in <module>\n    get_todoist_data(token='48cbdb22977eb9d84368aef673d3c7ba7c0f311a')\n    ‚îî <function get_todoist_data at 0x0000027249F8BD80>\n\n> File \"D:\\–ê–°–£–ü\\Python\\Projects\\OwnBot\\todoist_api\\save_todoist_data.py\", line 70, in get_todoist_data\n    tzinfos = {gettz(\"America/Chicago\")}\n               ‚îî <dateutil.tz.tz.__get_gettz.<locals>.GettzFunc object at 0x000002724A31EFC0>\n\nTypeError: unhashable type: 'tzfile'\n", "record": {"elapsed": {"repr": "0:00:01.325500", "seconds": 1.3255}, "exception": {"type": "TypeError", "value": "unhashable type: 'tzfile'", "traceback": true}, "extra": {}, "file": {"name": "save_todoist_data.py", "path": "D:\\–ê–°–£–ü\\Python\\Projects\\OwnBot\\todoist_api\\save_todoist_data.py"}, "function": "get_todoist_data", "level": {"icon": "‚ùå", "name": "ERROR", "no": 40}, "line": 104, "message": "unhashable type: 'tzfile'", "module": "save_todoist_data", "name": "__main__", "process": {"id": 5712, "name": "MainProcess"}, "thread": {"id": 12520, "name": "MainThread"}, "time": {"repr": "2024-12-19 16:21:36.225125+06:00", "timestamp": 1734603696.225125}}}
{"text": "2024-12-19 16:56:25.775 | ERROR    | __main__:get_todoist_data:56 - –û—à–∏–±–∫–∞ –≤ completed_tasks_get\n", "record": {"elapsed": {"repr": "0:00:09.566442", "seconds": 9.566442}, "exception": null, "extra": {}, "file": {"name": "save_todoist_data.py", "path": "D:\\–ê–°–£–ü\\Python\\Projects\\OwnBot\\todoist_api\\save_todoist_data.py"}, "function": "get_todoist_data", "level": {"icon": "‚ùå", "name": "ERROR", "no": 40}, "line": 56, "message": "–û—à–∏–±–∫–∞ –≤ completed_tasks_get", "module": "save_todoist_data", "name": "__main__", "process": {"id": 11644, "name": "MainProcess"}, "thread": {"id": 4180, "name": "MainThread"}, "time": {"repr": "2024-12-19 16:56:25.775262+06:00", "timestamp": 1734605785.775262}}}
{"text": "2024-12-19 16:56:25.775 | ERROR    | __main__:get_todoist_data:57 - 'Task' object has no attribute 'dusdfsdfe'\nTraceback (most recent call last):\n\n  File \"D:\\–ê–°–£–ü\\Python\\Projects\\OwnBot\\todoist_api\\save_todoist_data.py\", line 61, in <module>\n    get_todoist_data(token='48cbdb22977eb9d84368aef673d3c7ba7c0f311a')\n    ‚îî <function get_todoist_data at 0x0000023E8CAD8EA0>\n\n> File \"D:\\–ê–°–£–ü\\Python\\Projects\\OwnBot\\todoist_api\\save_todoist_data.py\", line 49, in get_todoist_data\n    'due': api_task.dusdfsdfe\n           ‚îî Task(assignee_id=None, assigner_id=None, comment_count=0, is_completed=False, content='Med', created_at='2022-12-02T07:44:42....\n\nAttributeError: 'Task' object has no attribute 'dusdfsdfe'\n", "record": {"elapsed": {"repr": "0:00:09.566442", "seconds": 9.566442}, "exception": {"type": "AttributeError", "value": "'Task' object has no attribute 'dusdfsdfe'", "traceback": true}, "extra": {}, "file": {"name": "save_todoist_data.py", "path": "D:\\–ê–°–£–ü\\Python\\Projects\\OwnBot\\todoist_api\\save_todoist_data.py"}, "function": "get_todoist_data", "level": {"icon": "‚ùå", "name": "ERROR", "no": 40}, "line": 57, "message": "'Task' object has no attribute 'dusdfsdfe'", "module": "save_todoist_data", "name": "__main__", "process": {"id": 11644, "name": "MainProcess"}, "thread": {"id": 4180, "name": "MainThread"}, "time": {"repr": "2024-12-19 16:56:25.775262+06:00", "timestamp": 1734605785.775262}}}
{"text": "2024-12-19 17:18:50.362 | ERROR    | __main__:get_todoist_data:87 - –û—à–∏–±–∫–∞ –≤ completed_tasks_get\n", "record": {"elapsed": {"repr": "0:00:00.703054", "seconds": 0.703054}, "exception": null, "extra": {}, "file": {"name": "save_todoist_data.py", "path": "D:\\–ê–°–£–ü\\Python\\Projects\\OwnBot\\todoist_api\\save_todoist_data.py"}, "function": "get_todoist_data", "level": {"icon": "‚ùå", "name": "ERROR", "no": 40}, "line": 87, "message": "–û—à–∏–±–∫–∞ –≤ completed_tasks_get", "module": "save_todoist_data", "name": "__main__", "process": {"id": 11148, "name": "MainProcess"}, "thread": {"id": 7368, "name": "MainThread"}, "time": {"repr": "2024-12-19 17:18:50.362084+06:00", "timestamp": 1734607130.362084}}}
{"text": "2024-12-19 17:18:50.362 | ERROR    | __main__:get_todoist_data:88 - 'projects'\nTraceback (most recent call last):\n\n  File \"D:\\–ê–°–£–ü\\Python\\Projects\\OwnBot\\todoist_api\\save_todoist_data.py\", line 96, in <module>\n    asyncio.run(get_todoist_data(token='48cbdb22977eb9d84368aef673d3c7ba7c0f311a'))\n    ‚îÇ       ‚îÇ   ‚îî <function get_todoist_data at 0x0000019A5EA0E840>\n    ‚îÇ       ‚îî <function run at 0x0000019A5AC60680>\n    ‚îî <module 'asyncio' from 'C:\\\\Users\\\\user-18\\\\AppData\\\\Local\\\\Programs\\\\Python\\\\Python312\\\\Lib\\\\asyncio\\\\__init__.py'>\n\n  File \"C:\\Users\\user-18\\AppData\\Local\\Programs\\Python\\Python312\\Lib\\asyncio\\runners.py\", line 194, in run\n    return runner.run(main)\n           ‚îÇ      ‚îÇ   ‚îî <coroutine object get_todoist_data at 0x0000019A5EB341C0>\n           ‚îÇ      ‚îî <function Runner.run at 0x0000019A5DF35C60>\n           ‚îî <asyncio.runners.Runner object at 0x0000019A5B00FE60>\n  File \"C:\\Users\\user-18\\AppData\\Local\\Programs\\Python\\Python312\\Lib\\asyncio\\runners.py\", line 118, in run\n    return self._loop.run_until_complete(task)\n           ‚îÇ    ‚îÇ     ‚îÇ                  ‚îî <Task pending name='Task-1' coro=<get_todoist_data() running at D:\\–ê–°–£–ü\\Python\\Projects\\OwnBot\\todoist_api\\save_todoist_data....\n           ‚îÇ    ‚îÇ     ‚îî <function BaseEventLoop.run_until_complete at 0x0000019A5DF33740>\n           ‚îÇ    ‚îî <ProactorEventLoop running=True closed=False debug=False>\n           ‚îî <asyncio.runners.Runner object at 0x0000019A5B00FE60>\n  File \"C:\\Users\\user-18\\AppData\\Local\\Programs\\Python\\Python312\\Lib\\asyncio\\base_events.py\", line 673, in run_until_complete\n    self.run_forever()\n    ‚îÇ    ‚îî <function ProactorEventLoop.run_forever at 0x0000019A5DF98D60>\n    ‚îî <ProactorEventLoop running=True closed=False debug=False>\n  File \"C:\\Users\\user-18\\AppData\\Local\\Programs\\Python\\Python312\\Lib\\asyncio\\windows_events.py\", line 322, in run_forever\n    super().run_forever()\n  File \"C:\\Users\\user-18\\AppData\\Local\\Programs\\Python\\Python312\\Lib\\asyncio\\base_events.py\", line 640, in run_forever\n    self._run_once()\n    ‚îÇ    ‚îî <function BaseEventLoop._run_once at 0x0000019A5DF354E0>\n    ‚îî <ProactorEventLoop running=True closed=False debug=False>\n  File \"C:\\Users\\user-18\\AppData\\Local\\Programs\\Python\\Python312\\Lib\\asyncio\\base_events.py\", line 1992, in _run_once\n    handle._run()\n    ‚îÇ      ‚îî <function Handle._run at 0x0000019A5D691440>\n    ‚îî <Handle <_asyncio.TaskStepMethWrapper object at 0x0000019A5EB61FC0>()>\n  File \"C:\\Users\\user-18\\AppData\\Local\\Programs\\Python\\Python312\\Lib\\asyncio\\events.py\", line 88, in _run\n    self._context.run(self._callback, *self._args)\n    ‚îÇ    ‚îÇ            ‚îÇ    ‚îÇ           ‚îÇ    ‚îî <member '_args' of 'Handle' objects>\n    ‚îÇ    ‚îÇ            ‚îÇ    ‚îÇ           ‚îî <Handle <_asyncio.TaskStepMethWrapper object at 0x0000019A5EB61FC0>()>\n    ‚îÇ    ‚îÇ            ‚îÇ    ‚îî <member '_callback' of 'Handle' objects>\n    ‚îÇ    ‚îÇ            ‚îî <Handle <_asyncio.TaskStepMethWrapper object at 0x0000019A5EB61FC0>()>\n    ‚îÇ    ‚îî <member '_context' of 'Handle' objects>\n    ‚îî <Handle <_asyncio.TaskStepMethWrapper object at 0x0000019A5EB61FC0>()>\n\n> File \"D:\\–ê–°–£–ü\\Python\\Projects\\OwnBot\\todoist_api\\save_todoist_data.py\", line 63, in get_todoist_data\n    projects = {value['id']: value['name'] for _, value in response['projects'].items()}\n                                                           ‚îî {'error': 'Invalid token', 'error_code': 401, 'error_extra': {'access_type': 'none', 'event_id': '253638a6e9ac43d396719f1363b...\n\nKeyError: 'projects'\n", "record": {"elapsed": {"repr": "0:00:00.703054", "seconds": 0.703054}, "exception": {"type": "KeyError", "value": "'projects'", "traceback": true}, "extra": {}, "file": {"name": "save_todoist_data.py", "path": "D:\\–ê–°–£–ü\\Python\\Projects\\OwnBot\\todoist_api\\save_todoist_data.py"}, "function": "get_todoist_data", "level": {"icon": "‚ùå", "name": "ERROR", "no": 40}, "line": 88, "message": "'projects'", "module": "save_todoist_data", "name": "__main__", "process": {"id": 11148, "name": "MainProcess"}, "thread": {"id": 7368, "name": "MainThread"}, "time": {"repr": "2024-12-19 17:18:50.362084+06:00", "timestamp": 1734607130.362084}}}
{"text": "2024-12-19 17:19:23.785 | ERROR    | __main__:get_todoist_data:87 - –û—à–∏–±–∫–∞ –≤ completed_tasks_get\n", "record": {"elapsed": {"repr": "0:00:00.510533", "seconds": 0.510533}, "exception": null, "extra": {}, "file": {"name": "save_todoist_data.py", "path": "D:\\–ê–°–£–ü\\Python\\Projects\\OwnBot\\todoist_api\\save_todoist_data.py"}, "function": "get_todoist_data", "level": {"icon": "‚ùå", "name": "ERROR", "no": 40}, "line": 87, "message": "–û—à–∏–±–∫–∞ –≤ completed_tasks_get", "module": "save_todoist_data", "name": "__main__", "process": {"id": 8060, "name": "MainProcess"}, "thread": {"id": 15732, "name": "MainThread"}, "time": {"repr": "2024-12-19 17:19:23.785210+06:00", "timestamp": 1734607163.78521}}}
{"text": "2024-12-19 17:19:23.785 | ERROR    | __main__:get_todoist_data:88 - 'projects'\nTraceback (most recent call last):\n\n  File \"D:\\–ê–°–£–ü\\Python\\Projects\\OwnBot\\todoist_api\\save_todoist_data.py\", line 96, in <module>\n    asyncio.run(get_todoist_data(token='48cbdb22977eb9d84368aef673d3c7ba7c0f311a'))\n    ‚îÇ       ‚îÇ   ‚îî <function get_todoist_data at 0x00000173C8EAE840>\n    ‚îÇ       ‚îî <function run at 0x00000173C5150680>\n    ‚îî <module 'asyncio' from 'C:\\\\Users\\\\user-18\\\\AppData\\\\Local\\\\Programs\\\\Python\\\\Python312\\\\Lib\\\\asyncio\\\\__init__.py'>\n\n  File \"C:\\Users\\user-18\\AppData\\Local\\Programs\\Python\\Python312\\Lib\\asyncio\\runners.py\", line 194, in run\n    return runner.run(main)\n           ‚îÇ      ‚îÇ   ‚îî <coroutine object get_todoist_data at 0x00000173C8FD41C0>\n           ‚îÇ      ‚îî <function Runner.run at 0x00000173C83D5C60>\n           ‚îî <asyncio.runners.Runner object at 0x00000173C54CFE60>\n  File \"C:\\Users\\user-18\\AppData\\Local\\Programs\\Python\\Python312\\Lib\\asyncio\\runners.py\", line 118, in run\n    return self._loop.run_until_complete(task)\n           ‚îÇ    ‚îÇ     ‚îÇ                  ‚îî <Task pending name='Task-1' coro=<get_todoist_data() running at D:\\–ê–°–£–ü\\Python\\Projects\\OwnBot\\todoist_api\\save_todoist_data....\n           ‚îÇ    ‚îÇ     ‚îî <function BaseEventLoop.run_until_complete at 0x00000173C83D3740>\n           ‚îÇ    ‚îî <ProactorEventLoop running=True closed=False debug=False>\n           ‚îî <asyncio.runners.Runner object at 0x00000173C54CFE60>\n  File \"C:\\Users\\user-18\\AppData\\Local\\Programs\\Python\\Python312\\Lib\\asyncio\\base_events.py\", line 673, in run_until_complete\n    self.run_forever()\n    ‚îÇ    ‚îî <function ProactorEventLoop.run_forever at 0x00000173C8438D60>\n    ‚îî <ProactorEventLoop running=True closed=False debug=False>\n  File \"C:\\Users\\user-18\\AppData\\Local\\Programs\\Python\\Python312\\Lib\\asyncio\\windows_events.py\", line 322, in run_forever\n    super().run_forever()\n  File \"C:\\Users\\user-18\\AppData\\Local\\Programs\\Python\\Python312\\Lib\\asyncio\\base_events.py\", line 640, in run_forever\n    self._run_once()\n    ‚îÇ    ‚îî <function BaseEventLoop._run_once at 0x00000173C83D54E0>\n    ‚îî <ProactorEventLoop running=True closed=False debug=False>\n  File \"C:\\Users\\user-18\\AppData\\Local\\Programs\\Python\\Python312\\Lib\\asyncio\\base_events.py\", line 1992, in _run_once\n    handle._run()\n    ‚îÇ      ‚îî <function Handle._run at 0x00000173C7B31440>\n    ‚îî <Handle <_asyncio.TaskStepMethWrapper object at 0x00000173C9002170>()>\n  File \"C:\\Users\\user-18\\AppData\\Local\\Programs\\Python\\Python312\\Lib\\asyncio\\events.py\", line 88, in _run\n    self._context.run(self._callback, *self._args)\n    ‚îÇ    ‚îÇ            ‚îÇ    ‚îÇ           ‚îÇ    ‚îî <member '_args' of 'Handle' objects>\n    ‚îÇ    ‚îÇ            ‚îÇ    ‚îÇ           ‚îî <Handle <_asyncio.TaskStepMethWrapper object at 0x00000173C9002170>()>\n    ‚îÇ    ‚îÇ            ‚îÇ    ‚îî <member '_callback' of 'Handle' objects>\n    ‚îÇ    ‚îÇ            ‚îî <Handle <_asyncio.TaskStepMethWrapper object at 0x00000173C9002170>()>\n    ‚îÇ    ‚îî <member '_context' of 'Handle' objects>\n    ‚îî <Handle <_asyncio.TaskStepMethWrapper object at 0x00000173C9002170>()>\n\n> File \"D:\\–ê–°–£–ü\\Python\\Projects\\OwnBot\\todoist_api\\save_todoist_data.py\", line 63, in get_todoist_data\n    projects = {value['id']: value['name'] for _, value in response['projects'].items()}\n                                                           ‚îî {'error': 'Invalid token', 'error_code': 401, 'error_extra': {'access_type': 'none', 'event_id': '294595fab66b4950b14f39061cc...\n\nKeyError: 'projects'\n", "record": {"elapsed": {"repr": "0:00:00.510533", "seconds": 0.510533}, "exception": {"type": "KeyError", "value": "'projects'", "traceback": true}, "extra": {}, "file": {"name": "save_todoist_data.py", "path": "D:\\–ê–°–£–ü\\Python\\Projects\\OwnBot\\todoist_api\\save_todoist_data.py"}, "function": "get_todoist_data", "level": {"icon": "‚ùå", "name": "ERROR", "no": 40}, "line": 88, "message": "'projects'", "module": "save_todoist_data", "name": "__main__", "process": {"id": 8060, "name": "MainProcess"}, "thread": {"id": 15732, "name": "MainThread"}, "time": {"repr": "2024-12-19 17:19:23.785210+06:00", "timestamp": 1734607163.78521}}}
{"text": "2024-12-19 17:33:14.920 | ERROR    | __main__:get_todoist_data:60 - –û—à–∏–±–∫–∞ –≤ completed_tasks_get\n", "record": {"elapsed": {"repr": "0:00:04.349568", "seconds": 4.349568}, "exception": null, "extra": {}, "file": {"name": "save_todoist_data.py", "path": "D:\\–ê–°–£–ü\\Python\\Projects\\OwnBot\\todoist_api\\save_todoist_data.py"}, "function": "get_todoist_data", "level": {"icon": "‚ùå", "name": "ERROR", "no": 40}, "line": 60, "message": "–û—à–∏–±–∫–∞ –≤ completed_tasks_get", "module": "save_todoist_data", "name": "__main__", "process": {"id": 6512, "name": "MainProcess"}, "thread": {"id": 9448, "name": "MainThread"}, "time": {"repr": "2024-12-19 17:33:14.920075+06:00", "timestamp": 1734607994.920075}}}
{"text": "2024-12-19 17:33:14.920 | ERROR    | __main__:get_todoist_data:61 - 'async for' requires an object with __aiter__ method, got list\nTraceback (most recent call last):\n\n  File \"D:\\–ê–°–£–ü\\Python\\Projects\\OwnBot\\todoist_api\\save_todoist_data.py\", line 69, in <module>\n    print(asyncio.run(get_todoist_data(token='48cbdb22977eb9d84368aef673d3c7ba7c0f311a')))\n          ‚îÇ       ‚îÇ   ‚îî <function get_todoist_data at 0x000001FBBA009BC0>\n          ‚îÇ       ‚îî <function run at 0x000001FBB9CF0680>\n          ‚îî <module 'asyncio' from 'C:\\\\Users\\\\user-18\\\\AppData\\\\Local\\\\Programs\\\\Python\\\\Python312\\\\Lib\\\\asyncio\\\\__init__.py'>\n\n  File \"C:\\Users\\user-18\\AppData\\Local\\Programs\\Python\\Python312\\Lib\\asyncio\\runners.py\", line 194, in run\n    return runner.run(main)\n           ‚îÇ      ‚îÇ   ‚îî <coroutine object get_todoist_data at 0x000001FBBDBA01C0>\n           ‚îÇ      ‚îî <function Runner.run at 0x000001FBBCF95C60>\n           ‚îî <asyncio.runners.Runner object at 0x000001FBBA02FE60>\n  File \"C:\\Users\\user-18\\AppData\\Local\\Programs\\Python\\Python312\\Lib\\asyncio\\runners.py\", line 118, in run\n    return self._loop.run_until_complete(task)\n           ‚îÇ    ‚îÇ     ‚îÇ                  ‚îî <Task pending name='Task-1' coro=<get_todoist_data() running at D:\\–ê–°–£–ü\\Python\\Projects\\OwnBot\\todoist_api\\save_todoist_data....\n           ‚îÇ    ‚îÇ     ‚îî <function BaseEventLoop.run_until_complete at 0x000001FBBCF93740>\n           ‚îÇ    ‚îî <ProactorEventLoop running=True closed=False debug=False>\n           ‚îî <asyncio.runners.Runner object at 0x000001FBBA02FE60>\n  File \"C:\\Users\\user-18\\AppData\\Local\\Programs\\Python\\Python312\\Lib\\asyncio\\base_events.py\", line 673, in run_until_complete\n    self.run_forever()\n    ‚îÇ    ‚îî <function ProactorEventLoop.run_forever at 0x000001FBBCFF8D60>\n    ‚îî <ProactorEventLoop running=True closed=False debug=False>\n  File \"C:\\Users\\user-18\\AppData\\Local\\Programs\\Python\\Python312\\Lib\\asyncio\\windows_events.py\", line 322, in run_forever\n    super().run_forever()\n  File \"C:\\Users\\user-18\\AppData\\Local\\Programs\\Python\\Python312\\Lib\\asyncio\\base_events.py\", line 640, in run_forever\n    self._run_once()\n    ‚îÇ    ‚îî <function BaseEventLoop._run_once at 0x000001FBBCF954E0>\n    ‚îî <ProactorEventLoop running=True closed=False debug=False>\n  File \"C:\\Users\\user-18\\AppData\\Local\\Programs\\Python\\Python312\\Lib\\asyncio\\base_events.py\", line 1992, in _run_once\n    handle._run()\n    ‚îÇ      ‚îî <function Handle._run at 0x000001FBBC6ED440>\n    ‚îî <Handle <_asyncio.TaskStepMethWrapper object at 0x000001FBBDBADB40>()>\n  File \"C:\\Users\\user-18\\AppData\\Local\\Programs\\Python\\Python312\\Lib\\asyncio\\events.py\", line 88, in _run\n    self._context.run(self._callback, *self._args)\n    ‚îÇ    ‚îÇ            ‚îÇ    ‚îÇ           ‚îÇ    ‚îî <member '_args' of 'Handle' objects>\n    ‚îÇ    ‚îÇ            ‚îÇ    ‚îÇ           ‚îî <Handle <_asyncio.TaskStepMethWrapper object at 0x000001FBBDBADB40>()>\n    ‚îÇ    ‚îÇ            ‚îÇ    ‚îî <member '_callback' of 'Handle' objects>\n    ‚îÇ    ‚îÇ            ‚îî <Handle <_asyncio.TaskStepMethWrapper object at 0x000001FBBDBADB40>()>\n    ‚îÇ    ‚îî <member '_context' of 'Handle' objects>\n    ‚îî <Handle <_asyncio.TaskStepMethWrapper object at 0x000001FBBDBADB40>()>\n\n> File \"D:\\–ê–°–£–ü\\Python\\Projects\\OwnBot\\todoist_api\\save_todoist_data.py\", line 41, in get_todoist_data\n    async for task_id in tasks:\n                         ‚îî [('6402304524', '2024-12-19T02:15:30.000000Z'), ('6402304085', '2024-12-19T02:15:29.000000Z'), ('7586598774', '2024-12-18T16:...\n\nTypeError: 'async for' requires an object with __aiter__ method, got list\n", "record": {"elapsed": {"repr": "0:00:04.349568", "seconds": 4.349568}, "exception": {"type": "TypeError", "value": "'async for' requires an object with __aiter__ method, got list", "traceback": true}, "extra": {}, "file": {"name": "save_todoist_data.py", "path": "D:\\–ê–°–£–ü\\Python\\Projects\\OwnBot\\todoist_api\\save_todoist_data.py"}, "function": "get_todoist_data", "level": {"icon": "‚ùå", "name": "ERROR", "no": 40}, "line": 61, "message": "'async for' requires an object with __aiter__ method, got list", "module": "save_todoist_data", "name": "__main__", "process": {"id": 6512, "name": "MainProcess"}, "thread": {"id": 9448, "name": "MainThread"}, "time": {"repr": "2024-12-19 17:33:14.920075+06:00", "timestamp": 1734607994.920075}}}
{"text": "2024-12-19 17:35:36.789 | ERROR    | __main__:get_todoist_data:72 - –û—à–∏–±–∫–∞ –≤ completed_tasks_get\n", "record": {"elapsed": {"repr": "0:00:00.598582", "seconds": 0.598582}, "exception": null, "extra": {}, "file": {"name": "save_todoist_data.py", "path": "D:\\–ê–°–£–ü\\Python\\Projects\\OwnBot\\todoist_api\\save_todoist_data.py"}, "function": "get_todoist_data", "level": {"icon": "‚ùå", "name": "ERROR", "no": 40}, "line": 72, "message": "–û—à–∏–±–∫–∞ –≤ completed_tasks_get", "module": "save_todoist_data", "name": "__main__", "process": {"id": 8228, "name": "MainProcess"}, "thread": {"id": 16024, "name": "MainThread"}, "time": {"repr": "2024-12-19 17:35:36.789940+06:00", "timestamp": 1734608136.78994}}}
{"text": "2024-12-19 17:35:36.790 | ERROR    | __main__:get_todoist_data:73 - 'async for' requires an object with __aiter__ method, got coroutine\nTraceback (most recent call last):\n\n  File \"D:\\–ê–°–£–ü\\Python\\Projects\\OwnBot\\todoist_api\\save_todoist_data.py\", line 81, in <module>\n    print(asyncio.run(get_todoist_data(token='48cbdb22977eb9d84368aef673d3c7ba7c0f311a')))\n          ‚îÇ       ‚îÇ   ‚îî <function get_todoist_data at 0x0000021DBD0F9BC0>\n          ‚îÇ       ‚îî <function run at 0x0000021DBCDC0680>\n          ‚îî <module 'asyncio' from 'C:\\\\Users\\\\user-18\\\\AppData\\\\Local\\\\Programs\\\\Python\\\\Python312\\\\Lib\\\\asyncio\\\\__init__.py'>\n\n  File \"C:\\Users\\user-18\\AppData\\Local\\Programs\\Python\\Python312\\Lib\\asyncio\\runners.py\", line 194, in run\n    return runner.run(main)\n           ‚îÇ      ‚îÇ   ‚îî <coroutine object get_todoist_data at 0x0000021DC0C941C0>\n           ‚îÇ      ‚îî <function Runner.run at 0x0000021DC0085C60>\n           ‚îî <asyncio.runners.Runner object at 0x0000021DC0B2F290>\n  File \"C:\\Users\\user-18\\AppData\\Local\\Programs\\Python\\Python312\\Lib\\asyncio\\runners.py\", line 118, in run\n    return self._loop.run_until_complete(task)\n           ‚îÇ    ‚îÇ     ‚îÇ                  ‚îî <Task pending name='Task-1' coro=<get_todoist_data() running at D:\\–ê–°–£–ü\\Python\\Projects\\OwnBot\\todoist_api\\save_todoist_data....\n           ‚îÇ    ‚îÇ     ‚îî <function BaseEventLoop.run_until_complete at 0x0000021DC0083740>\n           ‚îÇ    ‚îî <ProactorEventLoop running=True closed=False debug=False>\n           ‚îî <asyncio.runners.Runner object at 0x0000021DC0B2F290>\n  File \"C:\\Users\\user-18\\AppData\\Local\\Programs\\Python\\Python312\\Lib\\asyncio\\base_events.py\", line 673, in run_until_complete\n    self.run_forever()\n    ‚îÇ    ‚îî <function ProactorEventLoop.run_forever at 0x0000021DC00E8D60>\n    ‚îî <ProactorEventLoop running=True closed=False debug=False>\n  File \"C:\\Users\\user-18\\AppData\\Local\\Programs\\Python\\Python312\\Lib\\asyncio\\windows_events.py\", line 322, in run_forever\n    super().run_forever()\n  File \"C:\\Users\\user-18\\AppData\\Local\\Programs\\Python\\Python312\\Lib\\asyncio\\base_events.py\", line 640, in run_forever\n    self._run_once()\n    ‚îÇ    ‚îî <function BaseEventLoop._run_once at 0x0000021DC00854E0>\n    ‚îî <ProactorEventLoop running=True closed=False debug=False>\n  File \"C:\\Users\\user-18\\AppData\\Local\\Programs\\Python\\Python312\\Lib\\asyncio\\base_events.py\", line 1992, in _run_once\n    handle._run()\n    ‚îÇ      ‚îî <function Handle._run at 0x0000021DBF7DD440>\n    ‚îî <Handle <_asyncio.TaskStepMethWrapper object at 0x0000021DC0C9F5E0>()>\n  File \"C:\\Users\\user-18\\AppData\\Local\\Programs\\Python\\Python312\\Lib\\asyncio\\events.py\", line 88, in _run\n    self._context.run(self._callback, *self._args)\n    ‚îÇ    ‚îÇ            ‚îÇ    ‚îÇ           ‚îÇ    ‚îî <member '_args' of 'Handle' objects>\n    ‚îÇ    ‚îÇ            ‚îÇ    ‚îÇ           ‚îî <Handle <_asyncio.TaskStepMethWrapper object at 0x0000021DC0C9F5E0>()>\n    ‚îÇ    ‚îÇ            ‚îÇ    ‚îî <member '_callback' of 'Handle' objects>\n    ‚îÇ    ‚îÇ            ‚îî <Handle <_asyncio.TaskStepMethWrapper object at 0x0000021DC0C9F5E0>()>\n    ‚îÇ    ‚îî <member '_context' of 'Handle' objects>\n    ‚îî <Handle <_asyncio.TaskStepMethWrapper object at 0x0000021DC0C9F5E0>()>\n\n> File \"D:\\–ê–°–£–ü\\Python\\Projects\\OwnBot\\todoist_api\\save_todoist_data.py\", line 53, in get_todoist_data\n    async for task_id in process_tasks():\n                         ‚îî <function get_todoist_data.<locals>.process_tasks at 0x0000021DC0CB8EA0>\n\nTypeError: 'async for' requires an object with __aiter__ method, got coroutine\n", "record": {"elapsed": {"repr": "0:00:00.599583", "seconds": 0.599583}, "exception": {"type": "TypeError", "value": "'async for' requires an object with __aiter__ method, got coroutine", "traceback": true}, "extra": {}, "file": {"name": "save_todoist_data.py", "path": "D:\\–ê–°–£–ü\\Python\\Projects\\OwnBot\\todoist_api\\save_todoist_data.py"}, "function": "get_todoist_data", "level": {"icon": "‚ùå", "name": "ERROR", "no": 40}, "line": 73, "message": "'async for' requires an object with __aiter__ method, got coroutine", "module": "save_todoist_data", "name": "__main__", "process": {"id": 8228, "name": "MainProcess"}, "thread": {"id": 16024, "name": "MainThread"}, "time": {"repr": "2024-12-19 17:35:36.790941+06:00", "timestamp": 1734608136.790941}}}
{"text": "2024-12-19 17:37:08.837 | ERROR    | __main__:get_todoist_data:73 - –û—à–∏–±–∫–∞ –≤ completed_tasks_get\n", "record": {"elapsed": {"repr": "0:00:08.059065", "seconds": 8.059065}, "exception": null, "extra": {}, "file": {"name": "save_todoist_data.py", "path": "D:\\–ê–°–£–ü\\Python\\Projects\\OwnBot\\todoist_api\\save_todoist_data.py"}, "function": "get_todoist_data", "level": {"icon": "‚ùå", "name": "ERROR", "no": 40}, "line": 73, "message": "–û—à–∏–±–∫–∞ –≤ completed_tasks_get", "module": "save_todoist_data", "name": "__main__", "process": {"id": 14032, "name": "MainProcess"}, "thread": {"id": 7768, "name": "MainThread"}, "time": {"repr": "2024-12-19 17:37:08.837497+06:00", "timestamp": 1734608228.837497}}}
{"text": "2024-12-19 17:37:08.837 | ERROR    | __main__:get_todoist_data:74 - 'async for' requires an object with __aiter__ method, got coroutine\nTraceback (most recent call last):\n\n  File \"D:\\–ê–°–£–ü\\Python\\Projects\\OwnBot\\todoist_api\\save_todoist_data.py\", line 82, in <module>\n    print(asyncio.run(get_todoist_data(token='48cbdb22977eb9d84368aef673d3c7ba7c0f311a')))\n          ‚îÇ       ‚îÇ   ‚îî <function get_todoist_data at 0x0000023CEE469BC0>\n          ‚îÇ       ‚îî <function run at 0x0000023CEE070680>\n          ‚îî <module 'asyncio' from 'C:\\\\Users\\\\user-18\\\\AppData\\\\Local\\\\Programs\\\\Python\\\\Python312\\\\Lib\\\\asyncio\\\\__init__.py'>\n\n  File \"C:\\Users\\user-18\\AppData\\Local\\Programs\\Python\\Python312\\Lib\\asyncio\\runners.py\", line 194, in run\n    return runner.run(main)\n           ‚îÇ      ‚îÇ   ‚îî <coroutine object get_todoist_data at 0x0000023CF1F441C0>\n           ‚îÇ      ‚îî <function Runner.run at 0x0000023CF12E5C60>\n           ‚îî <asyncio.runners.Runner object at 0x0000023CF1E04800>\n  File \"C:\\Users\\user-18\\AppData\\Local\\Programs\\Python\\Python312\\Lib\\asyncio\\runners.py\", line 118, in run\n    return self._loop.run_until_complete(task)\n           ‚îÇ    ‚îÇ     ‚îÇ                  ‚îî <Task pending name='Task-1' coro=<get_todoist_data() running at D:\\–ê–°–£–ü\\Python\\Projects\\OwnBot\\todoist_api\\save_todoist_data....\n           ‚îÇ    ‚îÇ     ‚îî <function BaseEventLoop.run_until_complete at 0x0000023CF12E3740>\n           ‚îÇ    ‚îî <ProactorEventLoop running=True closed=False debug=False>\n           ‚îî <asyncio.runners.Runner object at 0x0000023CF1E04800>\n  File \"C:\\Users\\user-18\\AppData\\Local\\Programs\\Python\\Python312\\Lib\\asyncio\\base_events.py\", line 673, in run_until_complete\n    self.run_forever()\n    ‚îÇ    ‚îî <function ProactorEventLoop.run_forever at 0x0000023CF1348D60>\n    ‚îî <ProactorEventLoop running=True closed=False debug=False>\n  File \"C:\\Users\\user-18\\AppData\\Local\\Programs\\Python\\Python312\\Lib\\asyncio\\windows_events.py\", line 322, in run_forever\n    super().run_forever()\n  File \"C:\\Users\\user-18\\AppData\\Local\\Programs\\Python\\Python312\\Lib\\asyncio\\base_events.py\", line 640, in run_forever\n    self._run_once()\n    ‚îÇ    ‚îî <function BaseEventLoop._run_once at 0x0000023CF12E54E0>\n    ‚îî <ProactorEventLoop running=True closed=False debug=False>\n  File \"C:\\Users\\user-18\\AppData\\Local\\Programs\\Python\\Python312\\Lib\\asyncio\\base_events.py\", line 1992, in _run_once\n    handle._run()\n    ‚îÇ      ‚îî <function Handle._run at 0x0000023CF0A6D440>\n    ‚îî <Handle <_asyncio.TaskStepMethWrapper object at 0x0000023CF1F4F370>()>\n  File \"C:\\Users\\user-18\\AppData\\Local\\Programs\\Python\\Python312\\Lib\\asyncio\\events.py\", line 88, in _run\n    self._context.run(self._callback, *self._args)\n    ‚îÇ    ‚îÇ            ‚îÇ    ‚îÇ           ‚îÇ    ‚îî <member '_args' of 'Handle' objects>\n    ‚îÇ    ‚îÇ            ‚îÇ    ‚îÇ           ‚îî <Handle <_asyncio.TaskStepMethWrapper object at 0x0000023CF1F4F370>()>\n    ‚îÇ    ‚îÇ            ‚îÇ    ‚îî <member '_callback' of 'Handle' objects>\n    ‚îÇ    ‚îÇ            ‚îî <Handle <_asyncio.TaskStepMethWrapper object at 0x0000023CF1F4F370>()>\n    ‚îÇ    ‚îî <member '_context' of 'Handle' objects>\n    ‚îî <Handle <_asyncio.TaskStepMethWrapper object at 0x0000023CF1F4F370>()>\n\n> File \"D:\\–ê–°–£–ü\\Python\\Projects\\OwnBot\\todoist_api\\save_todoist_data.py\", line 54, in get_todoist_data\n    async for task_id in process_tasks():\n                         ‚îî <function get_todoist_data.<locals>.process_tasks at 0x0000023CF1F68EA0>\n\nTypeError: 'async for' requires an object with __aiter__ method, got coroutine\n", "record": {"elapsed": {"repr": "0:00:08.059065", "seconds": 8.059065}, "exception": {"type": "TypeError", "value": "'async for' requires an object with __aiter__ method, got coroutine", "traceback": true}, "extra": {}, "file": {"name": "save_todoist_data.py", "path": "D:\\–ê–°–£–ü\\Python\\Projects\\OwnBot\\todoist_api\\save_todoist_data.py"}, "function": "get_todoist_data", "level": {"icon": "‚ùå", "name": "ERROR", "no": 40}, "line": 74, "message": "'async for' requires an object with __aiter__ method, got coroutine", "module": "save_todoist_data", "name": "__main__", "process": {"id": 14032, "name": "MainProcess"}, "thread": {"id": 7768, "name": "MainThread"}, "time": {"repr": "2024-12-19 17:37:08.837497+06:00", "timestamp": 1734608228.837497}}}
{"text": "2024-12-19 17:37:19.057 | ERROR    | __main__:get_todoist_data:73 - –û—à–∏–±–∫–∞ –≤ completed_tasks_get\n", "record": {"elapsed": {"repr": "0:00:00.493073", "seconds": 0.493073}, "exception": null, "extra": {}, "file": {"name": "save_todoist_data.py", "path": "D:\\–ê–°–£–ü\\Python\\Projects\\OwnBot\\todoist_api\\save_todoist_data.py"}, "function": "get_todoist_data", "level": {"icon": "‚ùå", "name": "ERROR", "no": 40}, "line": 73, "message": "–û—à–∏–±–∫–∞ –≤ completed_tasks_get", "module": "save_todoist_data", "name": "__main__", "process": {"id": 13084, "name": "MainProcess"}, "thread": {"id": 2544, "name": "MainThread"}, "time": {"repr": "2024-12-19 17:37:19.057189+06:00", "timestamp": 1734608239.057189}}}
{"text": "2024-12-19 17:37:19.057 | ERROR    | __main__:get_todoist_data:74 - 'async for' requires an object with __aiter__ method, got coroutine\nTraceback (most recent call last):\n\n  File \"D:\\–ê–°–£–ü\\Python\\Projects\\OwnBot\\todoist_api\\save_todoist_data.py\", line 82, in <module>\n    print(asyncio.run(get_todoist_data(token='48cbdb22977eb9d84368aef673d3c7ba7c0f311a')))\n          ‚îÇ       ‚îÇ   ‚îî <function get_todoist_data at 0x000001BE1FEF9BC0>\n          ‚îÇ       ‚îî <function run at 0x000001BE1FB20680>\n          ‚îî <module 'asyncio' from 'C:\\\\Users\\\\user-18\\\\AppData\\\\Local\\\\Programs\\\\Python\\\\Python312\\\\Lib\\\\asyncio\\\\__init__.py'>\n\n  File \"C:\\Users\\user-18\\AppData\\Local\\Programs\\Python\\Python312\\Lib\\asyncio\\runners.py\", line 194, in run\n    return runner.run(main)\n           ‚îÇ      ‚îÇ   ‚îî <coroutine object get_todoist_data at 0x000001BE239FC340>\n           ‚îÇ      ‚îî <function Runner.run at 0x000001BE22DF5C60>\n           ‚îî <asyncio.runners.Runner object at 0x000001BE238C4800>\n  File \"C:\\Users\\user-18\\AppData\\Local\\Programs\\Python\\Python312\\Lib\\asyncio\\runners.py\", line 118, in run\n    return self._loop.run_until_complete(task)\n           ‚îÇ    ‚îÇ     ‚îÇ                  ‚îî <Task pending name='Task-1' coro=<get_todoist_data() running at D:\\–ê–°–£–ü\\Python\\Projects\\OwnBot\\todoist_api\\save_todoist_data....\n           ‚îÇ    ‚îÇ     ‚îî <function BaseEventLoop.run_until_complete at 0x000001BE22DF3740>\n           ‚îÇ    ‚îî <ProactorEventLoop running=True closed=False debug=False>\n           ‚îî <asyncio.runners.Runner object at 0x000001BE238C4800>\n  File \"C:\\Users\\user-18\\AppData\\Local\\Programs\\Python\\Python312\\Lib\\asyncio\\base_events.py\", line 673, in run_until_complete\n    self.run_forever()\n    ‚îÇ    ‚îî <function ProactorEventLoop.run_forever at 0x000001BE22E5CD60>\n    ‚îî <ProactorEventLoop running=True closed=False debug=False>\n  File \"C:\\Users\\user-18\\AppData\\Local\\Programs\\Python\\Python312\\Lib\\asyncio\\windows_events.py\", line 322, in run_forever\n    super().run_forever()\n  File \"C:\\Users\\user-18\\AppData\\Local\\Programs\\Python\\Python312\\Lib\\asyncio\\base_events.py\", line 640, in run_forever\n    self._run_once()\n    ‚îÇ    ‚îî <function BaseEventLoop._run_once at 0x000001BE22DF54E0>\n    ‚îî <ProactorEventLoop running=True closed=False debug=False>\n  File \"C:\\Users\\user-18\\AppData\\Local\\Programs\\Python\\Python312\\Lib\\asyncio\\base_events.py\", line 1992, in _run_once\n    handle._run()\n    ‚îÇ      ‚îî <function Handle._run at 0x000001BE2254D440>\n    ‚îî <Handle <_asyncio.TaskStepMethWrapper object at 0x000001BE20420880>()>\n  File \"C:\\Users\\user-18\\AppData\\Local\\Programs\\Python\\Python312\\Lib\\asyncio\\events.py\", line 88, in _run\n    self._context.run(self._callback, *self._args)\n    ‚îÇ    ‚îÇ            ‚îÇ    ‚îÇ           ‚îÇ    ‚îî <member '_args' of 'Handle' objects>\n    ‚îÇ    ‚îÇ            ‚îÇ    ‚îÇ           ‚îî <Handle <_asyncio.TaskStepMethWrapper object at 0x000001BE20420880>()>\n    ‚îÇ    ‚îÇ            ‚îÇ    ‚îî <member '_callback' of 'Handle' objects>\n    ‚îÇ    ‚îÇ            ‚îî <Handle <_asyncio.TaskStepMethWrapper object at 0x000001BE20420880>()>\n    ‚îÇ    ‚îî <member '_context' of 'Handle' objects>\n    ‚îî <Handle <_asyncio.TaskStepMethWrapper object at 0x000001BE20420880>()>\n\n> File \"D:\\–ê–°–£–ü\\Python\\Projects\\OwnBot\\todoist_api\\save_todoist_data.py\", line 54, in get_todoist_data\n    async for task_id in process_tasks():\n                         ‚îî <function get_todoist_data.<locals>.process_tasks at 0x000001BE23A28EA0>\n\nTypeError: 'async for' requires an object with __aiter__ method, got coroutine\n", "record": {"elapsed": {"repr": "0:00:00.493073", "seconds": 0.493073}, "exception": {"type": "TypeError", "value": "'async for' requires an object with __aiter__ method, got coroutine", "traceback": true}, "extra": {}, "file": {"name": "save_todoist_data.py", "path": "D:\\–ê–°–£–ü\\Python\\Projects\\OwnBot\\todoist_api\\save_todoist_data.py"}, "function": "get_todoist_data", "level": {"icon": "‚ùå", "name": "ERROR", "no": 40}, "line": 74, "message": "'async for' requires an object with __aiter__ method, got coroutine", "module": "save_todoist_data", "name": "__main__", "process": {"id": 13084, "name": "MainProcess"}, "thread": {"id": 2544, "name": "MainThread"}, "time": {"repr": "2024-12-19 17:37:19.057189+06:00", "timestamp": 1734608239.057189}}}
{"text": "2024-12-19 17:40:50.620 | ERROR    | __main__:get_todoist_data:99 - –û—à–∏–±–∫–∞ –≤ completed_tasks_get\n", "record": {"elapsed": {"repr": "0:00:00.611091", "seconds": 0.611091}, "exception": null, "extra": {}, "file": {"name": "save_todoist_data.py", "path": "D:\\–ê–°–£–ü\\Python\\Projects\\OwnBot\\todoist_api\\save_todoist_data.py"}, "function": "get_todoist_data", "level": {"icon": "‚ùå", "name": "ERROR", "no": 40}, "line": 99, "message": "–û—à–∏–±–∫–∞ –≤ completed_tasks_get", "module": "save_todoist_data", "name": "__main__", "process": {"id": 12144, "name": "MainProcess"}, "thread": {"id": 8800, "name": "MainThread"}, "time": {"repr": "2024-12-19 17:40:50.620599+06:00", "timestamp": 1734608450.620599}}}
{"text": "2024-12-19 17:40:50.620 | ERROR    | __main__:get_todoist_data:100 - object of type 'type' has no len()\nTraceback (most recent call last):\n\n  File \"D:\\–ê–°–£–ü\\Python\\Projects\\OwnBot\\todoist_api\\save_todoist_data.py\", line 108, in <module>\n    print(asyncio.run(get_todoist_data(token='48cbdb22977eb9d84368aef673d3c7ba7c0f311a')))\n          ‚îÇ       ‚îÇ   ‚îî <function get_todoist_data at 0x000001CB1A7E8EA0>\n          ‚îÇ       ‚îî <function run at 0x000001CB1A4D0680>\n          ‚îî <module 'asyncio' from 'C:\\\\Users\\\\user-18\\\\AppData\\\\Local\\\\Programs\\\\Python\\\\Python312\\\\Lib\\\\asyncio\\\\__init__.py'>\n\n  File \"C:\\Users\\user-18\\AppData\\Local\\Programs\\Python\\Python312\\Lib\\asyncio\\runners.py\", line 194, in run\n    return runner.run(main)\n           ‚îÇ      ‚îÇ   ‚îî <coroutine object get_todoist_data at 0x000001CB1CCC1620>\n           ‚îÇ      ‚îî <function Runner.run at 0x000001CB1D6F5C60>\n           ‚îî <asyncio.runners.Runner object at 0x000001CB1E22FA40>\n  File \"C:\\Users\\user-18\\AppData\\Local\\Programs\\Python\\Python312\\Lib\\asyncio\\runners.py\", line 118, in run\n    return self._loop.run_until_complete(task)\n           ‚îÇ    ‚îÇ     ‚îÇ                  ‚îî <Task pending name='Task-1' coro=<get_todoist_data() running at D:\\–ê–°–£–ü\\Python\\Projects\\OwnBot\\todoist_api\\save_todoist_data....\n           ‚îÇ    ‚îÇ     ‚îî <function BaseEventLoop.run_until_complete at 0x000001CB1D6F3740>\n           ‚îÇ    ‚îî <ProactorEventLoop running=True closed=False debug=False>\n           ‚îî <asyncio.runners.Runner object at 0x000001CB1E22FA40>\n  File \"C:\\Users\\user-18\\AppData\\Local\\Programs\\Python\\Python312\\Lib\\asyncio\\base_events.py\", line 673, in run_until_complete\n    self.run_forever()\n    ‚îÇ    ‚îî <function ProactorEventLoop.run_forever at 0x000001CB1D758D60>\n    ‚îî <ProactorEventLoop running=True closed=False debug=False>\n  File \"C:\\Users\\user-18\\AppData\\Local\\Programs\\Python\\Python312\\Lib\\asyncio\\windows_events.py\", line 322, in run_forever\n    super().run_forever()\n  File \"C:\\Users\\user-18\\AppData\\Local\\Programs\\Python\\Python312\\Lib\\asyncio\\base_events.py\", line 640, in run_forever\n    self._run_once()\n    ‚îÇ    ‚îî <function BaseEventLoop._run_once at 0x000001CB1D6F54E0>\n    ‚îî <ProactorEventLoop running=True closed=False debug=False>\n  File \"C:\\Users\\user-18\\AppData\\Local\\Programs\\Python\\Python312\\Lib\\asyncio\\base_events.py\", line 1992, in _run_once\n    handle._run()\n    ‚îÇ      ‚îî <function Handle._run at 0x000001CB1CE4D440>\n    ‚îî <Handle <_asyncio.TaskStepMethWrapper object at 0x000001CB1E30BF40>()>\n  File \"C:\\Users\\user-18\\AppData\\Local\\Programs\\Python\\Python312\\Lib\\asyncio\\events.py\", line 88, in _run\n    self._context.run(self._callback, *self._args)\n    ‚îÇ    ‚îÇ            ‚îÇ    ‚îÇ           ‚îÇ    ‚îî <member '_args' of 'Handle' objects>\n    ‚îÇ    ‚îÇ            ‚îÇ    ‚îÇ           ‚îî <Handle <_asyncio.TaskStepMethWrapper object at 0x000001CB1E30BF40>()>\n    ‚îÇ    ‚îÇ            ‚îÇ    ‚îî <member '_callback' of 'Handle' objects>\n    ‚îÇ    ‚îÇ            ‚îî <Handle <_asyncio.TaskStepMethWrapper object at 0x000001CB1E30BF40>()>\n    ‚îÇ    ‚îî <member '_context' of 'Handle' objects>\n    ‚îî <Handle <_asyncio.TaskStepMethWrapper object at 0x000001CB1E30BF40>()>\n\n> File \"D:\\–ê–°–£–ü\\Python\\Projects\\OwnBot\\todoist_api\\save_todoist_data.py\", line 80, in get_todoist_data\n    async for task_id in aslist:\n                         ‚îî [('6402304524', '2024-12-17T01:12:12.000000Z')]\n\n  File \"D:\\–ê–°–£–ü\\Python\\Projects\\OwnBot\\todoist_api\\save_todoist_data.py\", line 30, in __anext__\n    if self.index < len(self.data):\n       ‚îÇ    ‚îÇ           ‚îÇ    ‚îî <class 'object'>\n       ‚îÇ    ‚îÇ           ‚îî [('6402304524', '2024-12-17T01:12:12.000000Z')]\n       ‚îÇ    ‚îî 0\n       ‚îî [('6402304524', '2024-12-17T01:12:12.000000Z')]\n\nTypeError: object of type 'type' has no len()\n", "record": {"elapsed": {"repr": "0:00:00.611091", "seconds": 0.611091}, "exception": {"type": "TypeError", "value": "object of type 'type' has no len()", "traceback": true}, "extra": {}, "file": {"name": "save_todoist_data.py", "path": "D:\\–ê–°–£–ü\\Python\\Projects\\OwnBot\\todoist_api\\save_todoist_data.py"}, "function": "get_todoist_data", "level": {"icon": "‚ùå", "name": "ERROR", "no": 40}, "line": 100, "message": "object of type 'type' has no len()", "module": "save_todoist_data", "name": "__main__", "process": {"id": 12144, "name": "MainProcess"}, "thread": {"id": 8800, "name": "MainThread"}, "time": {"repr": "2024-12-19 17:40:50.620599+06:00", "timestamp": 1734608450.620599}}}
{"text": "2024-12-19 17:44:14.514 | ERROR    | __main__:get_todoist_data:98 - –û—à–∏–±–∫–∞ –≤ completed_tasks_get\n", "record": {"elapsed": {"repr": "0:00:01.859635", "seconds": 1.859635}, "exception": null, "extra": {}, "file": {"name": "save_todoist_data.py", "path": "D:\\–ê–°–£–ü\\Python\\Projects\\OwnBot\\todoist_api\\save_todoist_data.py"}, "function": "get_todoist_data", "level": {"icon": "‚ùå", "name": "ERROR", "no": 40}, "line": 98, "message": "–û—à–∏–±–∫–∞ –≤ completed_tasks_get", "module": "save_todoist_data", "name": "__main__", "process": {"id": 15696, "name": "MainProcess"}, "thread": {"id": 7024, "name": "MainThread"}, "time": {"repr": "2024-12-19 17:44:14.514480+06:00", "timestamp": 1734608654.51448}}}
{"text": "2024-12-19 17:44:14.514 | ERROR    | __main__:get_todoist_data:99 - object str can't be used in 'await' expression\nTraceback (most recent call last):\n\n  File \"D:\\–ê–°–£–ü\\Python\\Projects\\OwnBot\\todoist_api\\save_todoist_data.py\", line 107, in <module>\n    print(asyncio.run(get_todoist_data(token='48cbdb22977eb9d84368aef673d3c7ba7c0f311a')))\n          ‚îÇ       ‚îÇ   ‚îî <function get_todoist_data at 0x0000029FC3148EA0>\n          ‚îÇ       ‚îî <function run at 0x0000029FC2E30680>\n          ‚îî <module 'asyncio' from 'C:\\\\Users\\\\user-18\\\\AppData\\\\Local\\\\Programs\\\\Python\\\\Python312\\\\Lib\\\\asyncio\\\\__init__.py'>\n\n  File \"C:\\Users\\user-18\\AppData\\Local\\Programs\\Python\\Python312\\Lib\\asyncio\\runners.py\", line 194, in run\n    return runner.run(main)\n           ‚îÇ      ‚îÇ   ‚îî <coroutine object get_todoist_data at 0x0000029FC5641620>\n           ‚îÇ      ‚îî <function Runner.run at 0x0000029FC6075C60>\n           ‚îî <asyncio.runners.Runner object at 0x0000029FC316FE60>\n  File \"C:\\Users\\user-18\\AppData\\Local\\Programs\\Python\\Python312\\Lib\\asyncio\\runners.py\", line 118, in run\n    return self._loop.run_until_complete(task)\n           ‚îÇ    ‚îÇ     ‚îÇ                  ‚îî <Task pending name='Task-1' coro=<get_todoist_data() running at D:\\–ê–°–£–ü\\Python\\Projects\\OwnBot\\todoist_api\\save_todoist_data....\n           ‚îÇ    ‚îÇ     ‚îî <function BaseEventLoop.run_until_complete at 0x0000029FC6073740>\n           ‚îÇ    ‚îî <ProactorEventLoop running=True closed=False debug=False>\n           ‚îî <asyncio.runners.Runner object at 0x0000029FC316FE60>\n  File \"C:\\Users\\user-18\\AppData\\Local\\Programs\\Python\\Python312\\Lib\\asyncio\\base_events.py\", line 673, in run_until_complete\n    self.run_forever()\n    ‚îÇ    ‚îî <function ProactorEventLoop.run_forever at 0x0000029FC60D8D60>\n    ‚îî <ProactorEventLoop running=True closed=False debug=False>\n  File \"C:\\Users\\user-18\\AppData\\Local\\Programs\\Python\\Python312\\Lib\\asyncio\\windows_events.py\", line 322, in run_forever\n    super().run_forever()\n  File \"C:\\Users\\user-18\\AppData\\Local\\Programs\\Python\\Python312\\Lib\\asyncio\\base_events.py\", line 640, in run_forever\n    self._run_once()\n    ‚îÇ    ‚îî <function BaseEventLoop._run_once at 0x0000029FC60754E0>\n    ‚îî <ProactorEventLoop running=True closed=False debug=False>\n  File \"C:\\Users\\user-18\\AppData\\Local\\Programs\\Python\\Python312\\Lib\\asyncio\\base_events.py\", line 1992, in _run_once\n    handle._run()\n    ‚îÇ      ‚îî <function Handle._run at 0x0000029FC57CD440>\n    ‚îî <Handle Task.task_wakeup(<Future finished result=None>)>\n  File \"C:\\Users\\user-18\\AppData\\Local\\Programs\\Python\\Python312\\Lib\\asyncio\\events.py\", line 88, in _run\n    self._context.run(self._callback, *self._args)\n    ‚îÇ    ‚îÇ            ‚îÇ    ‚îÇ           ‚îÇ    ‚îî <member '_args' of 'Handle' objects>\n    ‚îÇ    ‚îÇ            ‚îÇ    ‚îÇ           ‚îî <Handle Task.task_wakeup(<Future finished result=None>)>\n    ‚îÇ    ‚îÇ            ‚îÇ    ‚îî <member '_callback' of 'Handle' objects>\n    ‚îÇ    ‚îÇ            ‚îî <Handle Task.task_wakeup(<Future finished result=None>)>\n    ‚îÇ    ‚îî <member '_context' of 'Handle' objects>\n    ‚îî <Handle Task.task_wakeup(<Future finished result=None>)>\n\n> File \"D:\\–ê–°–£–ü\\Python\\Projects\\OwnBot\\todoist_api\\save_todoist_data.py\", line 80, in get_todoist_data\n    api_task = await api.get_task(task_id=await task_id[0])\n                     ‚îÇ   ‚îÇ                      ‚îî ('6402304524', '2024-12-19T02:15:30.000000Z')\n                     ‚îÇ   ‚îî <function TodoistAPIAsync.get_task at 0x0000029FC6B15BC0>\n                     ‚îî <todoist_api_python.api_async.TodoistAPIAsync object at 0x0000029FC57DEE40>\n\nTypeError: object str can't be used in 'await' expression\n", "record": {"elapsed": {"repr": "0:00:01.859635", "seconds": 1.859635}, "exception": {"type": "TypeError", "value": "object str can't be used in 'await' expression", "traceback": true}, "extra": {}, "file": {"name": "save_todoist_data.py", "path": "D:\\–ê–°–£–ü\\Python\\Projects\\OwnBot\\todoist_api\\save_todoist_data.py"}, "function": "get_todoist_data", "level": {"icon": "‚ùå", "name": "ERROR", "no": 40}, "line": 99, "message": "object str can't be used in 'await' expression", "module": "save_todoist_data", "name": "__main__", "process": {"id": 15696, "name": "MainProcess"}, "thread": {"id": 7024, "name": "MainThread"}, "time": {"repr": "2024-12-19 17:44:14.514480+06:00", "timestamp": 1734608654.51448}}}
{"text": "2024-12-19 17:46:01.640 | ERROR    | __main__:get_todoist_data:99 - –û—à–∏–±–∫–∞ –≤ completed_tasks_get\n", "record": {"elapsed": {"repr": "0:00:01.791280", "seconds": 1.79128}, "exception": null, "extra": {}, "file": {"name": "save_todoist_data.py", "path": "D:\\–ê–°–£–ü\\Python\\Projects\\OwnBot\\todoist_api\\save_todoist_data.py"}, "function": "get_todoist_data", "level": {"icon": "‚ùå", "name": "ERROR", "no": 40}, "line": 99, "message": "–û—à–∏–±–∫–∞ –≤ completed_tasks_get", "module": "save_todoist_data", "name": "__main__", "process": {"id": 2920, "name": "MainProcess"}, "thread": {"id": 13052, "name": "MainThread"}, "time": {"repr": "2024-12-19 17:46:01.640638+06:00", "timestamp": 1734608761.640638}}}
{"text": "2024-12-19 17:46:01.640 | ERROR    | __main__:get_todoist_data:100 - object tuple can't be used in 'await' expression\nTraceback (most recent call last):\n\n  File \"D:\\–ê–°–£–ü\\Python\\Projects\\OwnBot\\todoist_api\\save_todoist_data.py\", line 108, in <module>\n    print(asyncio.run(get_todoist_data(token='48cbdb22977eb9d84368aef673d3c7ba7c0f311a')))\n          ‚îÇ       ‚îÇ   ‚îî <function get_todoist_data at 0x000001F0C1498EA0>\n          ‚îÇ       ‚îî <function run at 0x000001F0C1180680>\n          ‚îî <module 'asyncio' from 'C:\\\\Users\\\\user-18\\\\AppData\\\\Local\\\\Programs\\\\Python\\\\Python312\\\\Lib\\\\asyncio\\\\__init__.py'>\n\n  File \"C:\\Users\\user-18\\AppData\\Local\\Programs\\Python\\Python312\\Lib\\asyncio\\runners.py\", line 194, in run\n    return runner.run(main)\n           ‚îÇ      ‚îÇ   ‚îî <coroutine object get_todoist_data at 0x000001F0C39D1620>\n           ‚îÇ      ‚îî <function Runner.run at 0x000001F0C4405C60>\n           ‚îî <asyncio.runners.Runner object at 0x000001F0C14BFE60>\n  File \"C:\\Users\\user-18\\AppData\\Local\\Programs\\Python\\Python312\\Lib\\asyncio\\runners.py\", line 118, in run\n    return self._loop.run_until_complete(task)\n           ‚îÇ    ‚îÇ     ‚îÇ                  ‚îî <Task pending name='Task-1' coro=<get_todoist_data() running at D:\\–ê–°–£–ü\\Python\\Projects\\OwnBot\\todoist_api\\save_todoist_data....\n           ‚îÇ    ‚îÇ     ‚îî <function BaseEventLoop.run_until_complete at 0x000001F0C4403740>\n           ‚îÇ    ‚îî <ProactorEventLoop running=True closed=False debug=False>\n           ‚îî <asyncio.runners.Runner object at 0x000001F0C14BFE60>\n  File \"C:\\Users\\user-18\\AppData\\Local\\Programs\\Python\\Python312\\Lib\\asyncio\\base_events.py\", line 673, in run_until_complete\n    self.run_forever()\n    ‚îÇ    ‚îî <function ProactorEventLoop.run_forever at 0x000001F0C4468D60>\n    ‚îî <ProactorEventLoop running=True closed=False debug=False>\n  File \"C:\\Users\\user-18\\AppData\\Local\\Programs\\Python\\Python312\\Lib\\asyncio\\windows_events.py\", line 322, in run_forever\n    super().run_forever()\n  File \"C:\\Users\\user-18\\AppData\\Local\\Programs\\Python\\Python312\\Lib\\asyncio\\base_events.py\", line 640, in run_forever\n    self._run_once()\n    ‚îÇ    ‚îî <function BaseEventLoop._run_once at 0x000001F0C44054E0>\n    ‚îî <ProactorEventLoop running=True closed=False debug=False>\n  File \"C:\\Users\\user-18\\AppData\\Local\\Programs\\Python\\Python312\\Lib\\asyncio\\base_events.py\", line 1992, in _run_once\n    handle._run()\n    ‚îÇ      ‚îî <function Handle._run at 0x000001F0C3B5D440>\n    ‚îî <Handle Task.task_wakeup(<Future finished result=None>)>\n  File \"C:\\Users\\user-18\\AppData\\Local\\Programs\\Python\\Python312\\Lib\\asyncio\\events.py\", line 88, in _run\n    self._context.run(self._callback, *self._args)\n    ‚îÇ    ‚îÇ            ‚îÇ    ‚îÇ           ‚îÇ    ‚îî <member '_args' of 'Handle' objects>\n    ‚îÇ    ‚îÇ            ‚îÇ    ‚îÇ           ‚îî <Handle Task.task_wakeup(<Future finished result=None>)>\n    ‚îÇ    ‚îÇ            ‚îÇ    ‚îî <member '_callback' of 'Handle' objects>\n    ‚îÇ    ‚îÇ            ‚îî <Handle Task.task_wakeup(<Future finished result=None>)>\n    ‚îÇ    ‚îî <member '_context' of 'Handle' objects>\n    ‚îî <Handle Task.task_wakeup(<Future finished result=None>)>\n\n> File \"D:\\–ê–°–£–ü\\Python\\Projects\\OwnBot\\todoist_api\\save_todoist_data.py\", line 80, in get_todoist_data\n    task_id = await task_id\n                    ‚îî ('6402304524', '2024-12-19T02:15:30.000000Z')\n\nTypeError: object tuple can't be used in 'await' expression\n", "record": {"elapsed": {"repr": "0:00:01.791280", "seconds": 1.79128}, "exception": {"type": "TypeError", "value": "object tuple can't be used in 'await' expression", "traceback": true}, "extra": {}, "file": {"name": "save_todoist_data.py", "path": "D:\\–ê–°–£–ü\\Python\\Projects\\OwnBot\\todoist_api\\save_todoist_data.py"}, "function": "get_todoist_data", "level": {"icon": "‚ùå", "name": "ERROR", "no": 40}, "line": 100, "message": "object tuple can't be used in 'await' expression", "module": "save_todoist_data", "name": "__main__", "process": {"id": 2920, "name": "MainProcess"}, "thread": {"id": 13052, "name": "MainThread"}, "time": {"repr": "2024-12-19 17:46:01.640638+06:00", "timestamp": 1734608761.640638}}}
{"text": "2024-12-19 18:36:40.106 | ERROR    | __main__:save_todoist_tasks:25 - –û—à–∏–±–∫–∞ –¥–æ–±–∞–≤–ª–µ–Ω–∏—è –¥–∞–Ω–Ω—ã—Ö todoist\n", "record": {"elapsed": {"repr": "0:00:16.117038", "seconds": 16.117038}, "exception": null, "extra": {}, "file": {"name": "todoist_task_db_utils.py", "path": "D:\\–ê–°–£–ü\\Python\\Projects\\OwnBot\\db\\db_utils\\todoist_task_db_utils.py"}, "function": "save_todoist_tasks", "level": {"icon": "‚ùå", "name": "ERROR", "no": 40}, "line": 25, "message": "–û—à–∏–±–∫–∞ –¥–æ–±–∞–≤–ª–µ–Ω–∏—è –¥–∞–Ω–Ω—ã—Ö todoist", "module": "todoist_task_db_utils", "name": "__main__", "process": {"id": 14052, "name": "MainProcess"}, "thread": {"id": 14528, "name": "MainThread"}, "time": {"repr": "2024-12-19 18:36:40.106937+06:00", "timestamp": 1734611800.106937}}}
{"text": "2024-12-19 18:36:40.106 | ERROR    | __main__:save_todoist_tasks:26 - (sqlite3.IntegrityError) NOT NULL constraint failed: todoisttask.user_id\n[SQL: INSERT INTO todoisttask (user_id, task, project, labels, priority, description, completed_at) VALUES (?, ?, ?, ?, ?, ?, ?) RETURNING id, created_at, updated_at]\n[parameters: (None, None, None, None, None, None, None)]\n(Background on this error at: https://sqlalche.me/e/20/gkpj)\nTraceback (most recent call last):\n\n  File \"D:\\–ê–°–£–ü\\Python\\Projects\\OwnBot\\venv\\Lib\\site-packages\\sqlalchemy\\engine\\base.py\", line 2118, in _exec_insertmany_context\n    dialect.do_execute(\n    ‚îÇ       ‚îî <function DefaultDialect.do_execute at 0x000001ADF3F036A0>\n    ‚îî <sqlalchemy.dialects.sqlite.aiosqlite.SQLiteDialect_aiosqlite object at 0x000001ADF46D1AC0>\n  File \"D:\\–ê–°–£–ü\\Python\\Projects\\OwnBot\\venv\\Lib\\site-packages\\sqlalchemy\\engine\\default.py\", line 941, in do_execute\n    cursor.execute(statement, parameters)\n    ‚îÇ      ‚îÇ       ‚îÇ          ‚îî (None, None, None, None, None, None, None)\n    ‚îÇ      ‚îÇ       ‚îî 'INSERT INTO todoisttask (user_id, task, project, labels, priority, description, completed_at) VALUES (?, ?, ?, ?, ?, ?, ?) R...\n    ‚îÇ      ‚îî <function AsyncAdapt_aiosqlite_cursor.execute at 0x000001ADF4632520>\n    ‚îî <sqlalchemy.dialects.sqlite.aiosqlite.AsyncAdapt_aiosqlite_cursor object at 0x000001ADF4707B80>\n  File \"D:\\–ê–°–£–ü\\Python\\Projects\\OwnBot\\venv\\Lib\\site-packages\\sqlalchemy\\dialects\\sqlite\\aiosqlite.py\", line 147, in execute\n    self._adapt_connection._handle_exception(error)\n    ‚îÇ    ‚îî <member '_adapt_connection' of 'AsyncAdapt_aiosqlite_cursor' objects>\n    ‚îî <sqlalchemy.dialects.sqlite.aiosqlite.AsyncAdapt_aiosqlite_cursor object at 0x000001ADF4707B80>\n  File \"D:\\–ê–°–£–ü\\Python\\Projects\\OwnBot\\venv\\Lib\\site-packages\\sqlalchemy\\dialects\\sqlite\\aiosqlite.py\", line 298, in _handle_exception\n    raise error\n          ‚îî IntegrityError('NOT NULL constraint failed: todoisttask.user_id')\n  File \"D:\\–ê–°–£–ü\\Python\\Projects\\OwnBot\\venv\\Lib\\site-packages\\sqlalchemy\\dialects\\sqlite\\aiosqlite.py\", line 129, in execute\n    self.await_(_cursor.execute(operation, parameters))\n    ‚îÇ    ‚îÇ      ‚îÇ       ‚îÇ       ‚îÇ          ‚îî (None, None, None, None, None, None, None)\n    ‚îÇ    ‚îÇ      ‚îÇ       ‚îÇ       ‚îî 'INSERT INTO todoisttask (user_id, task, project, labels, priority, description, completed_at) VALUES (?, ?, ?, ?, ?, ?, ?) R...\n    ‚îÇ    ‚îÇ      ‚îÇ       ‚îî <function Cursor.execute at 0x000001ADF46E7C40>\n    ‚îÇ    ‚îÇ      ‚îî <aiosqlite.cursor.Cursor object at 0x000001ADF6175580>\n    ‚îÇ    ‚îî <member 'await_' of 'AsyncAdapt_aiosqlite_cursor' objects>\n    ‚îî <sqlalchemy.dialects.sqlite.aiosqlite.AsyncAdapt_aiosqlite_cursor object at 0x000001ADF4707B80>\n  File \"D:\\–ê–°–£–ü\\Python\\Projects\\OwnBot\\venv\\Lib\\site-packages\\sqlalchemy\\util\\_concurrency_py3k.py\", line 132, in await_only\n    return current.parent.switch(awaitable)  # type: ignore[no-any-return,attr-defined] # noqa: E501\n           ‚îÇ       ‚îÇ             ‚îî <coroutine object Cursor.execute at 0x000001ADF616FCA0>\n           ‚îÇ       ‚îî <attribute 'parent' of 'greenlet.greenlet' objects>\n           ‚îî <_AsyncIoGreenlet object at 0x000001ADF617A440 (otid=0x000001ADF2D869D0) dead>\n  File \"D:\\–ê–°–£–ü\\Python\\Projects\\OwnBot\\venv\\Lib\\site-packages\\sqlalchemy\\util\\_concurrency_py3k.py\", line 196, in greenlet_spawn\n    value = await result\n                  ‚îî <coroutine object Connection.rollback at 0x000001ADF605E440>\n  File \"D:\\–ê–°–£–ü\\Python\\Projects\\OwnBot\\venv\\Lib\\site-packages\\aiosqlite\\cursor.py\", line 48, in execute\n    await self._execute(self._cursor.execute, sql, parameters)\n          ‚îÇ    ‚îÇ        ‚îÇ    ‚îÇ       ‚îÇ        ‚îÇ    ‚îî (None, None, None, None, None, None, None)\n          ‚îÇ    ‚îÇ        ‚îÇ    ‚îÇ       ‚îÇ        ‚îî 'INSERT INTO todoisttask (user_id, task, project, labels, priority, description, completed_at) VALUES (?, ?, ?, ?, ?, ?, ?) R...\n          ‚îÇ    ‚îÇ        ‚îÇ    ‚îÇ       ‚îî <method 'execute' of 'sqlite3.Cursor' objects>\n          ‚îÇ    ‚îÇ        ‚îÇ    ‚îî <sqlite3.Cursor object at 0x000001ADF615FAC0>\n          ‚îÇ    ‚îÇ        ‚îî <aiosqlite.cursor.Cursor object at 0x000001ADF6175580>\n          ‚îÇ    ‚îî <function Cursor._execute at 0x000001ADF46E7BA0>\n          ‚îî <aiosqlite.cursor.Cursor object at 0x000001ADF6175580>\n  File \"D:\\–ê–°–£–ü\\Python\\Projects\\OwnBot\\venv\\Lib\\site-packages\\aiosqlite\\cursor.py\", line 40, in _execute\n    return await self._conn._execute(fn, *args, **kwargs)\n                 ‚îÇ    ‚îÇ     ‚îÇ        ‚îÇ    ‚îÇ       ‚îî {}\n                 ‚îÇ    ‚îÇ     ‚îÇ        ‚îÇ    ‚îî ('INSERT INTO todoisttask (user_id, task, project, labels, priority, description, completed_at) VALUES (?, ?, ?, ?, ?, ?, ?) ...\n                 ‚îÇ    ‚îÇ     ‚îÇ        ‚îî <built-in method execute of sqlite3.Cursor object at 0x000001ADF615FAC0>\n                 ‚îÇ    ‚îÇ     ‚îî <function Connection._execute at 0x000001ADF46F0EA0>\n                 ‚îÇ    ‚îî <Connection(Thread-1, stopped daemon 4060)>\n                 ‚îî <aiosqlite.cursor.Cursor object at 0x000001ADF6175580>\n  File \"D:\\–ê–°–£–ü\\Python\\Projects\\OwnBot\\venv\\Lib\\site-packages\\aiosqlite\\core.py\", line 132, in _execute\n    return await future\n                 ‚îî <Future finished exception=IntegrityError('NOT NULL constraint failed: todoisttask.user_id')>\n  File \"D:\\–ê–°–£–ü\\Python\\Projects\\OwnBot\\venv\\Lib\\site-packages\\aiosqlite\\core.py\", line 115, in run\n    result = function()\n             ‚îî functools.partial(<built-in method close of sqlite3.Connection object at 0x000001ADF6181D50>)\n\nsqlite3.IntegrityError: NOT NULL constraint failed: todoisttask.user_id\n\n\nThe above exception was the direct cause of the following exception:\n\n\nTraceback (most recent call last):\n\n  File \"D:\\–ê–°–£–ü\\Python\\Projects\\OwnBot\\db\\db_utils\\todoist_task_db_utils.py\", line 44, in <module>\n    asyncio.run(save_todoist_tasks(token='48cbdb22977eb9d84368aef673d3c7ba7c0f311a', user_id=1))\n    ‚îÇ       ‚îÇ   ‚îî <function connection.<locals>.wrapper at 0x000001ADF46F3E20>\n    ‚îÇ       ‚îî <function run at 0x000001ADF0AEBF60>\n    ‚îî <module 'asyncio' from 'C:\\\\Users\\\\user-18\\\\AppData\\\\Local\\\\Programs\\\\Python\\\\Python312\\\\Lib\\\\asyncio\\\\__init__.py'>\n\n  File \"C:\\Users\\user-18\\AppData\\Local\\Programs\\Python\\Python312\\Lib\\asyncio\\runners.py\", line 194, in run\n    return runner.run(main)\n           ‚îÇ      ‚îÇ   ‚îî <coroutine object connection.<locals>.wrapper at 0x000001ADF6100240>\n           ‚îÇ      ‚îî <function Runner.run at 0x000001ADF2834540>\n           ‚îî <asyncio.runners.Runner object at 0x000001ADF0ADADB0>\n  File \"C:\\Users\\user-18\\AppData\\Local\\Programs\\Python\\Python312\\Lib\\asyncio\\runners.py\", line 118, in run\n    return self._loop.run_until_complete(task)\n           ‚îÇ    ‚îÇ     ‚îÇ                  ‚îî <Task pending name='Task-1' coro=<connection.<locals>.wrapper() running at D:\\–ê–°–£–ü\\Python\\Projects\\OwnBot\\db\\database.py:49> ...\n           ‚îÇ    ‚îÇ     ‚îî <function BaseEventLoop.run_until_complete at 0x000001ADF28320C0>\n           ‚îÇ    ‚îî <ProactorEventLoop running=True closed=False debug=False>\n           ‚îî <asyncio.runners.Runner object at 0x000001ADF0ADADB0>\n  File \"C:\\Users\\user-18\\AppData\\Local\\Programs\\Python\\Python312\\Lib\\asyncio\\base_events.py\", line 673, in run_until_complete\n    self.run_forever()\n    ‚îÇ    ‚îî <function ProactorEventLoop.run_forever at 0x000001ADF28FDE40>\n    ‚îî <ProactorEventLoop running=True closed=False debug=False>\n  File \"C:\\Users\\user-18\\AppData\\Local\\Programs\\Python\\Python312\\Lib\\asyncio\\windows_events.py\", line 322, in run_forever\n    super().run_forever()\n  File \"C:\\Users\\user-18\\AppData\\Local\\Programs\\Python\\Python312\\Lib\\asyncio\\base_events.py\", line 640, in run_forever\n    self._run_once()\n    ‚îÇ    ‚îî <function BaseEventLoop._run_once at 0x000001ADF2833E20>\n    ‚îî <ProactorEventLoop running=True closed=False debug=False>\n  File \"C:\\Users\\user-18\\AppData\\Local\\Programs\\Python\\Python312\\Lib\\asyncio\\base_events.py\", line 1992, in _run_once\n    handle._run()\n    ‚îÇ      ‚îî <function Handle._run at 0x000001ADF2771D00>\n    ‚îî <Handle Task.task_wakeup(<Future finished result=None>)>\n  File \"C:\\Users\\user-18\\AppData\\Local\\Programs\\Python\\Python312\\Lib\\asyncio\\events.py\", line 88, in _run\n    self._context.run(self._callback, *self._args)\n    ‚îÇ    ‚îÇ            ‚îÇ    ‚îÇ           ‚îÇ    ‚îî <member '_args' of 'Handle' objects>\n    ‚îÇ    ‚îÇ            ‚îÇ    ‚îÇ           ‚îî <Handle Task.task_wakeup(<Future finished result=None>)>\n    ‚îÇ    ‚îÇ            ‚îÇ    ‚îî <member '_callback' of 'Handle' objects>\n    ‚îÇ    ‚îÇ            ‚îî <Handle Task.task_wakeup(<Future finished result=None>)>\n    ‚îÇ    ‚îî <member '_context' of 'Handle' objects>\n    ‚îî <Handle Task.task_wakeup(<Future finished result=None>)>\n\n  File \"D:\\–ê–°–£–ü\\Python\\Projects\\OwnBot\\db\\database.py\", line 49, in wrapper\n    return await method(*args, session=session, **kwargs)\n                 ‚îÇ       ‚îÇ             ‚îÇ          ‚îî {'token': '48cbdb22977eb9d84368aef673d3c7ba7c0f311a', 'user_id': 1}\n                 ‚îÇ       ‚îÇ             ‚îî <sqlalchemy.ext.asyncio.session.AsyncSession object at 0x000001ADF5EBB920>\n                 ‚îÇ       ‚îî ()\n                 ‚îî <function save_todoist_tasks at 0x000001ADF0A98EA0>\n\n> File \"D:\\–ê–°–£–ü\\Python\\Projects\\OwnBot\\db\\db_utils\\todoist_task_db_utils.py\", line 21, in save_todoist_tasks\n    await session.commit()\n          ‚îÇ       ‚îî <function AsyncSession.commit at 0x000001ADF4300CC0>\n          ‚îî <sqlalchemy.ext.asyncio.session.AsyncSession object at 0x000001ADF5EBB920>\n\n  File \"D:\\–ê–°–£–ü\\Python\\Projects\\OwnBot\\venv\\Lib\\site-packages\\sqlalchemy\\ext\\asyncio\\session.py\", line 1009, in commit\n    await greenlet_spawn(self.sync_session.commit)\n          ‚îÇ              ‚îÇ    ‚îÇ            ‚îî <function Session.commit at 0x000001ADF41BB7E0>\n          ‚îÇ              ‚îÇ    ‚îî <sqlalchemy.orm.session.Session object at 0x000001ADF6072360>\n          ‚îÇ              ‚îî <sqlalchemy.ext.asyncio.session.AsyncSession object at 0x000001ADF5EBB920>\n          ‚îî <function greenlet_spawn at 0x000001ADF3145D00>\n  File \"D:\\–ê–°–£–ü\\Python\\Projects\\OwnBot\\venv\\Lib\\site-packages\\sqlalchemy\\util\\_concurrency_py3k.py\", line 203, in greenlet_spawn\n    result = context.switch(value)\n             ‚îÇ       ‚îÇ      ‚îî None\n             ‚îÇ       ‚îî <method 'switch' of 'greenlet.greenlet' objects>\n             ‚îî <_AsyncIoGreenlet object at 0x000001ADF617A440 (otid=0x000001ADF2D869D0) dead>\n  File \"D:\\–ê–°–£–ü\\Python\\Projects\\OwnBot\\venv\\Lib\\site-packages\\sqlalchemy\\orm\\session.py\", line 2028, in commit\n    trans.commit(_to_root=True)\n    ‚îÇ     ‚îî <function SessionTransaction.commit at 0x000001ADF41BA8E0>\n    ‚îî <sqlalchemy.orm.session.SessionTransaction object at 0x000001ADF6178E50>\n  File \"<string>\", line 2, in commit\n  File \"D:\\–ê–°–£–ü\\Python\\Projects\\OwnBot\\venv\\Lib\\site-packages\\sqlalchemy\\orm\\state_changes.py\", line 139, in _go\n    ret_value = fn(self, *arg, **kw)\n                ‚îÇ  ‚îÇ      ‚îÇ      ‚îî {'_to_root': True}\n                ‚îÇ  ‚îÇ      ‚îî ()\n                ‚îÇ  ‚îî <sqlalchemy.orm.session.SessionTransaction object at 0x000001ADF6178E50>\n                ‚îî <function SessionTransaction.commit at 0x000001ADF41BA700>\n  File \"D:\\–ê–°–£–ü\\Python\\Projects\\OwnBot\\venv\\Lib\\site-packages\\sqlalchemy\\orm\\session.py\", line 1313, in commit\n    self._prepare_impl()\n    ‚îÇ    ‚îî <function SessionTransaction._prepare_impl at 0x000001ADF41BA5C0>\n    ‚îî <sqlalchemy.orm.session.SessionTransaction object at 0x000001ADF6178E50>\n  File \"<string>\", line 2, in _prepare_impl\n  File \"D:\\–ê–°–£–ü\\Python\\Projects\\OwnBot\\venv\\Lib\\site-packages\\sqlalchemy\\orm\\state_changes.py\", line 139, in _go\n    ret_value = fn(self, *arg, **kw)\n                ‚îÇ  ‚îÇ      ‚îÇ      ‚îî {}\n                ‚îÇ  ‚îÇ      ‚îî ()\n                ‚îÇ  ‚îî <sqlalchemy.orm.session.SessionTransaction object at 0x000001ADF6178E50>\n                ‚îî <function SessionTransaction._prepare_impl at 0x000001ADF41BA520>\n  File \"D:\\–ê–°–£–ü\\Python\\Projects\\OwnBot\\venv\\Lib\\site-packages\\sqlalchemy\\orm\\session.py\", line 1288, in _prepare_impl\n    self.session.flush()\n    ‚îÇ    ‚îÇ       ‚îî <function Session.flush at 0x000001ADF41C2700>\n    ‚îÇ    ‚îî <sqlalchemy.orm.session.Session object at 0x000001ADF6072360>\n    ‚îî <sqlalchemy.orm.session.SessionTransaction object at 0x000001ADF6178E50>\n  File \"D:\\–ê–°–£–ü\\Python\\Projects\\OwnBot\\venv\\Lib\\site-packages\\sqlalchemy\\orm\\session.py\", line 4352, in flush\n    self._flush(objects)\n    ‚îÇ    ‚îÇ      ‚îî None\n    ‚îÇ    ‚îî <function Session._flush at 0x000001ADF41C28E0>\n    ‚îî <sqlalchemy.orm.session.Session object at 0x000001ADF6072360>\n  File \"D:\\–ê–°–£–ü\\Python\\Projects\\OwnBot\\venv\\Lib\\site-packages\\sqlalchemy\\orm\\session.py\", line 4487, in _flush\n    with util.safe_reraise():\n         ‚îÇ    ‚îî <class 'sqlalchemy.util.langhelpers.safe_reraise'>\n         ‚îî <module 'sqlalchemy.util' from 'D:\\\\–ê–°–£–ü\\\\Python\\\\Projects\\\\OwnBot\\\\venv\\\\Lib\\\\site-packages\\\\sqlalchemy\\\\util\\\\__init__.py'>\n  File \"D:\\–ê–°–£–ü\\Python\\Projects\\OwnBot\\venv\\Lib\\site-packages\\sqlalchemy\\util\\langhelpers.py\", line 146, in __exit__\n    raise exc_value.with_traceback(exc_tb)\n          ‚îÇ         ‚îÇ              ‚îî <traceback object at 0x000001ADF6185E80>\n          ‚îÇ         ‚îî <method 'with_traceback' of 'BaseException' objects>\n          ‚îî IntegrityError('(sqlite3.IntegrityError) NOT NULL constraint failed: todoisttask.user_id')\n  File \"D:\\–ê–°–£–ü\\Python\\Projects\\OwnBot\\venv\\Lib\\site-packages\\sqlalchemy\\orm\\session.py\", line 4448, in _flush\n    flush_context.execute()\n    ‚îÇ             ‚îî <function UOWTransaction.execute at 0x000001ADF419F060>\n    ‚îî <sqlalchemy.orm.unitofwork.UOWTransaction object at 0x000001ADF6174350>\n  File \"D:\\–ê–°–£–ü\\Python\\Projects\\OwnBot\\venv\\Lib\\site-packages\\sqlalchemy\\orm\\unitofwork.py\", line 466, in execute\n    rec.execute(self)\n    ‚îÇ   ‚îÇ       ‚îî <sqlalchemy.orm.unitofwork.UOWTransaction object at 0x000001ADF6174350>\n    ‚îÇ   ‚îî <function SaveUpdateAll.execute at 0x000001ADF419FBA0>\n    ‚îî SaveUpdateAll(Mapper[TodoistTask(todoisttask)])\n  File \"D:\\–ê–°–£–ü\\Python\\Projects\\OwnBot\\venv\\Lib\\site-packages\\sqlalchemy\\orm\\unitofwork.py\", line 642, in execute\n    util.preloaded.orm_persistence.save_obj(\n    ‚îÇ    ‚îÇ         ‚îÇ               ‚îî <function save_obj at 0x000001ADF4191300>\n    ‚îÇ    ‚îÇ         ‚îî <module 'sqlalchemy.orm.persistence' from 'D:\\\\–ê–°–£–ü\\\\Python\\\\Projects\\\\OwnBot\\\\venv\\\\Lib\\\\site-packages\\\\sqlalchemy\\\\orm\\\\per...\n    ‚îÇ    ‚îî <module 'sqlalchemy.util.preloaded' from 'D:\\\\–ê–°–£–ü\\\\Python\\\\Projects\\\\OwnBot\\\\venv\\\\Lib\\\\site-packages\\\\sqlalchemy\\\\util\\\\pre...\n    ‚îî <module 'sqlalchemy.util' from 'D:\\\\–ê–°–£–ü\\\\Python\\\\Projects\\\\OwnBot\\\\venv\\\\Lib\\\\site-packages\\\\sqlalchemy\\\\util\\\\__init__.py'>\n  File \"D:\\–ê–°–£–ü\\Python\\Projects\\OwnBot\\venv\\Lib\\site-packages\\sqlalchemy\\orm\\persistence.py\", line 93, in save_obj\n    _emit_insert_statements(\n    ‚îî <function _emit_insert_statements at 0x000001ADF4192160>\n  File \"D:\\–ê–°–£–ü\\Python\\Projects\\OwnBot\\venv\\Lib\\site-packages\\sqlalchemy\\orm\\persistence.py\", line 1143, in _emit_insert_statements\n    result = connection.execute(\n             ‚îÇ          ‚îî <function Connection.execute at 0x000001ADF3E789A0>\n             ‚îî <sqlalchemy.engine.base.Connection object at 0x000001ADF6174560>\n  File \"D:\\–ê–°–£–ü\\Python\\Projects\\OwnBot\\venv\\Lib\\site-packages\\sqlalchemy\\engine\\base.py\", line 1418, in execute\n    return meth(\n           ‚îî <bound method ClauseElement._execute_on_connection of <sqlalchemy.sql.dml.Insert object at 0x000001ADF6174BC0>>\n  File \"D:\\–ê–°–£–ü\\Python\\Projects\\OwnBot\\venv\\Lib\\site-packages\\sqlalchemy\\sql\\elements.py\", line 515, in _execute_on_connection\n    return connection._execute_clauseelement(\n           ‚îÇ          ‚îî <function Connection._execute_clauseelement at 0x000001ADF3E78CC0>\n           ‚îî <sqlalchemy.engine.base.Connection object at 0x000001ADF6174560>\n  File \"D:\\–ê–°–£–ü\\Python\\Projects\\OwnBot\\venv\\Lib\\site-packages\\sqlalchemy\\engine\\base.py\", line 1640, in _execute_clauseelement\n    ret = self._execute_context(\n          ‚îÇ    ‚îî <function Connection._execute_context at 0x000001ADF3E78EA0>\n          ‚îî <sqlalchemy.engine.base.Connection object at 0x000001ADF6174560>\n  File \"D:\\–ê–°–£–ü\\Python\\Projects\\OwnBot\\venv\\Lib\\site-packages\\sqlalchemy\\engine\\base.py\", line 1844, in _execute_context\n    return self._exec_insertmany_context(dialect, context)\n           ‚îÇ    ‚îÇ                        ‚îÇ        ‚îî <sqlalchemy.dialects.sqlite.aiosqlite.SQLiteExecutionContext_aiosqlite object at 0x000001ADF5FFEBA0>\n           ‚îÇ    ‚îÇ                        ‚îî <sqlalchemy.dialects.sqlite.aiosqlite.SQLiteDialect_aiosqlite object at 0x000001ADF46D1AC0>\n           ‚îÇ    ‚îî <function Connection._exec_insertmany_context at 0x000001ADF3E78FE0>\n           ‚îî <sqlalchemy.engine.base.Connection object at 0x000001ADF6174560>\n  File \"D:\\–ê–°–£–ü\\Python\\Projects\\OwnBot\\venv\\Lib\\site-packages\\sqlalchemy\\engine\\base.py\", line 2126, in _exec_insertmany_context\n    self._handle_dbapi_exception(\n    ‚îÇ    ‚îî <function Connection._handle_dbapi_exception at 0x000001ADF3E791C0>\n    ‚îî <sqlalchemy.engine.base.Connection object at 0x000001ADF6174560>\n  File \"D:\\–ê–°–£–ü\\Python\\Projects\\OwnBot\\venv\\Lib\\site-packages\\sqlalchemy\\engine\\base.py\", line 2355, in _handle_dbapi_exception\n    raise sqlalchemy_exception.with_traceback(exc_info[2]) from e\n          ‚îÇ                    ‚îÇ              ‚îÇ                 ‚îî IntegrityError('NOT NULL constraint failed: todoisttask.user_id')\n          ‚îÇ                    ‚îÇ              ‚îî (<class 'sqlite3.IntegrityError'>, IntegrityError('NOT NULL constraint failed: todoisttask.user_id'), <traceback object at 0x...\n          ‚îÇ                    ‚îî <method 'with_traceback' of 'BaseException' objects>\n          ‚îî IntegrityError('(sqlite3.IntegrityError) NOT NULL constraint failed: todoisttask.user_id')\n  File \"D:\\–ê–°–£–ü\\Python\\Projects\\OwnBot\\venv\\Lib\\site-packages\\sqlalchemy\\engine\\base.py\", line 2118, in _exec_insertmany_context\n    dialect.do_execute(\n    ‚îÇ       ‚îî <function DefaultDialect.do_execute at 0x000001ADF3F036A0>\n    ‚îî <sqlalchemy.dialects.sqlite.aiosqlite.SQLiteDialect_aiosqlite object at 0x000001ADF46D1AC0>\n  File \"D:\\–ê–°–£–ü\\Python\\Projects\\OwnBot\\venv\\Lib\\site-packages\\sqlalchemy\\engine\\default.py\", line 941, in do_execute\n    cursor.execute(statement, parameters)\n    ‚îÇ      ‚îÇ       ‚îÇ          ‚îî (None, None, None, None, None, None, None)\n    ‚îÇ      ‚îÇ       ‚îî 'INSERT INTO todoisttask (user_id, task, project, labels, priority, description, completed_at) VALUES (?, ?, ?, ?, ?, ?, ?) R...\n    ‚îÇ      ‚îî <function AsyncAdapt_aiosqlite_cursor.execute at 0x000001ADF4632520>\n    ‚îî <sqlalchemy.dialects.sqlite.aiosqlite.AsyncAdapt_aiosqlite_cursor object at 0x000001ADF4707B80>\n  File \"D:\\–ê–°–£–ü\\Python\\Projects\\OwnBot\\venv\\Lib\\site-packages\\sqlalchemy\\dialects\\sqlite\\aiosqlite.py\", line 147, in execute\n    self._adapt_connection._handle_exception(error)\n    ‚îÇ    ‚îî <member '_adapt_connection' of 'AsyncAdapt_aiosqlite_cursor' objects>\n    ‚îî <sqlalchemy.dialects.sqlite.aiosqlite.AsyncAdapt_aiosqlite_cursor object at 0x000001ADF4707B80>\n  File \"D:\\–ê–°–£–ü\\Python\\Projects\\OwnBot\\venv\\Lib\\site-packages\\sqlalchemy\\dialects\\sqlite\\aiosqlite.py\", line 298, in _handle_exception\n    raise error\n          ‚îî IntegrityError('NOT NULL constraint failed: todoisttask.user_id')\n  File \"D:\\–ê–°–£–ü\\Python\\Projects\\OwnBot\\venv\\Lib\\site-packages\\sqlalchemy\\dialects\\sqlite\\aiosqlite.py\", line 129, in execute\n    self.await_(_cursor.execute(operation, parameters))\n    ‚îÇ    ‚îÇ      ‚îÇ       ‚îÇ       ‚îÇ          ‚îî (None, None, None, None, None, None, None)\n    ‚îÇ    ‚îÇ      ‚îÇ       ‚îÇ       ‚îî 'INSERT INTO todoisttask (user_id, task, project, labels, priority, description, completed_at) VALUES (?, ?, ?, ?, ?, ?, ?) R...\n    ‚îÇ    ‚îÇ      ‚îÇ       ‚îî <function Cursor.execute at 0x000001ADF46E7C40>\n    ‚îÇ    ‚îÇ      ‚îî <aiosqlite.cursor.Cursor object at 0x000001ADF6175580>\n    ‚îÇ    ‚îî <member 'await_' of 'AsyncAdapt_aiosqlite_cursor' objects>\n    ‚îî <sqlalchemy.dialects.sqlite.aiosqlite.AsyncAdapt_aiosqlite_cursor object at 0x000001ADF4707B80>\n  File \"D:\\–ê–°–£–ü\\Python\\Projects\\OwnBot\\venv\\Lib\\site-packages\\sqlalchemy\\util\\_concurrency_py3k.py\", line 132, in await_only\n    return current.parent.switch(awaitable)  # type: ignore[no-any-return,attr-defined] # noqa: E501\n           ‚îÇ       ‚îÇ             ‚îî <coroutine object Cursor.execute at 0x000001ADF616FCA0>\n           ‚îÇ       ‚îî <attribute 'parent' of 'greenlet.greenlet' objects>\n           ‚îî <_AsyncIoGreenlet object at 0x000001ADF617A440 (otid=0x000001ADF2D869D0) dead>\n  File \"D:\\–ê–°–£–ü\\Python\\Projects\\OwnBot\\venv\\Lib\\site-packages\\sqlalchemy\\util\\_concurrency_py3k.py\", line 196, in greenlet_spawn\n    value = await result\n                  ‚îî <coroutine object Connection.rollback at 0x000001ADF605E440>\n  File \"D:\\–ê–°–£–ü\\Python\\Projects\\OwnBot\\venv\\Lib\\site-packages\\aiosqlite\\cursor.py\", line 48, in execute\n    await self._execute(self._cursor.execute, sql, parameters)\n          ‚îÇ    ‚îÇ        ‚îÇ    ‚îÇ       ‚îÇ        ‚îÇ    ‚îî (None, None, None, None, None, None, None)\n          ‚îÇ    ‚îÇ        ‚îÇ    ‚îÇ       ‚îÇ        ‚îî 'INSERT INTO todoisttask (user_id, task, project, labels, priority, description, completed_at) VALUES (?, ?, ?, ?, ?, ?, ?) R...\n          ‚îÇ    ‚îÇ        ‚îÇ    ‚îÇ       ‚îî <method 'execute' of 'sqlite3.Cursor' objects>\n          ‚îÇ    ‚îÇ        ‚îÇ    ‚îî <sqlite3.Cursor object at 0x000001ADF615FAC0>\n          ‚îÇ    ‚îÇ        ‚îî <aiosqlite.cursor.Cursor object at 0x000001ADF6175580>\n          ‚îÇ    ‚îî <function Cursor._execute at 0x000001ADF46E7BA0>\n          ‚îî <aiosqlite.cursor.Cursor object at 0x000001ADF6175580>\n  File \"D:\\–ê–°–£–ü\\Python\\Projects\\OwnBot\\venv\\Lib\\site-packages\\aiosqlite\\cursor.py\", line 40, in _execute\n    return await self._conn._execute(fn, *args, **kwargs)\n                 ‚îÇ    ‚îÇ     ‚îÇ        ‚îÇ    ‚îÇ       ‚îî {}\n                 ‚îÇ    ‚îÇ     ‚îÇ        ‚îÇ    ‚îî ('INSERT INTO todoisttask (user_id, task, project, labels, priority, description, completed_at) VALUES (?, ?, ?, ?, ?, ?, ?) ...\n                 ‚îÇ    ‚îÇ     ‚îÇ        ‚îî <built-in method execute of sqlite3.Cursor object at 0x000001ADF615FAC0>\n                 ‚îÇ    ‚îÇ     ‚îî <function Connection._execute at 0x000001ADF46F0EA0>\n                 ‚îÇ    ‚îî <Connection(Thread-1, stopped daemon 4060)>\n                 ‚îî <aiosqlite.cursor.Cursor object at 0x000001ADF6175580>\n  File \"D:\\–ê–°–£–ü\\Python\\Projects\\OwnBot\\venv\\Lib\\site-packages\\aiosqlite\\core.py\", line 132, in _execute\n    return await future\n                 ‚îî <Future finished exception=IntegrityError('NOT NULL constraint failed: todoisttask.user_id')>\n  File \"D:\\–ê–°–£–ü\\Python\\Projects\\OwnBot\\venv\\Lib\\site-packages\\aiosqlite\\core.py\", line 115, in run\n    result = function()\n             ‚îî functools.partial(<built-in method close of sqlite3.Connection object at 0x000001ADF6181D50>)\n\nsqlalchemy.exc.IntegrityError: (sqlite3.IntegrityError) NOT NULL constraint failed: todoisttask.user_id\n[SQL: INSERT INTO todoisttask (user_id, task, project, labels, priority, description, completed_at) VALUES (?, ?, ?, ?, ?, ?, ?) RETURNING id, created_at, updated_at]\n[parameters: (None, None, None, None, None, None, None)]\n(Background on this error at: https://sqlalche.me/e/20/gkpj)\n", "record": {"elapsed": {"repr": "0:00:16.117038", "seconds": 16.117038}, "exception": {"type": "IntegrityError", "value": "(sqlite3.IntegrityError) NOT NULL constraint failed: todoisttask.user_id\n[SQL: INSERT INTO todoisttask (user_id, task, project, labels, priority, description, completed_at) VALUES (?, ?, ?, ?, ?, ?, ?) RETURNING id, created_at, updated_at]\n[parameters: (None, None, None, None, None, None, None)]\n(Background on this error at: https://sqlalche.me/e/20/gkpj)", "traceback": true}, "extra": {}, "file": {"name": "todoist_task_db_utils.py", "path": "D:\\–ê–°–£–ü\\Python\\Projects\\OwnBot\\db\\db_utils\\todoist_task_db_utils.py"}, "function": "save_todoist_tasks", "level": {"icon": "‚ùå", "name": "ERROR", "no": 40}, "line": 26, "message": "(sqlite3.IntegrityError) NOT NULL constraint failed: todoisttask.user_id\n[SQL: INSERT INTO todoisttask (user_id, task, project, labels, priority, description, completed_at) VALUES (?, ?, ?, ?, ?, ?, ?) RETURNING id, created_at, updated_at]\n[parameters: (None, None, None, None, None, None, None)]\n(Background on this error at: https://sqlalche.me/e/20/gkpj)", "module": "todoist_task_db_utils", "name": "__main__", "process": {"id": 14052, "name": "MainProcess"}, "thread": {"id": 14528, "name": "MainThread"}, "time": {"repr": "2024-12-19 18:36:40.106937+06:00", "timestamp": 1734611800.106937}}}
